Workbook
Name DS_Mon: PhanCong!$A$3:$A$18

Sheet HuongDan
A1: HƯỚNG DẪN — PHIÊN BẢN 9 LỚP + RÀNG BUỘC SƯ PHẠM
A3: Nhập liệu: PhanCong (GV — lớp 6C đang tạm chép từ 6B, HÃY SỬA LẠI), SoTiet (định mức), GV_Ban (GV nghỉ/bận), TKB_Nhap (vị trí tiết).
A4: Tự động: TKB (in), TKB_GV (đỏ = trùng GV), KiemTra (đỏ = lệch định mức; tổng tiết mỗi lớp so với khung 29–30 + buổi 2).
A6: MACRO XepTKB (Alt+F8) tự xếp với đầy đủ ràng buộc:
A7: Hệ thống: không trùng GV, không trùng lớp (1 ô 1 môn), đúng định mức SoTiet từng môn/lớp (⇒ đủ tiết GV).
A8: Sư phạm: mỗi môn ≤1 tiết/ngày (riêng Ngữ văn được tiết kép — 2 tiết LIỀN nhau cùng buổi);
A9: không quá 3 tiết 'môn nặng' (Toán, Văn, KHTN Lý/Hoá) liên tiếp trong 1 buổi; Thể dục tránh tiết 5;
A10: ưu tiên rải đều các tiết cùng môn cách ngày; chào cờ = HĐTN Thứ 2 tiết 1; sinh hoạt lớp = HĐTN tiết cuối Thứ 7.
A11: Số tiết/ngày do khung tiết quyết định (sheet ẩn Khung): ngày 2 buổi 7 tiết, ngày 1 buổi 5 tiết — đã đúng chuẩn.
A12: Chế độ giữ lịch tối đa: chỉ đổi các ô bắt buộc, báo rõ số ô giữ/đổi.
A14: Lần đầu sau khi thêm 6C: KiemTra sẽ đỏ ở cột 6C (chưa xếp tiết) — chạy macro 1 lần để điền.
A16: ĐỊNH MỨC GIÁO VIÊN (sheet DinhMuc_GV):
... A19: Macro v4 kiểm tra định mức trước khi xếp và thêm ràng buộc: GV không dạy quá 4 tiết/buổi (không full 5 tiết).

Sheet HuongDan_ChiTiet
B1: HƯỚNG DẪN CHI TIẾT — HỆ THỐNG XẾP THỜI KHÓA BIỂU TỰ ĐỘNG
B3: 8. CÂN BẰNG TẢI GIÁO VIÊN (ModCanBangTai)
B4: Alt+F8 → CanBangTai → tạo sheet 'DeXuat_CanBang'.
B5: Macro quét GV vượt trần (DinhMuc_GV), tìm GV nhược tải DẠY CÙNG MÔN còn quota để chuyển bớt tiết.
B6: Chỉ ĐỀ XUẤT — không tự sửa PhanCong (chuyển GV kéo theo GVCN/thực tế macro không biết).
B7: Quy trình: chạy CanBangTai → xem đề xuất → sửa tay PhanCong → chạy lại để kiểm → XepTKB.
B8: Nếu báo 'không tìm được GV nhận cùng môn': môn đó chỉ 1 GV dạy — cần phân công thêm GV hoặc chấp nhận vượt.
B9: • GV_Ban [NHẬP] — Giáo viên bận/nghỉ theo Thứ/Buổi/Tiết. Macro sẽ né các ô này.
B10: • DinhMuc_GV[NHẬP] — Chức vụ GV → trần tiết (19 − giảm trừ). Cột 'Vượt' đỏ = phải sửa PhanCong.
B11: • TKB_Nhap [LÕI] — Lưới TKB. Macro ghi kết quả vào đây. Là nguồn cho mọi sheet hiển thị.
B12: • Khung [ẨN] — Bản đồ ô được phép xếp (dấu 'x'). Quyết định mẫu buổi học (S4-C3, S5...).
B13: • TuanConfig[CẤU HÌNH] — Seed mỗi tuần (B1) + lịch sử. Điều khiển 'mỗi tuần một TKB'.
... B72: • Luôn lưu file dạng .xlsm (Macro-Enabled). Lưu .xlsx sẽ MẤT toàn bộ macro.

Sheet PhanCong
A1: PHÂN CÔNG CHUYÊN MÔN — 8 lớp (2 lớp/khối, khối 6–9)
A2: Môn \ Lớp | B2: 6A7 | C2: 6A8 | D2: 6A9 | E2: 6A10 | F2: 6A11 | G2: 7A7 | H2: 7A8 | I2: 7A9 | J2: 7A10 | K2: 7A11 | L2: 8A7 | M2: 8A8 | N2: 8A9 | O2: 8A10 | P2: 8A11 | Q2: 9A8 | R2: 9A9 | S2: 9A10 | T2: 9A11 | U2: 9A12 | W2: MÃ VAI TRÒ
A3: Toán học | B3: Lại Thị Thanh Huyền | C3: Lại Thị Thanh Huyền | D3: Lê Thị Thu Hằng | E3: Lê Thị Thu Hằng | F3: Lê Thị Thu Hằng | G3: Nguyễn Thị Hà | H3: Nguyễn Thị Hà | I3: Phùng Thị Lan | J3: Hoàng Thị Thanh Thắm | K3: Phùng Thị Lan | L3: Hoàng Thị Thanh Thắm | M3: Hoàng Thị Thanh Thắm | N3: Mẫn Xuân Thắng | O3: Nguyễn Thị Hiền | P3: Nguyễn Thị Hiền | Q3: Nguyễn Thị Hà | R3: Lại Thị Thanh Huyền | S3: Phùng Thị Lan | T3: Lê Thị Thu Hằng | U3: Nguyễn Thị Hà | W3: 3
A4: Ngữ văn | B4: Ngô Thị Xuân Hương | C4: Hoàng Thị Phương Duyên | D4: Hoàng Thị Phương Duyên | E4: Nông Thị Trà | F4: Bàng Thị Phượng | G4: Triệu Thị Luyến | H4: Đồng Thị Hiền | I4: Bùi Thị Mỹ Hạnh | J4: Bùi Thị Mỹ Hạnh | K4: Hoàng Thị Kiều Loan | L4: Phan Thị Thùy Linh | M4: Ngô Thị Xuân Hương | N4: Nguyễn Thị Thu Hương | O4: Hoàng Thị Phương Duyên | P4: Ngô Thị Xuân Hương | Q4: Đồng Thị Hiền | R4: Phan Thị Thùy Linh | S4: Bùi Thị Mỹ Hạnh | T4: Nguyễn Thị Thu Hương | U4: Triệu Thị Luyến | W4: 3
A5: Tiếng Anh | B5: Nguyễn Thị Hồng Minh | C5: Nguyễn Thị Hồng Minh | D5: Phan Thị Minh | E5: Phan Thị Minh | F5: Nguyễn Thị Hồng Minh | G5: Nguyễn Đình Tiến | H5: Nguyễn Đình Tiến | I5: Nguyễn Đình Tiến | J5: Nguyễn Thị Hồng Minh | K5: Nguyễn Thị Hồng Minh | L5: Trần Đức Ngân | M5: Nguyễn Thị Hồng Minh | N5: Trần Đức Ngân | O5: Trần Đức Ngân | P5: Trần Đức Ngân | Q5: Nguyễn Đình Tiến | R5: Nguyễn Đình Tiến | S5: Phan Thị Minh | T5: Phan Thị Minh | U5: Trần Đức Ngân | W5: 1
A6: Khoa học tự nhiên (Vật lý) | B6: Đỗ Thị Thu Hiền | C6: Đỗ Thị Thu Hiền | D6: Đỗ Thị Thu Hiền | E6: Đỗ Thị Thu Hiền | F6: Đỗ Thị Thu Hiền | G6: Trương Thị Thu Hương | H6: Trương Thị Thu Hương | I6: Trương Thị Thu Hương | J6: Trương Thị Thu Hương | K6: Trương Thị Thu Hương | L6: Đỗ Thị Thu Hiền | M6: Đỗ Thị Thu Hiền | N6: Đỗ Thị Thu Hiền | O6: Đỗ Thị Thu Hiền | P6: Đỗ Thị Thu Hiền | Q6: Trương Thị Thu Hương | R6: Trương Thị Thu Hương | S6: Trương Thị Thu Hương | T6: Trương Thị Thu Hương | U6: Trương Thị Thu Hương | W6: 0
A7: Khoa học tự nhiên (Hóa học) | B7: Trần Thị Liễu | C7: Trần Thị Liễu | D7: Trần Thị Liễu | E7: Trần Thị Liễu | F7: Trần Thị Liễu | G7: Trần Thị Liễu | H7: Trần Thị Liễu | I7: Trần Thị Liễu | J7: Trần Thị Liễu | K7: Trần Thị Liễu | L7: Trần Thị Liễu | M7: Trần Thị Liễu | N7: Trần Thị Liễu | O7: Trần Thị Liễu | P7: Trần Thị Liễu | Q7: Trần Thị Liễu | R7: Trần Thị Liễu | S7: Trần Thị Liễu | T7: Trần Thị Liễu | U7: Trần Thị Liễu | W7: 0
A8: Khoa học tự nhiên (Sinh học) | B8: Hà Thị Hải Yến | C8: Hà Thị Hải Yến | D8: Hà Thị Hải Yến | E8: Hà Thị Hải Yến | F8: Hà Thị Hải Yến | G8: Đoàn Tiến Quân | H8: Nguyễn Ánh Hồng | I8: Nguyễn Ánh Hồng | J8: Nguyễn Ánh Hồng | K8: Nguyễn Ánh Hồng | L8: Trần Thị Quỳnh Hằng | M8: Trần Thị Quỳnh Hằng | N8: Trần Thị Quỳnh Hằng | O8: Hà Thị Hải Yến | P8: Trần Thị Quỳnh Hằng | Q8: Hà Thị Hải Yến | R8: Hà Thị Hải Yến | S8: Hà Thị Hải Yến | T8: Hà Thị Hải Yến | U8: Hà Thị Hải Yến | W8: 0
A9: Lịch sử và Địa Lý (Lịch sử) | B9: Nguyễn Thị Thu Hương | C9: Nguyễn Thị Thu Hương | D9: Nguyễn Thị Thu Hương | E9: Nguyễn Thị Thu Hương | F9: Nguyễn Thị Thu Hương | G9: Bùi Thị Hòa | H9: Bùi Thị Hòa | I9: Nguyễn Thị Thu Hương | J9: Nguyễn Thị Thu Hương | K9: Bùi Thị Hòa | L9: Bùi Thị Hòa | M9: Bùi Thị Hòa | N9: Bùi Thị Hòa | O9: Bùi Thị Hòa | P9: Bùi Thị Hòa | Q9: Đồng Thị Hiền | R9: Bùi Thị Hòa | S9: Đồng Thị Hiền | T9: Bùi Thị Hòa | U9: Bùi Thị Hòa | W9: 0
A10: Lịch sử và Địa Lý (Địa lý) | B10: Vũ Thị Bích Hằng | C10: Vũ Thị Bích Hằng | D10: Vũ Thị Bích Hằng | E10: Vũ Thị Bích Hằng | F10: Vũ Thị Bích Hằng | G10: Vũ Thị Bích Hằng | H10: Vũ Thị Bích Hằng | I10: Vũ Thị Bích Hằng | J10: Vũ Thị Bích Hằng | K10: Vũ Thị Bích Hằng | L10: Chu Diệu Linh | M10: Chu Diệu Linh | N10: Chu Diệu Linh | O10: Chu Diệu Linh | P10: Chu Diệu Linh | Q10: Chu Diệu Linh | R10: Chu Diệu Linh | S10: Chu Diệu Linh | T10: Chu Diệu Linh | U10: Chu Diệu Linh | W10: 0
A11: GDCD | B11: Hoàng Thị Kiều Loan | C11: Hoàng Thị Kiều Loan | D11: Hoàng Thị Kiều Loan | E11: Hoàng Thị Kiều Loan | F11: Hoàng Thị Kiều Loan | G11: Bàng Thị Phượng | H11: Bàng Thị Phượng | I11: Bàng Thị Phượng | J11: Bàng Thị Phượng | K11: Bàng Thị Phượng | L11: Bùi Thị Mỹ Hạnh | M11: Bùi Thị Mỹ Hạnh | N11: Bùi Thị Mỹ Hạnh | O11: Bùi Thị Mỹ Hạnh | P11: Bùi Thị Mỹ Hạnh | Q11: Hoàng Thị Phương Duyên | R11: Hoàng Thị Phương Duyên | S11: Hoàng Thị Phương Duyên | T11: Hoàng Thị Phương Duyên | U11: Hoàng Thị Phương Duyên | W11: 0
A12: Công nghệ | B12: Vũ Thị Bích Hằng | C12: Vũ Thị Bích Hằng | D12: Vũ Thị Bích Hằng | E12: Vũ Thị Bích Hằng | F12: Bàng Như Quỳnh | G12: Hoàng Thị Kiều Loan | H12: Lương Thị Thu Hiền | I12: Lương Thị Thu Hiền | J12: Lương Thị Thu Hiền | K12: Lương Thị Thu Hiền | L12: Mẫn Xuân Thắng | M12: Mẫn Xuân Thắng | N12: Mẫn Xuân Thắng | O12: Mẫn Xuân Thắng | P12: Mẫn Xuân Thắng | Q12: Mẫn Xuân Thắng | R12: Mẫn Xuân Thắng | S12: Mẫn Xuân Thắng | T12: Mẫn Xuân Thắng | U12: Mẫn Xuân Thắng | W12: 0
A13: Tin học | B13: Lương Thị Thu Hiền | C13: Lương Thị Thu Hiền | D13: Lương Thị Thu Hiền | E13: Lương Thị Thu Hiền | F13: Lương Thị Thu Hiền | G13: Lương Thị Thu Hiền | H13: Lương Thị Thu Hiền | I13: Lương Thị Thu Hiền | J13: Lương Thị Thu Hiền | K13: Lương Thị Thu Hiền | L13: Lương Thị Thu Hiền | M13: Lương Thị Thu Hiền | N13: Lương Thị Thu Hiền | O13: Lương Thị Thu Hiền | P13: Lương Thị Thu Hiền | Q13: Nguyễn Thị Hiền | R13: Nguyễn Thị Hiền | S13: Nguyễn Thị Hiền | T13: Nguyễn Thị Hiền | U13: Nguyễn Thị Hiền | W13: 0
A14: Giáo dục thể chất | B14: Lê Văn Hậu | C14: Lê Văn Hậu | D14: Lê Văn Hậu | E14: Lê Văn Hậu | F14: Lê Văn Hậu | G14: Lê Văn Hậu | H14: Lê Văn Hậu | I14: Lê Văn Hậu | J14: Lê Văn Hậu | K14: Lê Văn Hậu | L14: GV môn GDTC | M14: GV môn GDTC | N14: GV môn GDTC | O14: GV môn GDTC | P14: Bùi Đức Anh | Q14: GV môn GDTC | R14: GV môn GDTC | S14: GV môn GDTC | T14: GV môn GDTC | U14: GV môn GDTC | W14: 4
... A18: Nghệ thuật (Mỹ thuật) | B18: Lý Thị Duyên | C18: Lý Thị Duyên | D18: Lý Thị Duyên | E18: Lý Thị Duyên | F18: Lý Thị Duyên | G18: Lê Thị Minh Anh | H18: Lê Thị Minh Anh | I18: Lê Thị Minh Anh | J18: Lê Thị Minh Anh | K18: Ngô Thuý Vân | L18: Lý Thị Duyên | M18: Lý Thị Duyên | N18: Lý Thị Duyên | O18: Lý Thị Duyên | P18: Lý Thị Duyên | Q18: Lý Thị Duyên | R18: Lý Thị Duyên | S18: Lý Thị Duyên | T18: Lý Thị Duyên | U18: Lý Thị Duyên | W18: 0

Sheet SoTiet
A1: ĐỊNH MỨC TIẾT/TUẦN — (C)=chẵn, (L)=lẻ. Môn .5: chẵn=2 lẻ=1
A2: Môn \ Lớp | B2: 6A7 C | C2: 6A8 C | D2: 6A9 C | E2: 6A10 C | F2: 6A11 C | G2: 7A7 C | H2: 7A8 C | I2: 7A9 C | J2: 7A10 C | K2: 7A11 C | L2: 8A7 C | M2: 8A8 C | N2: 8A9 C | O2: 8A10 C | P2: 8A11 C | Q2: 9A8 C | R2: 9A9 C | S2: 9A10 C | T2: 9A11 C | U2: 9A12 C | W2: 6A7 L | X2: 6A8 L | Y2: 6A9 L | Z2: 6A10 L | AA2: 6A11 L | AB2: 7A7 L | AC2: 7A8 L | AD2: 7A9 L | AE2: 7A10 L | AF2: 7A11 L | AG2: 8A7 L | AH2: 8A8 L | AI2: 8A9 L | AJ2: 8A10 L | AK2: 8A11 L | AL2: 9A8 L | AM2: 9A9 L | AN2: 9A10 L | AO2: 9A11 L | AP2: 9A12 L
A3: Toán học | B3: 4 | C3: 4 | D3: 4 | E3: 4 | F3: 4 | G3: 4 | H3: 4 | I3: 4 | J3: 4 | K3: 4 | L3: 4 | M3: 4 | N3: 4 | O3: 4 | P3: 4 | Q3: 4 | R3: 4 | S3: 4 | T3: 4 | U3: 4 | W3: 4 | X3: 4 | Y3: 4 | Z3: 4 | AA3: 4 | AB3: 4 | AC3: 4 | AD3: 4 | AE3: 4 | AF3: 4 | AG3: 4 | AH3: 4 | AI3: 4 | AJ3: 4 | AK3: 4 | AL3: 4 | AM3: 4 | AN3: 4 | AO3: 4 | AP3: 4
A4: Ngữ văn | B4: 4 | C4: 4 | D4: 4 | E4: 4 | F4: 4 | G4: 4 | H4: 4 | I4: 4 | J4: 4 | K4: 4 | L4: 4 | M4: 4 | N4: 4 | O4: 4 | P4: 4 | Q4: 4 | R4: 4 | S4: 4 | T4: 4 | U4: 4 | W4: 4 | X4: 4 | Y4: 4 | Z4: 4 | AA4: 4 | AB4: 4 | AC4: 4 | AD4: 4 | AE4: 4 | AF4: 4 | AG4: 4 | AH4: 4 | AI4: 4 | AJ4: 4 | AK4: 4 | AL4: 4 | AM4: 4 | AN4: 4 | AO4: 4 | AP4: 4
A5: Tiếng Anh | B5: 3 | C5: 3 | D5: 3 | E5: 3 | F5: 3 | G5: 3 | H5: 3 | I5: 3 | J5: 3 | K5: 3 | L5: 3 | M5: 3 | N5: 3 | O5: 3 | P5: 3 | Q5: 3 | R5: 3 | S5: 3 | T5: 3 | U5: 3 | W5: 3 | X5: 3 | Y5: 3 | Z5: 3 | AA5: 3 | AB5: 3 | AC5: 3 | AD5: 3 | AE5: 3 | AF5: 3 | AG5: 3 | AH5: 3 | AI5: 3 | AJ5: 3 | AK5: 3 | AL5: 3 | AM5: 3 | AN5: 3 | AO5: 3 | AP5: 3
A6: Khoa học tự nhiên (Vật lý) | B6: 2 | C6: 2 | D6: 2 | E6: 2 | F6: 2 | G6: 1 | H6: 1 | I6: 1 | J6: 1 | K6: 1 | L6: 1 | M6: 1 | N6: 1 | O6: 1 | P6: 1 | Q6: 2 | R6: 2 | S6: 2 | T6: 2 | U6: 2 | W6: 2 | X6: 2 | Y6: 2 | Z6: 2 | AA6: 2 | AB6: 1 | AC6: 1 | AD6: 1 | AE6: 1 | AF6: 1 | AG6: 1 | AH6: 1 | AI6: 1 | AJ6: 1 | AK6: 1 | AL6: 2 | AM6: 2 | AN6: 2 | AO6: 2 | AP6: 2
A7: Khoa học tự nhiên (Hóa học) | B7: 1 | C7: 1 | D7: 1 | E7: 1 | F7: 1 | G7: 1 | H7: 1 | I7: 1 | J7: 1 | K7: 1 | L7: 1 | M7: 1 | N7: 1 | O7: 1 | P7: 1 | Q7: 1 | R7: 1 | S7: 1 | T7: 1 | U7: 1 | W7: 1 | X7: 1 | Y7: 1 | Z7: 1 | AA7: 1 | AB7: 1 | AC7: 1 | AD7: 1 | AE7: 1 | AF7: 1 | AG7: 1 | AH7: 1 | AI7: 1 | AJ7: 1 | AK7: 1 | AL7: 1 | AM7: 1 | AN7: 1 | AO7: 1 | AP7: 1
A8: Khoa học tự nhiên (Sinh học) | B8: 1 | C8: 1 | D8: 1 | E8: 1 | F8: 1 | G8: 2 | H8: 2 | I8: 2 | J8: 2 | K8: 2 | L8: 2 | M8: 2 | N8: 2 | O8: 2 | P8: 2 | Q8: 1 | R8: 1 | S8: 1 | T8: 1 | U8: 1 | W8: 1 | X8: 1 | Y8: 1 | Z8: 1 | AA8: 1 | AB8: 2 | AC8: 2 | AD8: 2 | AE8: 2 | AF8: 2 | AG8: 2 | AH8: 2 | AI8: 2 | AJ8: 2 | AK8: 2 | AL8: 1 | AM8: 1 | AN8: 1 | AO8: 1 | AP8: 1
A9: Lịch sử và Địa Lý (Lịch sử) | B9: 1 | C9: 1 | D9: 1 | E9: 1 | F9: 1 | G9: 2 | H9: 2 | I9: 2 | J9: 2 | K9: 2 | L9: 1 | M9: 1 | N9: 1 | O9: 1 | P9: 1 | Q9: 2 | R9: 2 | S9: 2 | T9: 2 | U9: 2 | W9: 1 | X9: 1 | Y9: 1 | Z9: 1 | AA9: 1 | AB9: 2 | AC9: 2 | AD9: 2 | AE9: 2 | AF9: 2 | AG9: 1 | AH9: 1 | AI9: 1 | AJ9: 1 | AK9: 1 | AL9: 2 | AM9: 2 | AN9: 2 | AO9: 2 | AP9: 2
A10: Lịch sử và Địa Lý (Địa lý) | B10: 2 | C10: 2 | D10: 2 | E10: 2 | F10: 2 | G10: 1 | H10: 1 | I10: 1 | J10: 1 | K10: 1 | L10: 2 | M10: 2 | N10: 2 | O10: 2 | P10: 2 | Q10: 1 | R10: 1 | S10: 1 | T10: 1 | U10: 1 | W10: 2 | X10: 2 | Y10: 2 | Z10: 2 | AA10: 2 | AB10: 1 | AC10: 1 | AD10: 1 | AE10: 1 | AF10: 1 | AG10: 2 | AH10: 2 | AI10: 2 | AJ10: 2 | AK10: 2 | AL10: 1 | AM10: 1 | AN10: 1 | AO10: 1 | AP10: 1
A11: GDCD | B11: 1 | C11: 1 | D11: 1 | E11: 1 | F11: 1 | G11: 1 | H11: 1 | I11: 1 | J11: 1 | K11: 1 | L11: 1 | M11: 1 | N11: 1 | O11: 1 | P11: 1 | Q11: 1 | R11: 1 | S11: 1 | T11: 1 | U11: 1 | W11: 1 | X11: 1 | Y11: 1 | Z11: 1 | AA11: 1 | AB11: 1 | AC11: 1 | AD11: 1 | AE11: 1 | AF11: 1 | AG11: 1 | AH11: 1 | AI11: 1 | AJ11: 1 | AK11: 1 | AL11: 1 | AM11: 1 | AN11: 1 | AO11: 1 | AP11: 1
A12: Công nghệ | B12: 1 | C12: 1 | D12: 1 | E12: 1 | F12: 1 | G12: 1 | H12: 1 | I12: 1 | J12: 1 | K12: 1 | L12: 1 | M12: 1 | N12: 1 | O12: 1 | P12: 1 | Q12: 2 | R12: 2 | S12: 2 | T12: 2 | U12: 2 | W12: 1 | X12: 1 | Y12: 1 | Z12: 1 | AA12: 1 | AB12: 1 | AC12: 1 | AD12: 1 | AE12: 1 | AF12: 1 | AG12: 1 | AH12: 1 | AI12: 1 | AJ12: 1 | AK12: 1 | AL12: 2 | AM12: 2 | AN12: 2 | AO12: 2 | AP12: 2
A13: Tin học | B13: 1 | C13: 1 | D13: 1 | E13: 1 | F13: 1 | G13: 1 | H13: 1 | I13: 1 | J13: 1 | K13: 1 | L13: 1 | M13: 1 | N13: 1 | O13: 1 | P13: 1 | Q13: 1 | R13: 1 | S13: 1 | T13: 1 | U13: 1 | W13: 1 | X13: 1 | Y13: 1 | Z13: 1 | AA13: 1 | AB13: 1 | AC13: 1 | AD13: 1 | AE13: 1 | AF13: 1 | AG13: 1 | AH13: 1 | AI13: 1 | AJ13: 1 | AK13: 1 | AL13: 1 | AM13: 1 | AN13: 1 | AO13: 1 | AP13: 1
A14: Giáo dục thể chất | B14: 2 | C14: 2 | D14: 2 | E14: 2 | F14: 2 | G14: 2 | H14: 2 | I14: 2 | J14: 2 | K14: 2 | L14: 2 | M14: 2 | N14: 2 | O14: 2 | P14: 2 | Q14: 2 | R14: 2 | S14: 2 | T14: 2 | U14: 2 | W14: 2 | X14: 2 | Y14: 2 | Z14: 2 | AA14: 2 | AB14: 2 | AC14: 2 | AD14: 2 | AE14: 2 | AF14: 2 | AG14: 2 | AH14: 2 | AI14: 2 | AJ14: 2 | AK14: 2 | AL14: 2 | AM14: 2 | AN14: 2 | AO14: 2 | AP14: 2
... A18: Nghệ thuật (Mỹ thuật) | B18: 1 | C18: 1 | D18: 1 | E18: 1 | F18: 1 | G18: 1 | H18: 1 | I18: 1 | J18: 1 | K18: 1 | L18: 1 | M18: 1 | N18: 1 | O18: 1 | P18: 1 | Q18: 1 | R18: 1 | S18: 1 | T18: 1 | U18: 1 | W18: 1 | X18: 1 | Y18: 1 | Z18: 1 | AA18: 1 | AB18: 1 | AC18: 1 | AD18: 1 | AE18: 1 | AF18: 1 | AG18: 1 | AH18: 1 | AI18: 1 | AJ18: 1 | AK18: 1 | AL18: 1 | AM18: 1 | AN18: 1 | AO18: 1 | AP18: 1

Sheet GV_Ban
A1: GIÁO VIÊN BẬN / XIN NGHỈ — macro né các khung giờ này, chỉ đổi tối thiểu số tiết

Sheet DinhMuc_GV
A1: ĐỊNH MỨC GIÁO VIÊN — Vượt>0 (đỏ)=quá tải. Chức vụ điền sẵn từ Sheet2. | H1: Chuẩn: | I1: 19 | K1: Chức vụ | L1: Giảm | N1: Chuẩn: | O1: 19 | Q1: Sàn tối thiểu: | R1: 15
A2: Tên GV | B2: Chức vụ | C2: Giảm trừ | D2: Trần | E2: Tải Chẵn | F2: Tải Lẻ | G2: Vượt (Chẵn) | H2: Đi T2 (1/0) | I2: GVCN (1/0) | K2: Hiệu trưởng | L2: 17
A3: Đỗ Thị Sa | B3: Hiệu trưởng | H3: 1 | I3: 0 | K3: Phó hiệu trưởng | L3: 15
A4: Đoàn Tiến Quân | B4: Phó hiệu trưởng | H4: 1 | I4: 0 | K4: Tổ trưởng | L4: 3
A5: Phan Thị Thùy Linh | B5: Tổ trưởng | H5: 1 | I5: 1 | K5: Tổ phó | L5: 1
A6: Nguyễn Thị Thu Hương | B6: GVCN | H6: 1 | I6: 1 | K6: GVCN | L6: 4
A7: Đồng Thị Hiền | B7: GVCN | H7: 1 | I7: 1 | K7: Tổng phụ trách | L7: 8
A8: Hoàng Thị Phương Duyên | B8: GVCN | H8: 1 | I8: 1 | K8: Thư ký HĐ | L8: 2
A9: Ngô Thị Xuân Hương | B9: GVCN | H9: 1 | I9: 1
A10: Bùi Thị Mỹ Hạnh | B10: GVCN | H10: 1 | I10: 1
A11: Triệu Thị Luyến | B11: GVCN | H11: 1 | I11: 1
A12: Hoàng Thị Kiều Loan | B12: HĐ235 | H12: 1 | I12: 0
A13: Bàng Thị Phượng | B13: HĐ235 | H13: 1 | I13: 0
A14: Nông Thị Trà | B14: HĐ235 | H14: 1 | I14: 0
A15: Bùi Thị Hòa | B15: GVCN | H15: 1 | I15: 1
A16: Lại Thị Thanh Huyền | B16: Tổ phó | H16: 1 | I16: 1
A17: Nguyễn Thị Hà | B17: GVCN | H17: 1 | I17: 1
A18: Mẫn Xuân Thắng | H18: 1 | I18: 0
A19: Phùng Thị Lan | B19: GVCN | H19: 1 | I19: 1
A20: Hoàng Thị Thanh Thắm | B20: GVCN | H20: 1 | I20: 1
A21: Lê Thị Thu Hằng | B21: HĐ235 / GVCN | H21: 1 | I21: 1
A22: Nguyễn Thị Hiền | B22: HĐ235 | H22: 1 | I22: 0
A23: Lương Thị Thu Hiền | B23: HĐ235 | H23: 1 | I23: 0
A24: Hà Thị Hải Yến | B24: Tổ phó | H24: 1 | I24: 1
A25: Trần Thị Liễu | B25: HĐK | H25: 1 | I25: 0
A26: Trần Thị Quỳnh Hằng | B26: HĐK | H26: 1 | I26: 0
A27: Nguyễn Ánh Hồng | B27: HĐK | H27: 1 | I27: 0
A28: Vũ Thị Bích Hằng | H28: 1 | I28: 0
A29: Chu Diệu Linh | B29: GVCN | H29: 1 | I29: 1
A30: Trương Thị Thu Hương | B30: GVCN | H30: 1 | I30: 1
A31: Đỗ Thị Thu Hiền | H31: 1 | I31: 0
A32: Lê Văn Hậu | H32: 1 | I32: 0
A33: GV môn GDTC | H33: 1 | I33: 0
A34: Bùi Đức Anh | B34: Trường chính | H34: 1 | I34: 0
A35: Lý Thị Duyên | B35: GVCN | H35: 1 | I35: 1
A36: Lê Thị Minh Anh | B36: HĐK | H36: 1 | I36: 0
A37: Ngô Thuý Vân | B37: Tổng phụ trách | H37: 1 | I37: 0
A38: Nguyễn Thị Luyến | H38: 1 | I38: 0
A39: Nguyễn Đình Tiến | B39: GVCN | H39: 1 | I39: 1
A40: Phan Thị Minh | B40: Tổ phó | H40: 1 | I40: 1
...

Sheet TKB_Nhap
A1: LỚP HỌC | B1: BUỔI | C1: TIẾT THỨ | D1: Thứ 2 | E1: Thứ 3 | F1: Thứ 4 | G1: Thứ 5 | H1: Thứ 6 | I1: Thứ 7 | J1: Chủ Nhật
A2: 6A7 | B2: S | C2: 1
A3: 6A7 | B3: S | C3: 2
A4: 6A7 | B4: S | C4: 3
A5: 6A7 | B5: S | C5: 4
A6: 6A7 | B6: S | C6: 5
A7: 6A7 | B7: C | C7: 1
A8: 6A7 | B8: C | C8: 2
A9: 6A7 | B9: C | C9: 3
A10: 6A8 | B10: S | C10: 1
A11: 6A8 | B11: S | C11: 2
A12: 6A8 | B12: S | C12: 3
A13: 6A8 | B13: S | C13: 4
... A161: 9A12 | B161: C | C161: 3

Sheet TKB
A1: LỚP HỌC | B1: BUỔI | C1: TIẾT THỨ | D1: THỨ 2 | E1: THỨ 3 | F1: THỨ 4 | G1: THỨ 5 | H1: THỨ 6 | I1: THỨ 7 | J1: CHỦ NHẬT
A2: =TKB_Nhap!A2 | B2: =TKB_Nhap!B2 | C2: =TKB_Nhap!C2 | D2: =IF(TKB_Nhap!D2="","",TKB_Nhap!D2&CHAR(10)&IF(T(INDEX(PhanCong!$B$3:$I$18,MATCH(TKB_Nhap!D2,PhanCong!$A$3:$A$18,0),MATCH($A2,PhanCong!$B$2:$I$2,0)))="","(chưa PC GV)","GV: "&INDEX(PhanCong!$B$3:$I$18,MATCH(TKB_Nhap!D2,PhanCong!$A$3:$A$18,0),MATCH($A2,PhanCong!$B$2:$I$2,0)))) | E2: =IF(TKB_Nhap!E2="","",TKB_Nhap!E2&CHAR(10)&IF(T(INDEX(PhanCong!$B$3:$I$18,MATCH(TKB_Nhap!E2,PhanCong!$A$3:$A$18,0),MATCH($A2,PhanCong!$B$2:$I$2,0)))="","(chưa PC GV)","GV: "&INDEX(PhanCong!$B$3:$I$18,MATCH(TKB_Nhap!E2,PhanCong!$A$3:$A$18,0),MATCH($A2,PhanCong!$B$2:$I$2,0)))) | F2: =IF(TKB_Nhap!F2="","",TKB_Nhap!F2&CHAR(10)&IF(T(INDEX(PhanCong!$B$3:$I$18,MATCH(TKB_Nhap!F2,PhanCong!$A$3:$A$18,0),MATCH($A2,PhanCong!$B$2:$I$2,0)))="","(chưa PC GV)","GV: "&INDEX(PhanCong!$B$3:$I$18,MATCH(TKB_Nhap!F2,PhanCong!$A$3:$A$18,0),MATCH($A2,PhanCong!$B$2:$I$2,0)))) | G2: =IF(TKB_Nhap!G2="","",TKB_Nhap!G2&CHAR(10)&IF(T(INDEX(PhanCong!$B$3:$I$18,MATCH(TKB_Nhap!G2,PhanCong!$A$3:$A$18,0),MATCH($A2,PhanCong!$B$2:$I$2,0)))="","(chưa PC GV)","GV: "&INDEX(PhanCong!$B$3:$I$18,MATCH(TKB_Nhap!G2,PhanCong!$A$3:$A$18,0),MATCH($A2,PhanCong!$B$2:$I$2,0)))) | H2: =IF(TKB_Nhap!H2="","",TKB_Nhap!H2&CHAR(10)&IF(T(INDEX(PhanCong!$B$3:$I$18,MATCH(TKB_Nhap!H2,PhanCong!$A$3:$A$18,0),MATCH($A2,PhanCong!$B$2:$I$2,0)))="","(chưa PC GV)","GV: "&INDEX(PhanCong!$B$3:$I$18,MATCH(TKB_Nhap!H2,PhanCong!$A$3:$A$18,0),MATCH($A2,PhanCong!$B$2:$I$2,0)))) | I2: =IF(TKB_Nhap!I2="","",TKB_Nhap!I2&CHAR(10)&IF(T(INDEX(PhanCong!$B$3:$I$18,MATCH(TKB_Nhap!I2,PhanCong!$A$3:$A$18,0),MATCH($A2,PhanCong!$B$2:$I$2,0)))="","(chưa PC GV)","GV: "&INDEX(PhanCong!$B$3:$I$18,MATCH(TKB_Nhap!I2,PhanCong!$A$3:$A$18,0),MATCH($A2,PhanCong!$B$2:$I$2,0))))
A3: =TKB_Nhap!A3 | B3: =TKB_Nhap!B3 | C3: =TKB_Nhap!C3 | D3: =IF(TKB_Nhap!D3="","",TKB_Nhap!D3&CHAR(10)&IF(T(INDEX(PhanCong!$B$3:$I$18,MATCH(TKB_Nhap!D3,PhanCong!$A$3:$A$18,0),MATCH($A3,PhanCong!$B$2:$I$2,0)))="","(chưa PC GV)","GV: "&INDEX(PhanCong!$B$3:$I$18,MATCH(TKB_Nhap!D3,PhanCong!$A$3:$A$18,0),MATCH($A3,PhanCong!$B$2:$I$2,0)))) | E3: =IF(TKB_Nhap!E3="","",TKB_Nhap!E3&CHAR(10)&IF(T(INDEX(PhanCong!$B$3:$I$18,MATCH(TKB_Nhap!E3,PhanCong!$A$3:$A$18,0),MATCH($A3,PhanCong!$B$2:$I$2,0)))="","(chưa PC GV)","GV: "&INDEX(PhanCong!$B$3:$I$18,MATCH(TKB_Nhap!E3,PhanCong!$A$3:$A$18,0),MATCH($A3,PhanCong!$B$2:$I$2,0)))) | F3: =IF(TKB_Nhap!F3="","",TKB_Nhap!F3&CHAR(10)&IF(T(INDEX(PhanCong!$B$3:$I$18,MATCH(TKB_Nhap!F3,PhanCong!$A$3:$A$18,0),MATCH($A3,PhanCong!$B$2:$I$2,0)))="","(chưa PC GV)","GV: "&INDEX(PhanCong!$B$3:$I$18,MATCH(TKB_Nhap!F3,PhanCong!$A$3:$A$18,0),MATCH($A3,PhanCong!$B$2:$I$2,0)))) | G3: =IF(TKB_Nhap!G3="","",TKB_Nhap!G3&CHAR(10)&IF(T(INDEX(PhanCong!$B$3:$I$18,MATCH(TKB_Nhap!G3,PhanCong!$A$3:$A$18,0),MATCH($A3,PhanCong!$B$2:$I$2,0)))="","(chưa PC GV)","GV: "&INDEX(PhanCong!$B$3:$I$18,MATCH(TKB_Nhap!G3,PhanCong!$A$3:$A$18,0),MATCH($A3,PhanCong!$B$2:$I$2,0)))) | H3: =IF(TKB_Nhap!H3="","",TKB_Nhap!H3&CHAR(10)&IF(T(INDEX(PhanCong!$B$3:$I$18,MATCH(TKB_Nhap!H3,PhanCong!$A$3:$A$18,0),MATCH($A3,PhanCong!$B$2:$I$2,0)))="","(chưa PC GV)","GV: "&INDEX(PhanCong!$B$3:$I$18,MATCH(TKB_Nhap!H3,PhanCong!$A$3:$A$18,0),MATCH($A3,PhanCong!$B$2:$I$2,0)))) | I3: =IF(TKB_Nhap!I3="","",TKB_Nhap!I3&CHAR(10)&IF(T(INDEX(PhanCong!$B$3:$I$18,MATCH(TKB_Nhap!I3,PhanCong!$A$3:$A$18,0),MATCH($A3,PhanCong!$B$2:$I$2,0)))="","(chưa PC GV)","GV: "&INDEX(PhanCong!$B$3:$I$18,MATCH(TKB_Nhap!I3,PhanCong!$A$3:$A$18,0),MATCH($A3,PhanCong!$B$2:$I$2,0))))
A4: =TKB_Nhap!A4 | B4: =TKB_Nhap!B4 | C4: =TKB_Nhap!C4 | D4: =IF(TKB_Nhap!D4="","",TKB_Nhap!D4&CHAR(10)&IF(T(INDEX(PhanCong!$B$3:$I$18,MATCH(TKB_Nhap!D4,PhanCong!$A$3:$A$18,0),MATCH($A4,PhanCong!$B$2:$I$2,0)))="","(chưa PC GV)","GV: "&INDEX(PhanCong!$B$3:$I$18,MATCH(TKB_Nhap!D4,PhanCong!$A$3:$A$18,0),MATCH($A4,PhanCong!$B$2:$I$2,0)))) | E4: =IF(TKB_Nhap!E4="","",TKB_Nhap!E4&CHAR(10)&IF(T(INDEX(PhanCong!$B$3:$I$18,MATCH(TKB_Nhap!E4,PhanCong!$A$3:$A$18,0),MATCH($A4,PhanCong!$B$2:$I$2,0)))="","(chưa PC GV)","GV: "&INDEX(PhanCong!$B$3:$I$18,MATCH(TKB_Nhap!E4,PhanCong!$A$3:$A$18,0),MATCH($A4,PhanCong!$B$2:$I$2,0)))) | F4: =IF(TKB_Nhap!F4="","",TKB_Nhap!F4&CHAR(10)&IF(T(INDEX(PhanCong!$B$3:$I$18,MATCH(TKB_Nhap!F4,PhanCong!$A$3:$A$18,0),MATCH($A4,PhanCong!$B$2:$I$2,0)))="","(chưa PC GV)","GV: "&INDEX(PhanCong!$B$3:$I$18,MATCH(TKB_Nhap!F4,PhanCong!$A$3:$A$18,0),MATCH($A4,PhanCong!$B$2:$I$2,0)))) | G4: =IF(TKB_Nhap!G4="","",TKB_Nhap!G4&CHAR(10)&IF(T(INDEX(PhanCong!$B$3:$I$18,MATCH(TKB_Nhap!G4,PhanCong!$A$3:$A$18,0),MATCH($A4,PhanCong!$B$2:$I$2,0)))="","(chưa PC GV)","GV: "&INDEX(PhanCong!$B$3:$I$18,MATCH(TKB_Nhap!G4,PhanCong!$A$3:$A$18,0),MATCH($A4,PhanCong!$B$2:$I$2,0)))) | H4: =IF(TKB_Nhap!H4="","",TKB_Nhap!H4&CHAR(10)&IF(T(INDEX(PhanCong!$B$3:$I$18,MATCH(TKB_Nhap!H4,PhanCong!$A$3:$A$18,0),MATCH($A4,PhanCong!$B$2:$I$2,0)))="","(chưa PC GV)","GV: "&INDEX(PhanCong!$B$3:$I$18,MATCH(TKB_Nhap!H4,PhanCong!$A$3:$A$18,0),MATCH($A4,PhanCong!$B$2:$I$2,0)))) | I4: =IF(TKB_Nhap!I4="","",TKB_Nhap!I4&CHAR(10)&IF(T(INDEX(PhanCong!$B$3:$I$18,MATCH(TKB_Nhap!I4,PhanCong!$A$3:$A$18,0),MATCH($A4,PhanCong!$B$2:$I$2,0)))="","(chưa PC GV)","GV: "&INDEX(PhanCong!$B$3:$I$18,MATCH(TKB_Nhap!I4,PhanCong!$A$3:$A$18,0),MATCH($A4,PhanCong!$B$2:$I$2,0))))
A5: =TKB_Nhap!A5 | B5: =TKB_Nhap!B5 | C5: =TKB_Nhap!C5 | D5: =IF(TKB_Nhap!D5="","",TKB_Nhap!D5&CHAR(10)&IF(T(INDEX(PhanCong!$B$3:$I$18,MATCH(TKB_Nhap!D5,PhanCong!$A$3:$A$18,0),MATCH($A5,PhanCong!$B$2:$I$2,0)))="","(chưa PC GV)","GV: "&INDEX(PhanCong!$B$3:$I$18,MATCH(TKB_Nhap!D5,PhanCong!$A$3:$A$18,0),MATCH($A5,PhanCong!$B$2:$I$2,0)))) | E5: =IF(TKB_Nhap!E5="","",TKB_Nhap!E5&CHAR(10)&IF(T(INDEX(PhanCong!$B$3:$I$18,MATCH(TKB_Nhap!E5,PhanCong!$A$3:$A$18,0),MATCH($A5,PhanCong!$B$2:$I$2,0)))="","(chưa PC GV)","GV: "&INDEX(PhanCong!$B$3:$I$18,MATCH(TKB_Nhap!E5,PhanCong!$A$3:$A$18,0),MATCH($A5,PhanCong!$B$2:$I$2,0)))) | F5: =IF(TKB_Nhap!F5="","",TKB_Nhap!F5&CHAR(10)&IF(T(INDEX(PhanCong!$B$3:$I$18,MATCH(TKB_Nhap!F5,PhanCong!$A$3:$A$18,0),MATCH($A5,PhanCong!$B$2:$I$2,0)))="","(chưa PC GV)","GV: "&INDEX(PhanCong!$B$3:$I$18,MATCH(TKB_Nhap!F5,PhanCong!$A$3:$A$18,0),MATCH($A5,PhanCong!$B$2:$I$2,0)))) | G5: =IF(TKB_Nhap!G5="","",TKB_Nhap!G5&CHAR(10)&IF(T(INDEX(PhanCong!$B$3:$I$18,MATCH(TKB_Nhap!G5,PhanCong!$A$3:$A$18,0),MATCH($A5,PhanCong!$B$2:$I$2,0)))="","(chưa PC GV)","GV: "&INDEX(PhanCong!$B$3:$I$18,MATCH(TKB_Nhap!G5,PhanCong!$A$3:$A$18,0),MATCH($A5,PhanCong!$B$2:$I$2,0)))) | H5: =IF(TKB_Nhap!H5="","",TKB_Nhap!H5&CHAR(10)&IF(T(INDEX(PhanCong!$B$3:$I$18,MATCH(TKB_Nhap!H5,PhanCong!$A$3:$A$18,0),MATCH($A5,PhanCong!$B$2:$I$2,0)))="","(chưa PC GV)","GV: "&INDEX(PhanCong!$B$3:$I$18,MATCH(TKB_Nhap!H5,PhanCong!$A$3:$A$18,0),MATCH($A5,PhanCong!$B$2:$I$2,0)))) | I5: =IF(TKB_Nhap!I5="","",TKB_Nhap!I5&CHAR(10)&IF(T(INDEX(PhanCong!$B$3:$I$18,MATCH(TKB_Nhap!I5,PhanCong!$A$3:$A$18,0),MATCH($A5,PhanCong!$B$2:$I$2,0)))="","(chưa PC GV)","GV: "&INDEX(PhanCong!$B$3:$I$18,MATCH(TKB_Nhap!I5,PhanCong!$A$3:$A$18,0),MATCH($A5,PhanCong!$B$2:$I$2,0))))
A6: =TKB_Nhap!A6 | B6: =TKB_Nhap!B6 | C6: =TKB_Nhap!C6 | D6: =IF(TKB_Nhap!D6="","",TKB_Nhap!D6&CHAR(10)&IF(T(INDEX(PhanCong!$B$3:$I$18,MATCH(TKB_Nhap!D6,PhanCong!$A$3:$A$18,0),MATCH($A6,PhanCong!$B$2:$I$2,0)))="","(chưa PC GV)","GV: "&INDEX(PhanCong!$B$3:$I$18,MATCH(TKB_Nhap!D6,PhanCong!$A$3:$A$18,0),MATCH($A6,PhanCong!$B$2:$I$2,0)))) | E6: =IF(TKB_Nhap!E6="","",TKB_Nhap!E6&CHAR(10)&IF(T(INDEX(PhanCong!$B$3:$I$18,MATCH(TKB_Nhap!E6,PhanCong!$A$3:$A$18,0),MATCH($A6,PhanCong!$B$2:$I$2,0)))="","(chưa PC GV)","GV: "&INDEX(PhanCong!$B$3:$I$18,MATCH(TKB_Nhap!E6,PhanCong!$A$3:$A$18,0),MATCH($A6,PhanCong!$B$2:$I$2,0)))) | F6: =IF(TKB_Nhap!F6="","",TKB_Nhap!F6&CHAR(10)&IF(T(INDEX(PhanCong!$B$3:$I$18,MATCH(TKB_Nhap!F6,PhanCong!$A$3:$A$18,0),MATCH($A6,PhanCong!$B$2:$I$2,0)))="","(chưa PC GV)","GV: "&INDEX(PhanCong!$B$3:$I$18,MATCH(TKB_Nhap!F6,PhanCong!$A$3:$A$18,0),MATCH($A6,PhanCong!$B$2:$I$2,0)))) | G6: =IF(TKB_Nhap!G6="","",TKB_Nhap!G6&CHAR(10)&IF(T(INDEX(PhanCong!$B$3:$I$18,MATCH(TKB_Nhap!G6,PhanCong!$A$3:$A$18,0),MATCH($A6,PhanCong!$B$2:$I$2,0)))="","(chưa PC GV)","GV: "&INDEX(PhanCong!$B$3:$I$18,MATCH(TKB_Nhap!G6,PhanCong!$A$3:$A$18,0),MATCH($A6,PhanCong!$B$2:$I$2,0)))) | H6: =IF(TKB_Nhap!H6="","",TKB_Nhap!H6&CHAR(10)&IF(T(INDEX(PhanCong!$B$3:$I$18,MATCH(TKB_Nhap!H6,PhanCong!$A$3:$A$18,0),MATCH($A6,PhanCong!$B$2:$I$2,0)))="","(chưa PC GV)","GV: "&INDEX(PhanCong!$B$3:$I$18,MATCH(TKB_Nhap!H6,PhanCong!$A$3:$A$18,0),MATCH($A6,PhanCong!$B$2:$I$2,0)))) | I6: =IF(TKB_Nhap!I6="","",TKB_Nhap!I6&CHAR(10)&IF(T(INDEX(PhanCong!$B$3:$I$18,MATCH(TKB_Nhap!I6,PhanCong!$A$3:$A$18,0),MATCH($A6,PhanCong!$B$2:$I$2,0)))="","(chưa PC GV)","GV: "&INDEX(PhanCong!$B$3:$I$18,MATCH(TKB_Nhap!I6,PhanCong!$A$3:$A$18,0),MATCH($A6,PhanCong!$B$2:$I$2,0))))
A7: =TKB_Nhap!A7 | B7: =TKB_Nhap!B7 | C7: =TKB_Nhap!C7 | D7: =IF(TKB_Nhap!D7="","",TKB_Nhap!D7&CHAR(10)&IF(T(INDEX(PhanCong!$B$3:$I$18,MATCH(TKB_Nhap!D7,PhanCong!$A$3:$A$18,0),MATCH($A7,PhanCong!$B$2:$I$2,0)))="","(chưa PC GV)","GV: "&INDEX(PhanCong!$B$3:$I$18,MATCH(TKB_Nhap!D7,PhanCong!$A$3:$A$18,0),MATCH($A7,PhanCong!$B$2:$I$2,0)))) | E7: =IF(TKB_Nhap!E7="","",TKB_Nhap!E7&CHAR(10)&IF(T(INDEX(PhanCong!$B$3:$I$18,MATCH(TKB_Nhap!E7,PhanCong!$A$3:$A$18,0),MATCH($A7,PhanCong!$B$2:$I$2,0)))="","(chưa PC GV)","GV: "&INDEX(PhanCong!$B$3:$I$18,MATCH(TKB_Nhap!E7,PhanCong!$A$3:$A$18,0),MATCH($A7,PhanCong!$B$2:$I$2,0)))) | F7: =IF(TKB_Nhap!F7="","",TKB_Nhap!F7&CHAR(10)&IF(T(INDEX(PhanCong!$B$3:$I$18,MATCH(TKB_Nhap!F7,PhanCong!$A$3:$A$18,0),MATCH($A7,PhanCong!$B$2:$I$2,0)))="","(chưa PC GV)","GV: "&INDEX(PhanCong!$B$3:$I$18,MATCH(TKB_Nhap!F7,PhanCong!$A$3:$A$18,0),MATCH($A7,PhanCong!$B$2:$I$2,0)))) | G7: =IF(TKB_Nhap!G7="","",TKB_Nhap!G7&CHAR(10)&IF(T(INDEX(PhanCong!$B$3:$I$18,MATCH(TKB_Nhap!G7,PhanCong!$A$3:$A$18,0),MATCH($A7,PhanCong!$B$2:$I$2,0)))="","(chưa PC GV)","GV: "&INDEX(PhanCong!$B$3:$I$18,MATCH(TKB_Nhap!G7,PhanCong!$A$3:$A$18,0),MATCH($A7,PhanCong!$B$2:$I$2,0)))) | H7: =IF(TKB_Nhap!H7="","",TKB_Nhap!H7&CHAR(10)&IF(T(INDEX(PhanCong!$B$3:$I$18,MATCH(TKB_Nhap!H7,PhanCong!$A$3:$A$18,0),MATCH($A7,PhanCong!$B$2:$I$2,0)))="","(chưa PC GV)","GV: "&INDEX(PhanCong!$B$3:$I$18,MATCH(TKB_Nhap!H7,PhanCong!$A$3:$A$18,0),MATCH($A7,PhanCong!$B$2:$I$2,0)))) | I7: =IF(TKB_Nhap!I7="","",TKB_Nhap!I7&CHAR(10)&IF(T(INDEX(PhanCong!$B$3:$I$18,MATCH(TKB_Nhap!I7,PhanCong!$A$3:$A$18,0),MATCH($A7,PhanCong!$B$2:$I$2,0)))="","(chưa PC GV)","GV: "&INDEX(PhanCong!$B$3:$I$18,MATCH(TKB_Nhap!I7,PhanCong!$A$3:$A$18,0),MATCH($A7,PhanCong!$B$2:$I$2,0))))
A8: =TKB_Nhap!A8 | B8: =TKB_Nhap!B8 | C8: =TKB_Nhap!C8 | D8: =IF(TKB_Nhap!D8="","",TKB_Nhap!D8&CHAR(10)&IF(T(INDEX(PhanCong!$B$3:$I$18,MATCH(TKB_Nhap!D8,PhanCong!$A$3:$A$18,0),MATCH($A8,PhanCong!$B$2:$I$2,0)))="","(chưa PC GV)","GV: "&INDEX(PhanCong!$B$3:$I$18,MATCH(TKB_Nhap!D8,PhanCong!$A$3:$A$18,0),MATCH($A8,PhanCong!$B$2:$I$2,0)))) | E8: =IF(TKB_Nhap!E8="","",TKB_Nhap!E8&CHAR(10)&IF(T(INDEX(PhanCong!$B$3:$I$18,MATCH(TKB_Nhap!E8,PhanCong!$A$3:$A$18,0),MATCH($A8,PhanCong!$B$2:$I$2,0)))="","(chưa PC GV)","GV: "&INDEX(PhanCong!$B$3:$I$18,MATCH(TKB_Nhap!E8,PhanCong!$A$3:$A$18,0),MATCH($A8,PhanCong!$B$2:$I$2,0)))) | F8: =IF(TKB_Nhap!F8="","",TKB_Nhap!F8&CHAR(10)&IF(T(INDEX(PhanCong!$B$3:$I$18,MATCH(TKB_Nhap!F8,PhanCong!$A$3:$A$18,0),MATCH($A8,PhanCong!$B$2:$I$2,0)))="","(chưa PC GV)","GV: "&INDEX(PhanCong!$B$3:$I$18,MATCH(TKB_Nhap!F8,PhanCong!$A$3:$A$18,0),MATCH($A8,PhanCong!$B$2:$I$2,0)))) | G8: =IF(TKB_Nhap!G8="","",TKB_Nhap!G8&CHAR(10)&IF(T(INDEX(PhanCong!$B$3:$I$18,MATCH(TKB_Nhap!G8,PhanCong!$A$3:$A$18,0),MATCH($A8,PhanCong!$B$2:$I$2,0)))="","(chưa PC GV)","GV: "&INDEX(PhanCong!$B$3:$I$18,MATCH(TKB_Nhap!G8,PhanCong!$A$3:$A$18,0),MATCH($A8,PhanCong!$B$2:$I$2,0)))) | H8: =IF(TKB_Nhap!H8="","",TKB_Nhap!H8&CHAR(10)&IF(T(INDEX(PhanCong!$B$3:$I$18,MATCH(TKB_Nhap!H8,PhanCong!$A$3:$A$18,0),MATCH($A8,PhanCong!$B$2:$I$2,0)))="","(chưa PC GV)","GV: "&INDEX(PhanCong!$B$3:$I$18,MATCH(TKB_Nhap!H8,PhanCong!$A$3:$A$18,0),MATCH($A8,PhanCong!$B$2:$I$2,0)))) | I8: =IF(TKB_Nhap!I8="","",TKB_Nhap!I8&CHAR(10)&IF(T(INDEX(PhanCong!$B$3:$I$18,MATCH(TKB_Nhap!I8,PhanCong!$A$3:$A$18,0),MATCH($A8,PhanCong!$B$2:$I$2,0)))="","(chưa PC GV)","GV: "&INDEX(PhanCong!$B$3:$I$18,MATCH(TKB_Nhap!I8,PhanCong!$A$3:$A$18,0),MATCH($A8,PhanCong!$B$2:$I$2,0))))
A9: =TKB_Nhap!A9 | B9: =TKB_Nhap!B9 | C9: =TKB_Nhap!C9 | D9: =IF(TKB_Nhap!D9="","",TKB_Nhap!D9&CHAR(10)&IF(T(INDEX(PhanCong!$B$3:$I$18,MATCH(TKB_Nhap!D9,PhanCong!$A$3:$A$18,0),MATCH($A9,PhanCong!$B$2:$I$2,0)))="","(chưa PC GV)","GV: "&INDEX(PhanCong!$B$3:$I$18,MATCH(TKB_Nhap!D9,PhanCong!$A$3:$A$18,0),MATCH($A9,PhanCong!$B$2:$I$2,0)))) | E9: =IF(TKB_Nhap!E9="","",TKB_Nhap!E9&CHAR(10)&IF(T(INDEX(PhanCong!$B$3:$I$18,MATCH(TKB_Nhap!E9,PhanCong!$A$3:$A$18,0),MATCH($A9,PhanCong!$B$2:$I$2,0)))="","(chưa PC GV)","GV: "&INDEX(PhanCong!$B$3:$I$18,MATCH(TKB_Nhap!E9,PhanCong!$A$3:$A$18,0),MATCH($A9,PhanCong!$B$2:$I$2,0)))) | F9: =IF(TKB_Nhap!F9="","",TKB_Nhap!F9&CHAR(10)&IF(T(INDEX(PhanCong!$B$3:$I$18,MATCH(TKB_Nhap!F9,PhanCong!$A$3:$A$18,0),MATCH($A9,PhanCong!$B$2:$I$2,0)))="","(chưa PC GV)","GV: "&INDEX(PhanCong!$B$3:$I$18,MATCH(TKB_Nhap!F9,PhanCong!$A$3:$A$18,0),MATCH($A9,PhanCong!$B$2:$I$2,0)))) | G9: =IF(TKB_Nhap!G9="","",TKB_Nhap!G9&CHAR(10)&IF(T(INDEX(PhanCong!$B$3:$I$18,MATCH(TKB_Nhap!G9,PhanCong!$A$3:$A$18,0),MATCH($A9,PhanCong!$B$2:$I$2,0)))="","(chưa PC GV)","GV: "&INDEX(PhanCong!$B$3:$I$18,MATCH(TKB_Nhap!G9,PhanCong!$A$3:$A$18,0),MATCH($A9,PhanCong!$B$2:$I$2,0)))) | H9: =IF(TKB_Nhap!H9="","",TKB_Nhap!H9&CHAR(10)&IF(T(INDEX(PhanCong!$B$3:$I$18,MATCH(TKB_Nhap!H9,PhanCong!$A$3:$A$18,0),MATCH($A9,PhanCong!$B$2:$I$2,0)))="","(chưa PC GV)","GV: "&INDEX(PhanCong!$B$3:$I$18,MATCH(TKB_Nhap!H9,PhanCong!$A$3:$A$18,0),MATCH($A9,PhanCong!$B$2:$I$2,0)))) | I9: =IF(TKB_Nhap!I9="","",TKB_Nhap!I9&CHAR(10)&IF(T(INDEX(PhanCong!$B$3:$I$18,MATCH(TKB_Nhap!I9,PhanCong!$A$3:$A$18,0),MATCH($A9,PhanCong!$B$2:$I$2,0)))="","(chưa PC GV)","GV: "&INDEX(PhanCong!$B$3:$I$18,MATCH(TKB_Nhap!I9,PhanCong!$A$3:$A$18,0),MATCH($A9,PhanCong!$B$2:$I$2,0))))
A10: =TKB_Nhap!A10 | B10: =TKB_Nhap!B10 | C10: =TKB_Nhap!C10 | D10: =IF(TKB_Nhap!D10="","",TKB_Nhap!D10&CHAR(10)&IF(T(INDEX(PhanCong!$B$3:$I$18,MATCH(TKB_Nhap!D10,PhanCong!$A$3:$A$18,0),MATCH($A10,PhanCong!$B$2:$I$2,0)))="","(chưa PC GV)","GV: "&INDEX(PhanCong!$B$3:$I$18,MATCH(TKB_Nhap!D10,PhanCong!$A$3:$A$18,0),MATCH($A10,PhanCong!$B$2:$I$2,0)))) | E10: =IF(TKB_Nhap!E10="","",TKB_Nhap!E10&CHAR(10)&IF(T(INDEX(PhanCong!$B$3:$I$18,MATCH(TKB_Nhap!E10,PhanCong!$A$3:$A$18,0),MATCH($A10,PhanCong!$B$2:$I$2,0)))="","(chưa PC GV)","GV: "&INDEX(PhanCong!$B$3:$I$18,MATCH(TKB_Nhap!E10,PhanCong!$A$3:$A$18,0),MATCH($A10,PhanCong!$B$2:$I$2,0)))) | F10: =IF(TKB_Nhap!F10="","",TKB_Nhap!F10&CHAR(10)&IF(T(INDEX(PhanCong!$B$3:$I$18,MATCH(TKB_Nhap!F10,PhanCong!$A$3:$A$18,0),MATCH($A10,PhanCong!$B$2:$I$2,0)))="","(chưa PC GV)","GV: "&INDEX(PhanCong!$B$3:$I$18,MATCH(TKB_Nhap!F10,PhanCong!$A$3:$A$18,0),MATCH($A10,PhanCong!$B$2:$I$2,0)))) | G10: =IF(TKB_Nhap!G10="","",TKB_Nhap!G10&CHAR(10)&IF(T(INDEX(PhanCong!$B$3:$I$18,MATCH(TKB_Nhap!G10,PhanCong!$A$3:$A$18,0),MATCH($A10,PhanCong!$B$2:$I$2,0)))="","(chưa PC GV)","GV: "&INDEX(PhanCong!$B$3:$I$18,MATCH(TKB_Nhap!G10,PhanCong!$A$3:$A$18,0),MATCH($A10,PhanCong!$B$2:$I$2,0)))) | H10: =IF(TKB_Nhap!H10="","",TKB_Nhap!H10&CHAR(10)&IF(T(INDEX(PhanCong!$B$3:$I$18,MATCH(TKB_Nhap!H10,PhanCong!$A$3:$A$18,0),MATCH($A10,PhanCong!$B$2:$I$2,0)))="","(chưa PC GV)","GV: "&INDEX(PhanCong!$B$3:$I$18,MATCH(TKB_Nhap!H10,PhanCong!$A$3:$A$18,0),MATCH($A10,PhanCong!$B$2:$I$2,0)))) | I10: =IF(TKB_Nhap!I10="","",TKB_Nhap!I10&CHAR(10)&IF(T(INDEX(PhanCong!$B$3:$I$18,MATCH(TKB_Nhap!I10,PhanCong!$A$3:$A$18,0),MATCH($A10,PhanCong!$B$2:$I$2,0)))="","(chưa PC GV)","GV: "&INDEX(PhanCong!$B$3:$I$18,MATCH(TKB_Nhap!I10,PhanCong!$A$3:$A$18,0),MATCH($A10,PhanCong!$B$2:$I$2,0))))
A11: =TKB_Nhap!A11 | B11: =TKB_Nhap!B11 | C11: =TKB_Nhap!C11 | D11: =IF(TKB_Nhap!D11="","",TKB_Nhap!D11&CHAR(10)&IF(T(INDEX(PhanCong!$B$3:$I$18,MATCH(TKB_Nhap!D11,PhanCong!$A$3:$A$18,0),MATCH($A11,PhanCong!$B$2:$I$2,0)))="","(chưa PC GV)","GV: "&INDEX(PhanCong!$B$3:$I$18,MATCH(TKB_Nhap!D11,PhanCong!$A$3:$A$18,0),MATCH($A11,PhanCong!$B$2:$I$2,0)))) | E11: =IF(TKB_Nhap!E11="","",TKB_Nhap!E11&CHAR(10)&IF(T(INDEX(PhanCong!$B$3:$I$18,MATCH(TKB_Nhap!E11,PhanCong!$A$3:$A$18,0),MATCH($A11,PhanCong!$B$2:$I$2,0)))="","(chưa PC GV)","GV: "&INDEX(PhanCong!$B$3:$I$18,MATCH(TKB_Nhap!E11,PhanCong!$A$3:$A$18,0),MATCH($A11,PhanCong!$B$2:$I$2,0)))) | F11: =IF(TKB_Nhap!F11="","",TKB_Nhap!F11&CHAR(10)&IF(T(INDEX(PhanCong!$B$3:$I$18,MATCH(TKB_Nhap!F11,PhanCong!$A$3:$A$18,0),MATCH($A11,PhanCong!$B$2:$I$2,0)))="","(chưa PC GV)","GV: "&INDEX(PhanCong!$B$3:$I$18,MATCH(TKB_Nhap!F11,PhanCong!$A$3:$A$18,0),MATCH($A11,PhanCong!$B$2:$I$2,0)))) | G11: =IF(TKB_Nhap!G11="","",TKB_Nhap!G11&CHAR(10)&IF(T(INDEX(PhanCong!$B$3:$I$18,MATCH(TKB_Nhap!G11,PhanCong!$A$3:$A$18,0),MATCH($A11,PhanCong!$B$2:$I$2,0)))="","(chưa PC GV)","GV: "&INDEX(PhanCong!$B$3:$I$18,MATCH(TKB_Nhap!G11,PhanCong!$A$3:$A$18,0),MATCH($A11,PhanCong!$B$2:$I$2,0)))) | H11: =IF(TKB_Nhap!H11="","",TKB_Nhap!H11&CHAR(10)&IF(T(INDEX(PhanCong!$B$3:$I$18,MATCH(TKB_Nhap!H11,PhanCong!$A$3:$A$18,0),MATCH($A11,PhanCong!$B$2:$I$2,0)))="","(chưa PC GV)","GV: "&INDEX(PhanCong!$B$3:$I$18,MATCH(TKB_Nhap!H11,PhanCong!$A$3:$A$18,0),MATCH($A11,PhanCong!$B$2:$I$2,0)))) | I11: =IF(TKB_Nhap!I11="","",TKB_Nhap!I11&CHAR(10)&IF(T(INDEX(PhanCong!$B$3:$I$18,MATCH(TKB_Nhap!I11,PhanCong!$A$3:$A$18,0),MATCH($A11,PhanCong!$B$2:$I$2,0)))="","(chưa PC GV)","GV: "&INDEX(PhanCong!$B$3:$I$18,MATCH(TKB_Nhap!I11,PhanCong!$A$3:$A$18,0),MATCH($A11,PhanCong!$B$2:$I$2,0))))
A12: =TKB_Nhap!A12 | B12: =TKB_Nhap!B12 | C12: =TKB_Nhap!C12 | D12: =IF(TKB_Nhap!D12="","",TKB_Nhap!D12&CHAR(10)&IF(T(INDEX(PhanCong!$B$3:$I$18,MATCH(TKB_Nhap!D12,PhanCong!$A$3:$A$18,0),MATCH($A12,PhanCong!$B$2:$I$2,0)))="","(chưa PC GV)","GV: "&INDEX(PhanCong!$B$3:$I$18,MATCH(TKB_Nhap!D12,PhanCong!$A$3:$A$18,0),MATCH($A12,PhanCong!$B$2:$I$2,0)))) | E12: =IF(TKB_Nhap!E12="","",TKB_Nhap!E12&CHAR(10)&IF(T(INDEX(PhanCong!$B$3:$I$18,MATCH(TKB_Nhap!E12,PhanCong!$A$3:$A$18,0),MATCH($A12,PhanCong!$B$2:$I$2,0)))="","(chưa PC GV)","GV: "&INDEX(PhanCong!$B$3:$I$18,MATCH(TKB_Nhap!E12,PhanCong!$A$3:$A$18,0),MATCH($A12,PhanCong!$B$2:$I$2,0)))) | F12: =IF(TKB_Nhap!F12="","",TKB_Nhap!F12&CHAR(10)&IF(T(INDEX(PhanCong!$B$3:$I$18,MATCH(TKB_Nhap!F12,PhanCong!$A$3:$A$18,0),MATCH($A12,PhanCong!$B$2:$I$2,0)))="","(chưa PC GV)","GV: "&INDEX(PhanCong!$B$3:$I$18,MATCH(TKB_Nhap!F12,PhanCong!$A$3:$A$18,0),MATCH($A12,PhanCong!$B$2:$I$2,0)))) | G12: =IF(TKB_Nhap!G12="","",TKB_Nhap!G12&CHAR(10)&IF(T(INDEX(PhanCong!$B$3:$I$18,MATCH(TKB_Nhap!G12,PhanCong!$A$3:$A$18,0),MATCH($A12,PhanCong!$B$2:$I$2,0)))="","(chưa PC GV)","GV: "&INDEX(PhanCong!$B$3:$I$18,MATCH(TKB_Nhap!G12,PhanCong!$A$3:$A$18,0),MATCH($A12,PhanCong!$B$2:$I$2,0)))) | H12: =IF(TKB_Nhap!H12="","",TKB_Nhap!H12&CHAR(10)&IF(T(INDEX(PhanCong!$B$3:$I$18,MATCH(TKB_Nhap!H12,PhanCong!$A$3:$A$18,0),MATCH($A12,PhanCong!$B$2:$I$2,0)))="","(chưa PC GV)","GV: "&INDEX(PhanCong!$B$3:$I$18,MATCH(TKB_Nhap!H12,PhanCong!$A$3:$A$18,0),MATCH($A12,PhanCong!$B$2:$I$2,0)))) | I12: =IF(TKB_Nhap!I12="","",TKB_Nhap!I12&CHAR(10)&IF(T(INDEX(PhanCong!$B$3:$I$18,MATCH(TKB_Nhap!I12,PhanCong!$A$3:$A$18,0),MATCH($A12,PhanCong!$B$2:$I$2,0)))="","(chưa PC GV)","GV: "&INDEX(PhanCong!$B$3:$I$18,MATCH(TKB_Nhap!I12,PhanCong!$A$3:$A$18,0),MATCH($A12,PhanCong!$B$2:$I$2,0))))
A13: =TKB_Nhap!A13 | B13: =TKB_Nhap!B13 | C13: =TKB_Nhap!C13 | D13: =IF(TKB_Nhap!D13="","",TKB_Nhap!D13&CHAR(10)&IF(T(INDEX(PhanCong!$B$3:$I$18,MATCH(TKB_Nhap!D13,PhanCong!$A$3:$A$18,0),MATCH($A13,PhanCong!$B$2:$I$2,0)))="","(chưa PC GV)","GV: "&INDEX(PhanCong!$B$3:$I$18,MATCH(TKB_Nhap!D13,PhanCong!$A$3:$A$18,0),MATCH($A13,PhanCong!$B$2:$I$2,0)))) | E13: =IF(TKB_Nhap!E13="","",TKB_Nhap!E13&CHAR(10)&IF(T(INDEX(PhanCong!$B$3:$I$18,MATCH(TKB_Nhap!E13,PhanCong!$A$3:$A$18,0),MATCH($A13,PhanCong!$B$2:$I$2,0)))="","(chưa PC GV)","GV: "&INDEX(PhanCong!$B$3:$I$18,MATCH(TKB_Nhap!E13,PhanCong!$A$3:$A$18,0),MATCH($A13,PhanCong!$B$2:$I$2,0)))) | F13: =IF(TKB_Nhap!F13="","",TKB_Nhap!F13&CHAR(10)&IF(T(INDEX(PhanCong!$B$3:$I$18,MATCH(TKB_Nhap!F13,PhanCong!$A$3:$A$18,0),MATCH($A13,PhanCong!$B$2:$I$2,0)))="","(chưa PC GV)","GV: "&INDEX(PhanCong!$B$3:$I$18,MATCH(TKB_Nhap!F13,PhanCong!$A$3:$A$18,0),MATCH($A13,PhanCong!$B$2:$I$2,0)))) | G13: =IF(TKB_Nhap!G13="","",TKB_Nhap!G13&CHAR(10)&IF(T(INDEX(PhanCong!$B$3:$I$18,MATCH(TKB_Nhap!G13,PhanCong!$A$3:$A$18,0),MATCH($A13,PhanCong!$B$2:$I$2,0)))="","(chưa PC GV)","GV: "&INDEX(PhanCong!$B$3:$I$18,MATCH(TKB_Nhap!G13,PhanCong!$A$3:$A$18,0),MATCH($A13,PhanCong!$B$2:$I$2,0)))) | H13: =IF(TKB_Nhap!H13="","",TKB_Nhap!H13&CHAR(10)&IF(T(INDEX(PhanCong!$B$3:$I$18,MATCH(TKB_Nhap!H13,PhanCong!$A$3:$A$18,0),MATCH($A13,PhanCong!$B$2:$I$2,0)))="","(chưa PC GV)","GV: "&INDEX(PhanCong!$B$3:$I$18,MATCH(TKB_Nhap!H13,PhanCong!$A$3:$A$18,0),MATCH($A13,PhanCong!$B$2:$I$2,0)))) | I13: =IF(TKB_Nhap!I13="","",TKB_Nhap!I13&CHAR(10)&IF(T(INDEX(PhanCong!$B$3:$I$18,MATCH(TKB_Nhap!I13,PhanCong!$A$3:$A$18,0),MATCH($A13,PhanCong!$B$2:$I$2,0)))="","(chưa PC GV)","GV: "&INDEX(PhanCong!$B$3:$I$18,MATCH(TKB_Nhap!I13,PhanCong!$A$3:$A$18,0),MATCH($A13,PhanCong!$B$2:$I$2,0))))
... A57: =TKB_Nhap!A57 | B57: =TKB_Nhap!B57 | C57: =TKB_Nhap!C57 | D57: =IF(TKB_Nhap!D57="","",TKB_Nhap!D57&CHAR(10)&IF(T(INDEX(PhanCong!$B$3:$I$18,MATCH(TKB_Nhap!D57,PhanCong!$A$3:$A$18,0),MATCH($A57,PhanCong!$B$2:$I$2,0)))="","(chưa PC GV)","GV: "&INDEX(PhanCong!$B$3:$I$18,MATCH(TKB_Nhap!D57,PhanCong!$A$3:$A$18,0),MATCH($A57,PhanCong!$B$2:$I$2,0)))) | E57: =IF(TKB_Nhap!E57="","",TKB_Nhap!E57&CHAR(10)&IF(T(INDEX(PhanCong!$B$3:$I$18,MATCH(TKB_Nhap!E57,PhanCong!$A$3:$A$18,0),MATCH($A57,PhanCong!$B$2:$I$2,0)))="","(chưa PC GV)","GV: "&INDEX(PhanCong!$B$3:$I$18,MATCH(TKB_Nhap!E57,PhanCong!$A$3:$A$18,0),MATCH($A57,PhanCong!$B$2:$I$2,0)))) | F57: =IF(TKB_Nhap!F57="","",TKB_Nhap!F57&CHAR(10)&IF(T(INDEX(PhanCong!$B$3:$I$18,MATCH(TKB_Nhap!F57,PhanCong!$A$3:$A$18,0),MATCH($A57,PhanCong!$B$2:$I$2,0)))="","(chưa PC GV)","GV: "&INDEX(PhanCong!$B$3:$I$18,MATCH(TKB_Nhap!F57,PhanCong!$A$3:$A$18,0),MATCH($A57,PhanCong!$B$2:$I$2,0)))) | G57: =IF(TKB_Nhap!G57="","",TKB_Nhap!G57&CHAR(10)&IF(T(INDEX(PhanCong!$B$3:$I$18,MATCH(TKB_Nhap!G57,PhanCong!$A$3:$A$18,0),MATCH($A57,PhanCong!$B$2:$I$2,0)))="","(chưa PC GV)","GV: "&INDEX(PhanCong!$B$3:$I$18,MATCH(TKB_Nhap!G57,PhanCong!$A$3:$A$18,0),MATCH($A57,PhanCong!$B$2:$I$2,0)))) | H57: =IF(TKB_Nhap!H57="","",TKB_Nhap!H57&CHAR(10)&IF(T(INDEX(PhanCong!$B$3:$I$18,MATCH(TKB_Nhap!H57,PhanCong!$A$3:$A$18,0),MATCH($A57,PhanCong!$B$2:$I$2,0)))="","(chưa PC GV)","GV: "&INDEX(PhanCong!$B$3:$I$18,MATCH(TKB_Nhap!H57,PhanCong!$A$3:$A$18,0),MATCH($A57,PhanCong!$B$2:$I$2,0)))) | I57: =IF(TKB_Nhap!I57="","",TKB_Nhap!I57&CHAR(10)&IF(T(INDEX(PhanCong!$B$3:$I$18,MATCH(TKB_Nhap!I57,PhanCong!$A$3:$A$18,0),MATCH($A57,PhanCong!$B$2:$I$2,0)))="","(chưa PC GV)","GV: "&INDEX(PhanCong!$B$3:$I$18,MATCH(TKB_Nhap!I57,PhanCong!$A$3:$A$18,0),MATCH($A57,PhanCong!$B$2:$I$2,0))))

Sheet TKB_GV
A1: LỚP HỌC | B1: BUỔI | C1: TIẾT THỨ | D1: THỨ 2 | E1: THỨ 3 | F1: THỨ 4 | G1: THỨ 5 | H1: THỨ 6 | I1: THỨ 7 | J1: CHỦ NHẬT | L1: Cờ trùng GV (ẩn) →
A2: =TKB_Nhap!A2 | B2: =TKB_Nhap!B2 | C2: =TKB_Nhap!C2 | D2: =IF(TKB_Nhap!D2="","",IFERROR(T(INDEX(PhanCong!$B$3:$I$18,MATCH(TKB_Nhap!D2,PhanCong!$A$3:$A$18,0),MATCH($A2,PhanCong!$B$2:$I$2,0))),"")) | E2: =IF(TKB_Nhap!E2="","",IFERROR(T(INDEX(PhanCong!$B$3:$I$18,MATCH(TKB_Nhap!E2,PhanCong!$A$3:$A$18,0),MATCH($A2,PhanCong!$B$2:$I$2,0))),"")) | F2: =IF(TKB_Nhap!F2="","",IFERROR(T(INDEX(PhanCong!$B$3:$I$18,MATCH(TKB_Nhap!F2,PhanCong!$A$3:$A$18,0),MATCH($A2,PhanCong!$B$2:$I$2,0))),"")) | G2: =IF(TKB_Nhap!G2="","",IFERROR(T(INDEX(PhanCong!$B$3:$I$18,MATCH(TKB_Nhap!G2,PhanCong!$A$3:$A$18,0),MATCH($A2,PhanCong!$B$2:$I$2,0))),"")) | H2: =IF(TKB_Nhap!H2="","",IFERROR(T(INDEX(PhanCong!$B$3:$I$18,MATCH(TKB_Nhap!H2,PhanCong!$A$3:$A$18,0),MATCH($A2,PhanCong!$B$2:$I$2,0))),"")) | I2: =IF(TKB_Nhap!I2="","",IFERROR(T(INDEX(PhanCong!$B$3:$I$18,MATCH(TKB_Nhap!I2,PhanCong!$A$3:$A$18,0),MATCH($A2,PhanCong!$B$2:$I$2,0))),""))
A3: =TKB_Nhap!A3 | B3: =TKB_Nhap!B3 | C3: =TKB_Nhap!C3 | D3: =IF(TKB_Nhap!D3="","",IFERROR(T(INDEX(PhanCong!$B$3:$I$18,MATCH(TKB_Nhap!D3,PhanCong!$A$3:$A$18,0),MATCH($A3,PhanCong!$B$2:$I$2,0))),"")) | E3: =IF(TKB_Nhap!E3="","",IFERROR(T(INDEX(PhanCong!$B$3:$I$18,MATCH(TKB_Nhap!E3,PhanCong!$A$3:$A$18,0),MATCH($A3,PhanCong!$B$2:$I$2,0))),"")) | F3: =IF(TKB_Nhap!F3="","",IFERROR(T(INDEX(PhanCong!$B$3:$I$18,MATCH(TKB_Nhap!F3,PhanCong!$A$3:$A$18,0),MATCH($A3,PhanCong!$B$2:$I$2,0))),"")) | G3: =IF(TKB_Nhap!G3="","",IFERROR(T(INDEX(PhanCong!$B$3:$I$18,MATCH(TKB_Nhap!G3,PhanCong!$A$3:$A$18,0),MATCH($A3,PhanCong!$B$2:$I$2,0))),"")) | H3: =IF(TKB_Nhap!H3="","",IFERROR(T(INDEX(PhanCong!$B$3:$I$18,MATCH(TKB_Nhap!H3,PhanCong!$A$3:$A$18,0),MATCH($A3,PhanCong!$B$2:$I$2,0))),"")) | I3: =IF(TKB_Nhap!I3="","",IFERROR(T(INDEX(PhanCong!$B$3:$I$18,MATCH(TKB_Nhap!I3,PhanCong!$A$3:$A$18,0),MATCH($A3,PhanCong!$B$2:$I$2,0))),""))
A4: =TKB_Nhap!A4 | B4: =TKB_Nhap!B4 | C4: =TKB_Nhap!C4 | D4: =IF(TKB_Nhap!D4="","",IFERROR(T(INDEX(PhanCong!$B$3:$I$18,MATCH(TKB_Nhap!D4,PhanCong!$A$3:$A$18,0),MATCH($A4,PhanCong!$B$2:$I$2,0))),"")) | E4: =IF(TKB_Nhap!E4="","",IFERROR(T(INDEX(PhanCong!$B$3:$I$18,MATCH(TKB_Nhap!E4,PhanCong!$A$3:$A$18,0),MATCH($A4,PhanCong!$B$2:$I$2,0))),"")) | F4: =IF(TKB_Nhap!F4="","",IFERROR(T(INDEX(PhanCong!$B$3:$I$18,MATCH(TKB_Nhap!F4,PhanCong!$A$3:$A$18,0),MATCH($A4,PhanCong!$B$2:$I$2,0))),"")) | G4: =IF(TKB_Nhap!G4="","",IFERROR(T(INDEX(PhanCong!$B$3:$I$18,MATCH(TKB_Nhap!G4,PhanCong!$A$3:$A$18,0),MATCH($A4,PhanCong!$B$2:$I$2,0))),"")) | H4: =IF(TKB_Nhap!H4="","",IFERROR(T(INDEX(PhanCong!$B$3:$I$18,MATCH(TKB_Nhap!H4,PhanCong!$A$3:$A$18,0),MATCH($A4,PhanCong!$B$2:$I$2,0))),"")) | I4: =IF(TKB_Nhap!I4="","",IFERROR(T(INDEX(PhanCong!$B$3:$I$18,MATCH(TKB_Nhap!I4,PhanCong!$A$3:$A$18,0),MATCH($A4,PhanCong!$B$2:$I$2,0))),""))
A5: =TKB_Nhap!A5 | B5: =TKB_Nhap!B5 | C5: =TKB_Nhap!C5 | D5: =IF(TKB_Nhap!D5="","",IFERROR(T(INDEX(PhanCong!$B$3:$I$18,MATCH(TKB_Nhap!D5,PhanCong!$A$3:$A$18,0),MATCH($A5,PhanCong!$B$2:$I$2,0))),"")) | E5: =IF(TKB_Nhap!E5="","",IFERROR(T(INDEX(PhanCong!$B$3:$I$18,MATCH(TKB_Nhap!E5,PhanCong!$A$3:$A$18,0),MATCH($A5,PhanCong!$B$2:$I$2,0))),"")) | F5: =IF(TKB_Nhap!F5="","",IFERROR(T(INDEX(PhanCong!$B$3:$I$18,MATCH(TKB_Nhap!F5,PhanCong!$A$3:$A$18,0),MATCH($A5,PhanCong!$B$2:$I$2,0))),"")) | G5: =IF(TKB_Nhap!G5="","",IFERROR(T(INDEX(PhanCong!$B$3:$I$18,MATCH(TKB_Nhap!G5,PhanCong!$A$3:$A$18,0),MATCH($A5,PhanCong!$B$2:$I$2,0))),"")) | H5: =IF(TKB_Nhap!H5="","",IFERROR(T(INDEX(PhanCong!$B$3:$I$18,MATCH(TKB_Nhap!H5,PhanCong!$A$3:$A$18,0),MATCH($A5,PhanCong!$B$2:$I$2,0))),"")) | I5: =IF(TKB_Nhap!I5="","",IFERROR(T(INDEX(PhanCong!$B$3:$I$18,MATCH(TKB_Nhap!I5,PhanCong!$A$3:$A$18,0),MATCH($A5,PhanCong!$B$2:$I$2,0))),""))
A6: =TKB_Nhap!A6 | B6: =TKB_Nhap!B6 | C6: =TKB_Nhap!C6 | D6: =IF(TKB_Nhap!D6="","",IFERROR(T(INDEX(PhanCong!$B$3:$I$18,MATCH(TKB_Nhap!D6,PhanCong!$A$3:$A$18,0),MATCH($A6,PhanCong!$B$2:$I$2,0))),"")) | E6: =IF(TKB_Nhap!E6="","",IFERROR(T(INDEX(PhanCong!$B$3:$I$18,MATCH(TKB_Nhap!E6,PhanCong!$A$3:$A$18,0),MATCH($A6,PhanCong!$B$2:$I$2,0))),"")) | F6: =IF(TKB_Nhap!F6="","",IFERROR(T(INDEX(PhanCong!$B$3:$I$18,MATCH(TKB_Nhap!F6,PhanCong!$A$3:$A$18,0),MATCH($A6,PhanCong!$B$2:$I$2,0))),"")) | G6: =IF(TKB_Nhap!G6="","",IFERROR(T(INDEX(PhanCong!$B$3:$I$18,MATCH(TKB_Nhap!G6,PhanCong!$A$3:$A$18,0),MATCH($A6,PhanCong!$B$2:$I$2,0))),"")) | H6: =IF(TKB_Nhap!H6="","",IFERROR(T(INDEX(PhanCong!$B$3:$I$18,MATCH(TKB_Nhap!H6,PhanCong!$A$3:$A$18,0),MATCH($A6,PhanCong!$B$2:$I$2,0))),"")) | I6: =IF(TKB_Nhap!I6="","",IFERROR(T(INDEX(PhanCong!$B$3:$I$18,MATCH(TKB_Nhap!I6,PhanCong!$A$3:$A$18,0),MATCH($A6,PhanCong!$B$2:$I$2,0))),""))
A7: =TKB_Nhap!A7 | B7: =TKB_Nhap!B7 | C7: =TKB_Nhap!C7 | D7: =IF(TKB_Nhap!D7="","",IFERROR(T(INDEX(PhanCong!$B$3:$I$18,MATCH(TKB_Nhap!D7,PhanCong!$A$3:$A$18,0),MATCH($A7,PhanCong!$B$2:$I$2,0))),"")) | E7: =IF(TKB_Nhap!E7="","",IFERROR(T(INDEX(PhanCong!$B$3:$I$18,MATCH(TKB_Nhap!E7,PhanCong!$A$3:$A$18,0),MATCH($A7,PhanCong!$B$2:$I$2,0))),"")) | F7: =IF(TKB_Nhap!F7="","",IFERROR(T(INDEX(PhanCong!$B$3:$I$18,MATCH(TKB_Nhap!F7,PhanCong!$A$3:$A$18,0),MATCH($A7,PhanCong!$B$2:$I$2,0))),"")) | G7: =IF(TKB_Nhap!G7="","",IFERROR(T(INDEX(PhanCong!$B$3:$I$18,MATCH(TKB_Nhap!G7,PhanCong!$A$3:$A$18,0),MATCH($A7,PhanCong!$B$2:$I$2,0))),"")) | H7: =IF(TKB_Nhap!H7="","",IFERROR(T(INDEX(PhanCong!$B$3:$I$18,MATCH(TKB_Nhap!H7,PhanCong!$A$3:$A$18,0),MATCH($A7,PhanCong!$B$2:$I$2,0))),"")) | I7: =IF(TKB_Nhap!I7="","",IFERROR(T(INDEX(PhanCong!$B$3:$I$18,MATCH(TKB_Nhap!I7,PhanCong!$A$3:$A$18,0),MATCH($A7,PhanCong!$B$2:$I$2,0))),""))
A8: =TKB_Nhap!A8 | B8: =TKB_Nhap!B8 | C8: =TKB_Nhap!C8 | D8: =IF(TKB_Nhap!D8="","",IFERROR(T(INDEX(PhanCong!$B$3:$I$18,MATCH(TKB_Nhap!D8,PhanCong!$A$3:$A$18,0),MATCH($A8,PhanCong!$B$2:$I$2,0))),"")) | E8: =IF(TKB_Nhap!E8="","",IFERROR(T(INDEX(PhanCong!$B$3:$I$18,MATCH(TKB_Nhap!E8,PhanCong!$A$3:$A$18,0),MATCH($A8,PhanCong!$B$2:$I$2,0))),"")) | F8: =IF(TKB_Nhap!F8="","",IFERROR(T(INDEX(PhanCong!$B$3:$I$18,MATCH(TKB_Nhap!F8,PhanCong!$A$3:$A$18,0),MATCH($A8,PhanCong!$B$2:$I$2,0))),"")) | G8: =IF(TKB_Nhap!G8="","",IFERROR(T(INDEX(PhanCong!$B$3:$I$18,MATCH(TKB_Nhap!G8,PhanCong!$A$3:$A$18,0),MATCH($A8,PhanCong!$B$2:$I$2,0))),"")) | H8: =IF(TKB_Nhap!H8="","",IFERROR(T(INDEX(PhanCong!$B$3:$I$18,MATCH(TKB_Nhap!H8,PhanCong!$A$3:$A$18,0),MATCH($A8,PhanCong!$B$2:$I$2,0))),"")) | I8: =IF(TKB_Nhap!I8="","",IFERROR(T(INDEX(PhanCong!$B$3:$I$18,MATCH(TKB_Nhap!I8,PhanCong!$A$3:$A$18,0),MATCH($A8,PhanCong!$B$2:$I$2,0))),""))
A9: =TKB_Nhap!A9 | B9: =TKB_Nhap!B9 | C9: =TKB_Nhap!C9 | D9: =IF(TKB_Nhap!D9="","",IFERROR(T(INDEX(PhanCong!$B$3:$I$18,MATCH(TKB_Nhap!D9,PhanCong!$A$3:$A$18,0),MATCH($A9,PhanCong!$B$2:$I$2,0))),"")) | E9: =IF(TKB_Nhap!E9="","",IFERROR(T(INDEX(PhanCong!$B$3:$I$18,MATCH(TKB_Nhap!E9,PhanCong!$A$3:$A$18,0),MATCH($A9,PhanCong!$B$2:$I$2,0))),"")) | F9: =IF(TKB_Nhap!F9="","",IFERROR(T(INDEX(PhanCong!$B$3:$I$18,MATCH(TKB_Nhap!F9,PhanCong!$A$3:$A$18,0),MATCH($A9,PhanCong!$B$2:$I$2,0))),"")) | G9: =IF(TKB_Nhap!G9="","",IFERROR(T(INDEX(PhanCong!$B$3:$I$18,MATCH(TKB_Nhap!G9,PhanCong!$A$3:$A$18,0),MATCH($A9,PhanCong!$B$2:$I$2,0))),"")) | H9: =IF(TKB_Nhap!H9="","",IFERROR(T(INDEX(PhanCong!$B$3:$I$18,MATCH(TKB_Nhap!H9,PhanCong!$A$3:$A$18,0),MATCH($A9,PhanCong!$B$2:$I$2,0))),"")) | I9: =IF(TKB_Nhap!I9="","",IFERROR(T(INDEX(PhanCong!$B$3:$I$18,MATCH(TKB_Nhap!I9,PhanCong!$A$3:$A$18,0),MATCH($A9,PhanCong!$B$2:$I$2,0))),""))
A10: =TKB_Nhap!A10 | B10: =TKB_Nhap!B10 | C10: =TKB_Nhap!C10 | D10: =IF(TKB_Nhap!D10="","",IFERROR(T(INDEX(PhanCong!$B$3:$I$18,MATCH(TKB_Nhap!D10,PhanCong!$A$3:$A$18,0),MATCH($A10,PhanCong!$B$2:$I$2,0))),"")) | E10: =IF(TKB_Nhap!E10="","",IFERROR(T(INDEX(PhanCong!$B$3:$I$18,MATCH(TKB_Nhap!E10,PhanCong!$A$3:$A$18,0),MATCH($A10,PhanCong!$B$2:$I$2,0))),"")) | F10: =IF(TKB_Nhap!F10="","",IFERROR(T(INDEX(PhanCong!$B$3:$I$18,MATCH(TKB_Nhap!F10,PhanCong!$A$3:$A$18,0),MATCH($A10,PhanCong!$B$2:$I$2,0))),"")) | G10: =IF(TKB_Nhap!G10="","",IFERROR(T(INDEX(PhanCong!$B$3:$I$18,MATCH(TKB_Nhap!G10,PhanCong!$A$3:$A$18,0),MATCH($A10,PhanCong!$B$2:$I$2,0))),"")) | H10: =IF(TKB_Nhap!H10="","",IFERROR(T(INDEX(PhanCong!$B$3:$I$18,MATCH(TKB_Nhap!H10,PhanCong!$A$3:$A$18,0),MATCH($A10,PhanCong!$B$2:$I$2,0))),"")) | I10: =IF(TKB_Nhap!I10="","",IFERROR(T(INDEX(PhanCong!$B$3:$I$18,MATCH(TKB_Nhap!I10,PhanCong!$A$3:$A$18,0),MATCH($A10,PhanCong!$B$2:$I$2,0))),""))
A11: =TKB_Nhap!A11 | B11: =TKB_Nhap!B11 | C11: =TKB_Nhap!C11 | D11: =IF(TKB_Nhap!D11="","",IFERROR(T(INDEX(PhanCong!$B$3:$I$18,MATCH(TKB_Nhap!D11,PhanCong!$A$3:$A$18,0),MATCH($A11,PhanCong!$B$2:$I$2,0))),"")) | E11: =IF(TKB_Nhap!E11="","",IFERROR(T(INDEX(PhanCong!$B$3:$I$18,MATCH(TKB_Nhap!E11,PhanCong!$A$3:$A$18,0),MATCH($A11,PhanCong!$B$2:$I$2,0))),"")) | F11: =IF(TKB_Nhap!F11="","",IFERROR(T(INDEX(PhanCong!$B$3:$I$18,MATCH(TKB_Nhap!F11,PhanCong!$A$3:$A$18,0),MATCH($A11,PhanCong!$B$2:$I$2,0))),"")) | G11: =IF(TKB_Nhap!G11="","",IFERROR(T(INDEX(PhanCong!$B$3:$I$18,MATCH(TKB_Nhap!G11,PhanCong!$A$3:$A$18,0),MATCH($A11,PhanCong!$B$2:$I$2,0))),"")) | H11: =IF(TKB_Nhap!H11="","",IFERROR(T(INDEX(PhanCong!$B$3:$I$18,MATCH(TKB_Nhap!H11,PhanCong!$A$3:$A$18,0),MATCH($A11,PhanCong!$B$2:$I$2,0))),"")) | I11: =IF(TKB_Nhap!I11="","",IFERROR(T(INDEX(PhanCong!$B$3:$I$18,MATCH(TKB_Nhap!I11,PhanCong!$A$3:$A$18,0),MATCH($A11,PhanCong!$B$2:$I$2,0))),""))
A12: =TKB_Nhap!A12 | B12: =TKB_Nhap!B12 | C12: =TKB_Nhap!C12 | D12: =IF(TKB_Nhap!D12="","",IFERROR(T(INDEX(PhanCong!$B$3:$I$18,MATCH(TKB_Nhap!D12,PhanCong!$A$3:$A$18,0),MATCH($A12,PhanCong!$B$2:$I$2,0))),"")) | E12: =IF(TKB_Nhap!E12="","",IFERROR(T(INDEX(PhanCong!$B$3:$I$18,MATCH(TKB_Nhap!E12,PhanCong!$A$3:$A$18,0),MATCH($A12,PhanCong!$B$2:$I$2,0))),"")) | F12: =IF(TKB_Nhap!F12="","",IFERROR(T(INDEX(PhanCong!$B$3:$I$18,MATCH(TKB_Nhap!F12,PhanCong!$A$3:$A$18,0),MATCH($A12,PhanCong!$B$2:$I$2,0))),"")) | G12: =IF(TKB_Nhap!G12="","",IFERROR(T(INDEX(PhanCong!$B$3:$I$18,MATCH(TKB_Nhap!G12,PhanCong!$A$3:$A$18,0),MATCH($A12,PhanCong!$B$2:$I$2,0))),"")) | H12: =IF(TKB_Nhap!H12="","",IFERROR(T(INDEX(PhanCong!$B$3:$I$18,MATCH(TKB_Nhap!H12,PhanCong!$A$3:$A$18,0),MATCH($A12,PhanCong!$B$2:$I$2,0))),"")) | I12: =IF(TKB_Nhap!I12="","",IFERROR(T(INDEX(PhanCong!$B$3:$I$18,MATCH(TKB_Nhap!I12,PhanCong!$A$3:$A$18,0),MATCH($A12,PhanCong!$B$2:$I$2,0))),""))
A13: =TKB_Nhap!A13 | B13: =TKB_Nhap!B13 | C13: =TKB_Nhap!C13 | D13: =IF(TKB_Nhap!D13="","",IFERROR(T(INDEX(PhanCong!$B$3:$I$18,MATCH(TKB_Nhap!D13,PhanCong!$A$3:$A$18,0),MATCH($A13,PhanCong!$B$2:$I$2,0))),"")) | E13: =IF(TKB_Nhap!E13="","",IFERROR(T(INDEX(PhanCong!$B$3:$I$18,MATCH(TKB_Nhap!E13,PhanCong!$A$3:$A$18,0),MATCH($A13,PhanCong!$B$2:$I$2,0))),"")) | F13: =IF(TKB_Nhap!F13="","",IFERROR(T(INDEX(PhanCong!$B$3:$I$18,MATCH(TKB_Nhap!F13,PhanCong!$A$3:$A$18,0),MATCH($A13,PhanCong!$B$2:$I$2,0))),"")) | G13: =IF(TKB_Nhap!G13="","",IFERROR(T(INDEX(PhanCong!$B$3:$I$18,MATCH(TKB_Nhap!G13,PhanCong!$A$3:$A$18,0),MATCH($A13,PhanCong!$B$2:$I$2,0))),"")) | H13: =IF(TKB_Nhap!H13="","",IFERROR(T(INDEX(PhanCong!$B$3:$I$18,MATCH(TKB_Nhap!H13,PhanCong!$A$3:$A$18,0),MATCH($A13,PhanCong!$B$2:$I$2,0))),"")) | I13: =IF(TKB_Nhap!I13="","",IFERROR(T(INDEX(PhanCong!$B$3:$I$18,MATCH(TKB_Nhap!I13,PhanCong!$A$3:$A$18,0),MATCH($A13,PhanCong!$B$2:$I$2,0))),""))
... A57: =TKB_Nhap!A57 | B57: =TKB_Nhap!B57 | C57: =TKB_Nhap!C57 | D57: =IF(TKB_Nhap!D57="","",IFERROR(T(INDEX(PhanCong!$B$3:$I$18,MATCH(TKB_Nhap!D57,PhanCong!$A$3:$A$18,0),MATCH($A57,PhanCong!$B$2:$I$2,0))),"")) | E57: =IF(TKB_Nhap!E57="","",IFERROR(T(INDEX(PhanCong!$B$3:$I$18,MATCH(TKB_Nhap!E57,PhanCong!$A$3:$A$18,0),MATCH($A57,PhanCong!$B$2:$I$2,0))),"")) | F57: =IF(TKB_Nhap!F57="","",IFERROR(T(INDEX(PhanCong!$B$3:$I$18,MATCH(TKB_Nhap!F57,PhanCong!$A$3:$A$18,0),MATCH($A57,PhanCong!$B$2:$I$2,0))),"")) | G57: =IF(TKB_Nhap!G57="","",IFERROR(T(INDEX(PhanCong!$B$3:$I$18,MATCH(TKB_Nhap!G57,PhanCong!$A$3:$A$18,0),MATCH($A57,PhanCong!$B$2:$I$2,0))),"")) | H57: =IF(TKB_Nhap!H57="","",IFERROR(T(INDEX(PhanCong!$B$3:$I$18,MATCH(TKB_Nhap!H57,PhanCong!$A$3:$A$18,0),MATCH($A57,PhanCong!$B$2:$I$2,0))),"")) | I57: =IF(TKB_Nhap!I57="","",IFERROR(T(INDEX(PhanCong!$B$3:$I$18,MATCH(TKB_Nhap!I57,PhanCong!$A$3:$A$18,0),MATCH($A57,PhanCong!$B$2:$I$2,0))),""))

Sheet KiemTra
A1: KIỂM TRA — Định mức theo TuanConfig!B2 (C/L). Chênh lệch=Đã xếp−Định mức (0=đạt)
A3: Môn \ Lớp | B3: 6A5 | C3: 6A6 | D3: 7A4 | E3: 7A5 | F3: 8A5 | G3: 8A6 | H3: 9A5 | I3: 9A6
A4: Toán học | B4: =SUMPRODUCT((TKB_Nhap!$A$2:$A$57=B$3)*(TKB_Nhap!$D$2:$J$57=$A4))-IFERROR(N(IF(TuanConfig!$B$2="C",INDEX(SoTiet!$B$3:$I$18,MATCH($A4,SoTiet!$A$3:$A$18,0),1),INDEX(SoTiet!$K$3:$R$18,MATCH($A4,SoTiet!$A$3:$A$18,0),1))),0) | C4: =SUMPRODUCT((TKB_Nhap!$A$2:$A$57=C$3)*(TKB_Nhap!$D$2:$J$57=$A4))-IFERROR(N(IF(TuanConfig!$B$2="C",INDEX(SoTiet!$B$3:$I$18,MATCH($A4,SoTiet!$A$3:$A$18,0),2),INDEX(SoTiet!$K$3:$R$18,MATCH($A4,SoTiet!$A$3:$A$18,0),2))),0) | D4: =SUMPRODUCT((TKB_Nhap!$A$2:$A$57=D$3)*(TKB_Nhap!$D$2:$J$57=$A4))-IFERROR(N(IF(TuanConfig!$B$2="C",INDEX(SoTiet!$B$3:$I$18,MATCH($A4,SoTiet!$A$3:$A$18,0),3),INDEX(SoTiet!$K$3:$R$18,MATCH($A4,SoTiet!$A$3:$A$18,0),3))),0) | E4: =SUMPRODUCT((TKB_Nhap!$A$2:$A$57=E$3)*(TKB_Nhap!$D$2:$J$57=$A4))-IFERROR(N(IF(TuanConfig!$B$2="C",INDEX(SoTiet!$B$3:$I$18,MATCH($A4,SoTiet!$A$3:$A$18,0),4),INDEX(SoTiet!$K$3:$R$18,MATCH($A4,SoTiet!$A$3:$A$18,0),4))),0) | F4: =SUMPRODUCT((TKB_Nhap!$A$2:$A$57=F$3)*(TKB_Nhap!$D$2:$J$57=$A4))-IFERROR(N(IF(TuanConfig!$B$2="C",INDEX(SoTiet!$B$3:$I$18,MATCH($A4,SoTiet!$A$3:$A$18,0),5),INDEX(SoTiet!$K$3:$R$18,MATCH($A4,SoTiet!$A$3:$A$18,0),5))),0) | G4: =SUMPRODUCT((TKB_Nhap!$A$2:$A$57=G$3)*(TKB_Nhap!$D$2:$J$57=$A4))-IFERROR(N(IF(TuanConfig!$B$2="C",INDEX(SoTiet!$B$3:$I$18,MATCH($A4,SoTiet!$A$3:$A$18,0),6),INDEX(SoTiet!$K$3:$R$18,MATCH($A4,SoTiet!$A$3:$A$18,0),6))),0) | H4: =SUMPRODUCT((TKB_Nhap!$A$2:$A$57=H$3)*(TKB_Nhap!$D$2:$J$57=$A4))-IFERROR(N(IF(TuanConfig!$B$2="C",INDEX(SoTiet!$B$3:$I$18,MATCH($A4,SoTiet!$A$3:$A$18,0),7),INDEX(SoTiet!$K$3:$R$18,MATCH($A4,SoTiet!$A$3:$A$18,0),7))),0) | I4: =SUMPRODUCT((TKB_Nhap!$A$2:$A$57=I$3)*(TKB_Nhap!$D$2:$J$57=$A4))-IFERROR(N(IF(TuanConfig!$B$2="C",INDEX(SoTiet!$B$3:$I$18,MATCH($A4,SoTiet!$A$3:$A$18,0),8),INDEX(SoTiet!$K$3:$R$18,MATCH($A4,SoTiet!$A$3:$A$18,0),8))),0)
A5: Ngữ văn | B5: =SUMPRODUCT((TKB_Nhap!$A$2:$A$57=B$3)*(TKB_Nhap!$D$2:$J$57=$A5))-IFERROR(N(IF(TuanConfig!$B$2="C",INDEX(SoTiet!$B$3:$I$18,MATCH($A5,SoTiet!$A$3:$A$18,0),1),INDEX(SoTiet!$K$3:$R$18,MATCH($A5,SoTiet!$A$3:$A$18,0),1))),0) | C5: =SUMPRODUCT((TKB_Nhap!$A$2:$A$57=C$3)*(TKB_Nhap!$D$2:$J$57=$A5))-IFERROR(N(IF(TuanConfig!$B$2="C",INDEX(SoTiet!$B$3:$I$18,MATCH($A5,SoTiet!$A$3:$A$18,0),2),INDEX(SoTiet!$K$3:$R$18,MATCH($A5,SoTiet!$A$3:$A$18,0),2))),0) | D5: =SUMPRODUCT((TKB_Nhap!$A$2:$A$57=D$3)*(TKB_Nhap!$D$2:$J$57=$A5))-IFERROR(N(IF(TuanConfig!$B$2="C",INDEX(SoTiet!$B$3:$I$18,MATCH($A5,SoTiet!$A$3:$A$18,0),3),INDEX(SoTiet!$K$3:$R$18,MATCH($A5,SoTiet!$A$3:$A$18,0),3))),0) | E5: =SUMPRODUCT((TKB_Nhap!$A$2:$A$57=E$3)*(TKB_Nhap!$D$2:$J$57=$A5))-IFERROR(N(IF(TuanConfig!$B$2="C",INDEX(SoTiet!$B$3:$I$18,MATCH($A5,SoTiet!$A$3:$A$18,0),4),INDEX(SoTiet!$K$3:$R$18,MATCH($A5,SoTiet!$A$3:$A$18,0),4))),0) | F5: =SUMPRODUCT((TKB_Nhap!$A$2:$A$57=F$3)*(TKB_Nhap!$D$2:$J$57=$A5))-IFERROR(N(IF(TuanConfig!$B$2="C",INDEX(SoTiet!$B$3:$I$18,MATCH($A5,SoTiet!$A$3:$A$18,0),5),INDEX(SoTiet!$K$3:$R$18,MATCH($A5,SoTiet!$A$3:$A$18,0),5))),0) | G5: =SUMPRODUCT((TKB_Nhap!$A$2:$A$57=G$3)*(TKB_Nhap!$D$2:$J$57=$A5))-IFERROR(N(IF(TuanConfig!$B$2="C",INDEX(SoTiet!$B$3:$I$18,MATCH($A5,SoTiet!$A$3:$A$18,0),6),INDEX(SoTiet!$K$3:$R$18,MATCH($A5,SoTiet!$A$3:$A$18,0),6))),0) | H5: =SUMPRODUCT((TKB_Nhap!$A$2:$A$57=H$3)*(TKB_Nhap!$D$2:$J$57=$A5))-IFERROR(N(IF(TuanConfig!$B$2="C",INDEX(SoTiet!$B$3:$I$18,MATCH($A5,SoTiet!$A$3:$A$18,0),7),INDEX(SoTiet!$K$3:$R$18,MATCH($A5,SoTiet!$A$3:$A$18,0),7))),0) | I5: =SUMPRODUCT((TKB_Nhap!$A$2:$A$57=I$3)*(TKB_Nhap!$D$2:$J$57=$A5))-IFERROR(N(IF(TuanConfig!$B$2="C",INDEX(SoTiet!$B$3:$I$18,MATCH($A5,SoTiet!$A$3:$A$18,0),8),INDEX(SoTiet!$K$3:$R$18,MATCH($A5,SoTiet!$A$3:$A$18,0),8))),0)
A6: Ngoại ngữ | B6: =SUMPRODUCT((TKB_Nhap!$A$2:$A$57=B$3)*(TKB_Nhap!$D$2:$J$57=$A6))-IFERROR(N(IF(TuanConfig!$B$2="C",INDEX(SoTiet!$B$3:$I$18,MATCH($A6,SoTiet!$A$3:$A$18,0),1),INDEX(SoTiet!$K$3:$R$18,MATCH($A6,SoTiet!$A$3:$A$18,0),1))),0) | C6: =SUMPRODUCT((TKB_Nhap!$A$2:$A$57=C$3)*(TKB_Nhap!$D$2:$J$57=$A6))-IFERROR(N(IF(TuanConfig!$B$2="C",INDEX(SoTiet!$B$3:$I$18,MATCH($A6,SoTiet!$A$3:$A$18,0),2),INDEX(SoTiet!$K$3:$R$18,MATCH($A6,SoTiet!$A$3:$A$18,0),2))),0) | D6: =SUMPRODUCT((TKB_Nhap!$A$2:$A$57=D$3)*(TKB_Nhap!$D$2:$J$57=$A6))-IFERROR(N(IF(TuanConfig!$B$2="C",INDEX(SoTiet!$B$3:$I$18,MATCH($A6,SoTiet!$A$3:$A$18,0),3),INDEX(SoTiet!$K$3:$R$18,MATCH($A6,SoTiet!$A$3:$A$18,0),3))),0) | E6: =SUMPRODUCT((TKB_Nhap!$A$2:$A$57=E$3)*(TKB_Nhap!$D$2:$J$57=$A6))-IFERROR(N(IF(TuanConfig!$B$2="C",INDEX(SoTiet!$B$3:$I$18,MATCH($A6,SoTiet!$A$3:$A$18,0),4),INDEX(SoTiet!$K$3:$R$18,MATCH($A6,SoTiet!$A$3:$A$18,0),4))),0) | F6: =SUMPRODUCT((TKB_Nhap!$A$2:$A$57=F$3)*(TKB_Nhap!$D$2:$J$57=$A6))-IFERROR(N(IF(TuanConfig!$B$2="C",INDEX(SoTiet!$B$3:$I$18,MATCH($A6,SoTiet!$A$3:$A$18,0),5),INDEX(SoTiet!$K$3:$R$18,MATCH($A6,SoTiet!$A$3:$A$18,0),5))),0) | G6: =SUMPRODUCT((TKB_Nhap!$A$2:$A$57=G$3)*(TKB_Nhap!$D$2:$J$57=$A6))-IFERROR(N(IF(TuanConfig!$B$2="C",INDEX(SoTiet!$B$3:$I$18,MATCH($A6,SoTiet!$A$3:$A$18,0),6),INDEX(SoTiet!$K$3:$R$18,MATCH($A6,SoTiet!$A$3:$A$18,0),6))),0) | H6: =SUMPRODUCT((TKB_Nhap!$A$2:$A$57=H$3)*(TKB_Nhap!$D$2:$J$57=$A6))-IFERROR(N(IF(TuanConfig!$B$2="C",INDEX(SoTiet!$B$3:$I$18,MATCH($A6,SoTiet!$A$3:$A$18,0),7),INDEX(SoTiet!$K$3:$R$18,MATCH($A6,SoTiet!$A$3:$A$18,0),7))),0) | I6: =SUMPRODUCT((TKB_Nhap!$A$2:$A$57=I$3)*(TKB_Nhap!$D$2:$J$57=$A6))-IFERROR(N(IF(TuanConfig!$B$2="C",INDEX(SoTiet!$B$3:$I$18,MATCH($A6,SoTiet!$A$3:$A$18,0),8),INDEX(SoTiet!$K$3:$R$18,MATCH($A6,SoTiet!$A$3:$A$18,0),8))),0)
