Workbook
Name DS_Mon: PhanCong!$A$3:$A$18

Sheet TKB
A1: LỚP HỌC | B1: BUỔI | C1: TIẾT THỨ | D1: Thứ 2 | E1: Thứ 3 | F1: Thứ 4 | G1: Thứ 5 | H1: Thứ 6 | I1: Thứ 7 | J1: Chủ nhật
A2: 6A5 | B2: S | C2: 1 | D2: Hoạt động trải nghiệm, hướng nghiệp GV: Giang | E2: Ngữ văn GV: Hoa | F2: Tin học GV: Minh Anh | G2: Lịch sử và Địa Lý (Địa lý) GV: Nhung | H2: Ngoại ngữ GV: Giang
A3: 6A5 | B3: S | C3: 2 | D3: Ngoại ngữ GV: Giang | E3: Nghệ thuật (Mỹ thuật) GV: Lan Ly | F3: Lịch sử và Địa Lý (Địa lý) GV: Nhung | G3: Giáo dục thể chất GV: Hồng | H3: Toán học GV: Huyền Ly
A4: 6A5 | B4: S | C4: 3 | D4: Toán học GV: Huyền Ly | E4: Toán học GV: Huyền Ly | F4: Khoa học tự nhiên (Hóa học) GV: Sơn | G4: Ngữ văn GV: Hoa | H4: Ngữ văn GV: Hoa
A5: 6A5 | B5: S | C5: 4 | D5: Giáo dục thể chất GV: Hồng | E5: GDCD GV: Khu | F5: Ngữ văn GV: Hoa | G5: Toán học GV: Huyền Ly | H5: Hoạt động trải nghiệm, hướng nghiệp GV: Giang
A6: 6A5 | B6: C | C6: 1 | D6: Lịch sử và Địa Lý (Lịch sử) GV: Hoa | E6: Nghệ thuật (Âm nhạc) GV: Hà | F6: Ngoại ngữ GV: Giang
A7: 6A5 | B7: C | C7: 2 | D7: Khoa học tự nhiên (Hóa học) GV: Sơn | E7: Nội dung giáo dục của địa phương GV: Lan | F7: Khoa học tự nhiên (Hóa học) GV: Sơn
A8: 6A5 | B8: C | C8: 3 | D8: Công nghệ GV: Huyền Ly | E8: Khoa học tự nhiên (Hóa học) GV: Sơn | F8: Hoạt động trải nghiệm, hướng nghiệp GV: Giang
A9: 6A6 | B9: S | C9: 1 | D9: Hoạt động trải nghiệm, hướng nghiệp GV: Hoa | E9: Ngoại ngữ GV: Trung | F9: Ngoại ngữ GV: Trung | G9: Ngữ văn GV: Hoa | H9: Toán học GV: Huyền Ly
A10: 6A6 | B10: S | C10: 2 | D10: Ngữ văn GV: Hoa | E10: Giáo dục thể chất GV: Hồng | F10: Ngữ văn GV: Hoa | G10: Toán học GV: Huyền Ly | H10: Khoa học tự nhiên (Hóa học) GV: Sơn
A11: 6A6 | B11: S | C11: 3 | D11: Ngoại ngữ GV: Trung | E11: Ngữ văn GV: Hoa | F11: GDCD GV: Khu | G11: Khoa học tự nhiên (Hóa học) GV: Sơn | H11: Giáo dục thể chất GV: Hồng
A12: 6A6 | B12: S | C12: 4 | D12: Toán học GV: Huyền Ly | E12: Toán học GV: Huyền Ly | F12: Tin học GV: Sơn | G12: Nghệ thuật (Mỹ thuật) GV: Lan Ly | H12: Hoạt động trải nghiệm, hướng nghiệp GV: Hoa
A13: 6A6 | B13: C | C13: 1 | D13: Công nghệ GV: Huyền Ly | E13: Nội dung giáo dục của địa phương GV: Lan | F13: Nghệ thuật (Âm nhạc) GV: Hà
A14: 6A6 | B14: C | C14: 2 | D14: Lịch sử và Địa Lý (Lịch sử) GV: Hoa | E14: Khoa học tự nhiên (Hóa học) GV: Sơn | F14: Lịch sử và Địa Lý (Địa lý) GV: Nhung
A15: 6A6 | B15: C | C15: 3 | D15: Lịch sử và Địa Lý (Địa lý) GV: Nhung | E15: Hoạt động trải nghiệm, hướng nghiệp GV: Hoa | F15: Khoa học tự nhiên (Hóa học) GV: Sơn
A16: 7A4 | B16: S | C16: 1 | D16: Hoạt động trải nghiệm, hướng nghiệp GV: Lệ | E16: Lịch sử và Địa Lý (Địa lý) GV: Nhung | F16: Toán học GV: Lệ | G16: Tin học GV: Khu | H16: Công nghệ GV: Sơn
A17: 7A4 | B17: S | C17: 2 | D17: Giáo dục thể chất GV: Hồng | E17: Ngữ văn GV: Nhung | F17: Khoa học tự nhiên (Vật lý) GV: Huyền Ly | G17: Toán học GV: Lệ | H17: Ngữ văn GV: Nhung
A18: 7A4 | B18: S | C18: 3 | D18: Ngữ văn GV: Nhung | E18: Toán học GV: Lệ | F18: Lịch sử và Địa Lý (Lịch sử) GV: Thành | G18: Giáo dục thể chất GV: Hồng | H18: Toán học GV: Lệ
A19: 7A4 | B19: S | C19: 4 | D19: Ngoại ngữ GV: Trung | E19: Ngoại ngữ GV: Trung | F19: Hoạt động trải nghiệm, hướng nghiệp GV: Lệ | G19: Ngữ văn GV: Nhung | H19: Hoạt động trải nghiệm, hướng nghiệp GV: Lệ
A20: 7A4 | B20: C | C20: 1 | D20: Nghệ thuật (Mỹ thuật) GV: Lan Ly | E20: Khoa học tự nhiên (Hóa học) GV: Hoà | F20: Ngoại ngữ GV: Trung
A21: 7A4 | B21: C | C21: 2 | D21: Khoa học tự nhiên (Sinh học) GV: Hoà | E21: Nghệ thuật (Âm nhạc) GV: Lan Ly | F21: Khoa học tự nhiên (Sinh học) GV: Hoà
A22: 7A4 | B22: C | C22: 3 | D22: Nội dung giáo dục của địa phương GV: Khu | E22: Lịch sử và Địa Lý (Lịch sử) GV: Thành | F22: GDCD GV: Lan Ly
A23: 7A5 | B23: S | C23: 1 | D23: Hoạt động trải nghiệm, hướng nghiệp GV: Hoà | E23: Giáo dục thể chất GV: Hồng | F23: Ngữ văn GV: Thành | G23: Ngoại ngữ GV: Trung | H23: Nghệ thuật (Âm nhạc) GV: Lan Ly
A24: 7A5 | B24: S | C24: 2 | D24: Ngữ văn GV: Thành | E24: Ngoại ngữ GV: Trung | F24: Toán học GV: Lệ | G24: Ngữ văn GV: Thành | H24: Toán học GV: Lệ
A25: 7A5 | B25: S | C25: 3 | D25: Toán học GV: Lệ | E25: Ngữ văn GV: Thành | F25: Khoa học tự nhiên (Vật lý) GV: Huyền Ly | G25: Toán học GV: Lệ | H25: Nội dung giáo dục của địa phương GV: Khu
A26: 7A5 | B26: S | C26: 4 | D26: Lịch sử và Địa Lý (Lịch sử) GV: Thành | E26: GDCD GV: Lan Ly | F26: Tin học GV: Khu | G26: Giáo dục thể chất GV: Hồng | H26: Hoạt động trải nghiệm, hướng nghiệp GV: Hoà
A27: 7A5 | B27: C | C27: 1 | D27: Khoa học tự nhiên (Sinh học) GV: Hoà | E27: Công nghệ GV: Sơn | F27: Khoa học tự nhiên (Sinh học) GV: Hoà
A28: 7A5 | B28: C | C28: 2 | D28: Lịch sử và Địa Lý (Địa lý) GV: Nhung | E28: Lịch sử và Địa Lý (Lịch sử) GV: Thành | F28: Nghệ thuật (Mỹ thuật) GV: Lan Ly
A29: 7A5 | B29: C | C29: 3 | D29: Khoa học tự nhiên (Hóa học) GV: Hoà | E29: Ngoại ngữ GV: Trung | F29: Hoạt động trải nghiệm, hướng nghiệp GV: Hoà
A30: 8A5 | B30: S | C30: 1 | D30: Hoạt động trải nghiệm, hướng nghiệp GV: Minh Anh | E30: Khoa học tự nhiên (Hóa học) GV: Khu | F30: Ngữ văn GV: Uyên | G30: Toán học GV: Minh Anh | H30: Lịch sử và Địa Lý (Địa lý) GV: Nhung
A31: 8A5 | B31: S | C31: 2 | D31: Toán học GV: Minh Anh | E31: Ngữ văn GV: Uyên | F31: Khoa học tự nhiên (Hóa học) GV: Khu | G31: Hoạt động trải nghiệm, hướng nghiệp GV: Minh Anh | H31: Toán học GV: Minh Anh
A32: 8A5 | B32: S | C32: 3 | D32: Giáo dục thể chất GV: Hồng | E32: Toán học GV: Minh Anh | F32: Nội dung giáo dục của địa phương GV: Nhung | G32: Ngoại ngữ GV: Trung | H32: Công nghệ GV: Sơn
A33: 8A5 | B33: S | C33: 4 | D33: Ngữ văn GV: Uyên | E33: Lịch sử và Địa Lý (Địa lý) GV: Nhung | F33: Lịch sử và Địa Lý (Lịch sử) GV: Thành | G33: Khoa học tự nhiên (Hóa học) GV: Khu | H33: Ngữ văn GV: Uyên
A34: 8A5 | B34: S | C34: 5 | H34: Hoạt động trải nghiệm, hướng nghiệp GV: Minh Anh
A35: 8A5 | B35: C | C35: 1 | D35: Công nghệ GV: Sơn | E35: Ngoại ngữ GV: Trung | F35: Tin học GV: Lệ
A36: 8A5 | B36: C | C36: 2 | D36: Nghệ thuật (Âm nhạc) GV: Lan Ly | E36: GDCD GV: Hoà | F36: Ngoại ngữ GV: Trung
A37: 8A5 | B37: C | C37: 3 | D37: Nghệ thuật (Mỹ thuật) GV: Lan Ly | E37: Khoa học tự nhiên (Vật lý) GV: Nguyễn Ly | F37: Giáo dục thể chất GV: Hồng
A38: 8A6 | B38: S | C38: 1 | D38: Hoạt động trải nghiệm, hướng nghiệp GV: Uyên | E38: Toán học GV: Minh Anh | F38: Khoa học tự nhiên (Hóa học) GV: Khu | G38: Giáo dục thể chất GV: Hồng | H38: Ngữ văn GV: Uyên
A39: 8A6 | B39: S | C39: 2 | D39: Ngữ văn GV: Uyên | E39: Khoa học tự nhiên (Hóa học) GV: Khu | F39: Toán học GV: Minh Anh | G39: Nghệ thuật (Âm nhạc) GV: Lan Ly | H39: Khoa học tự nhiên (Hóa học) GV: Khu
A40: 8A6 | B40: S | C40: 3 | D40: Nghệ thuật (Mỹ thuật) GV: Lan Ly | E40: Ngữ văn GV: Uyên | F40: Ngữ văn GV: Uyên | G40: Toán học GV: Minh Anh | H40: Nội dung giáo dục của địa phương GV: Nhung
...

Sheet TKB_Mon
A1: LỚP HỌC | B1: BUỔI | C1: TIẾT THỨ | D1: Thứ 2 | E1: Thứ 3 | F1: Thứ 4 | G1: Thứ 5 | H1: Thứ 6 | I1: Thứ 7 | J1: Chủ nhật
A2: 6A5 | B2: S | C2: 1 | D2: Hoạt động trải nghiệm, hướng nghiệp | E2: Ngữ văn | F2: Tin học | G2: Lịch sử và Địa Lý (Địa lý) | H2: Ngoại ngữ
A3: 6A5 | B3: S | C3: 2 | D3: Ngoại ngữ | E3: Nghệ thuật (Mỹ thuật) | F3: Lịch sử và Địa Lý (Địa lý) | G3: Giáo dục thể chất | H3: Toán học
A4: 6A5 | B4: S | C4: 3 | D4: Toán học | E4: Toán học | F4: Khoa học tự nhiên (Hóa học) | G4: Ngữ văn | H4: Ngữ văn
A5: 6A5 | B5: S | C5: 4 | D5: Giáo dục thể chất | E5: GDCD | F5: Ngữ văn | G5: Toán học | H5: Hoạt động trải nghiệm, hướng nghiệp
A6: 6A5 | B6: C | C6: 1 | D6: Lịch sử và Địa Lý (Lịch sử) | E6: Nghệ thuật (Âm nhạc) | F6: Ngoại ngữ
A7: 6A5 | B7: C | C7: 2 | D7: Khoa học tự nhiên (Hóa học) | E7: Nội dung giáo dục của địa phương | F7: Khoa học tự nhiên (Hóa học)
A8: 6A5 | B8: C | C8: 3 | D8: Công nghệ | E8: Khoa học tự nhiên (Hóa học) | F8: Hoạt động trải nghiệm, hướng nghiệp
A9: 6A6 | B9: S | C9: 1 | D9: Hoạt động trải nghiệm, hướng nghiệp | E9: Ngoại ngữ | F9: Ngoại ngữ | G9: Ngữ văn | H9: Toán học
A10: 6A6 | B10: S | C10: 2 | D10: Ngữ văn | E10: Giáo dục thể chất | F10: Ngữ văn | G10: Toán học | H10: Khoa học tự nhiên (Hóa học)
A11: 6A6 | B11: S | C11: 3 | D11: Ngoại ngữ | E11: Ngữ văn | F11: GDCD | G11: Khoa học tự nhiên (Hóa học) | H11: Giáo dục thể chất
A12: 6A6 | B12: S | C12: 4 | D12: Toán học | E12: Toán học | F12: Tin học | G12: Nghệ thuật (Mỹ thuật) | H12: Hoạt động trải nghiệm, hướng nghiệp
A13: 6A6 | B13: C | C13: 1 | D13: Công nghệ | E13: Nội dung giáo dục của địa phương | F13: Nghệ thuật (Âm nhạc)
A14: 6A6 | B14: C | C14: 2 | D14: Lịch sử và Địa Lý (Lịch sử) | E14: Khoa học tự nhiên (Hóa học) | F14: Lịch sử và Địa Lý (Địa lý)
A15: 6A6 | B15: C | C15: 3 | D15: Lịch sử và Địa Lý (Địa lý) | E15: Hoạt động trải nghiệm, hướng nghiệp | F15: Khoa học tự nhiên (Hóa học)
A16: 7A4 | B16: S | C16: 1 | D16: Hoạt động trải nghiệm, hướng nghiệp | E16: Lịch sử và Địa Lý (Địa lý) | F16: Toán học | G16: Tin học | H16: Công nghệ
A17: 7A4 | B17: S | C17: 2 | D17: Giáo dục thể chất | E17: Ngữ văn | F17: Khoa học tự nhiên (Vật lý) | G17: Toán học | H17: Ngữ văn
A18: 7A4 | B18: S | C18: 3 | D18: Ngữ văn | E18: Toán học | F18: Lịch sử và Địa Lý (Lịch sử) | G18: Giáo dục thể chất | H18: Toán học
A19: 7A4 | B19: S | C19: 4 | D19: Ngoại ngữ | E19: Ngoại ngữ | F19: Hoạt động trải nghiệm, hướng nghiệp | G19: Ngữ văn | H19: Hoạt động trải nghiệm, hướng nghiệp
A20: 7A4 | B20: C | C20: 1 | D20: Nghệ thuật (Mỹ thuật) | E20: Khoa học tự nhiên (Hóa học) | F20: Ngoại ngữ
A21: 7A4 | B21: C | C21: 2 | D21: Khoa học tự nhiên (Sinh học) | E21: Nghệ thuật (Âm nhạc) | F21: Khoa học tự nhiên (Sinh học)
A22: 7A4 | B22: C | C22: 3 | D22: Nội dung giáo dục của địa phương | E22: Lịch sử và Địa Lý (Lịch sử) | F22: GDCD
A23: 7A5 | B23: S | C23: 1 | D23: Hoạt động trải nghiệm, hướng nghiệp | E23: Giáo dục thể chất | F23: Ngữ văn | G23: Ngoại ngữ | H23: Nghệ thuật (Âm nhạc)
A24: 7A5 | B24: S | C24: 2 | D24: Ngữ văn | E24: Ngoại ngữ | F24: Toán học | G24: Ngữ văn | H24: Toán học
A25: 7A5 | B25: S | C25: 3 | D25: Toán học | E25: Ngữ văn | F25: Khoa học tự nhiên (Vật lý) | G25: Toán học | H25: Nội dung giáo dục của địa phương
A26: 7A5 | B26: S | C26: 4 | D26: Lịch sử và Địa Lý (Lịch sử) | E26: GDCD | F26: Tin học | G26: Giáo dục thể chất | H26: Hoạt động trải nghiệm, hướng nghiệp
A27: 7A5 | B27: C | C27: 1 | D27: Khoa học tự nhiên (Sinh học) | E27: Công nghệ | F27: Khoa học tự nhiên (Sinh học)
A28: 7A5 | B28: C | C28: 2 | D28: Lịch sử và Địa Lý (Địa lý) | E28: Lịch sử và Địa Lý (Lịch sử) | F28: Nghệ thuật (Mỹ thuật)
A29: 7A5 | B29: C | C29: 3 | D29: Khoa học tự nhiên (Hóa học) | E29: Ngoại ngữ | F29: Hoạt động trải nghiệm, hướng nghiệp
A30: 8A5 | B30: S | C30: 1 | D30: Hoạt động trải nghiệm, hướng nghiệp | E30: Khoa học tự nhiên (Hóa học) | F30: Ngữ văn | G30: Toán học | H30: Lịch sử và Địa Lý (Địa lý)
A31: 8A5 | B31: S | C31: 2 | D31: Toán học | E31: Ngữ văn | F31: Khoa học tự nhiên (Hóa học) | G31: Hoạt động trải nghiệm, hướng nghiệp | H31: Toán học
A32: 8A5 | B32: S | C32: 3 | D32: Giáo dục thể chất | E32: Toán học | F32: Nội dung giáo dục của địa phương | G32: Ngoại ngữ | H32: Công nghệ
A33: 8A5 | B33: S | C33: 4 | D33: Ngữ văn | E33: Lịch sử và Địa Lý (Địa lý) | F33: Lịch sử và Địa Lý (Lịch sử) | G33: Khoa học tự nhiên (Hóa học) | H33: Ngữ văn
A34: 8A5 | B34: S | C34: 5 | H34: Hoạt động trải nghiệm, hướng nghiệp
A35: 8A5 | B35: C | C35: 1 | D35: Công nghệ | E35: Ngoại ngữ | F35: Tin học
A36: 8A5 | B36: C | C36: 2 | D36: Nghệ thuật (Âm nhạc) | E36: GDCD | F36: Ngoại ngữ
A37: 8A5 | B37: C | C37: 3 | D37: Nghệ thuật (Mỹ thuật) | E37: Khoa học tự nhiên (Vật lý) | F37: Giáo dục thể chất
A38: 8A6 | B38: S | C38: 1 | D38: Hoạt động trải nghiệm, hướng nghiệp | E38: Toán học | F38: Khoa học tự nhiên (Hóa học) | G38: Giáo dục thể chất | H38: Ngữ văn
A39: 8A6 | B39: S | C39: 2 | D39: Ngữ văn | E39: Khoa học tự nhiên (Hóa học) | F39: Toán học | G39: Nghệ thuật (Âm nhạc) | H39: Khoa học tự nhiên (Hóa học)
A40: 8A6 | B40: S | C40: 3 | D40: Nghệ thuật (Mỹ thuật) | E40: Ngữ văn | F40: Ngữ văn | G40: Toán học | H40: Nội dung giáo dục của địa phương
...

Sheet TKB_GV
A1: LỚP HỌC | B1: BUỔI | C1: TIẾT THỨ | D1: Thứ 2 | E1: Thứ 3 | F1: Thứ 4 | G1: Thứ 5 | H1: Thứ 6 | I1: Thứ 7 | J1: Chủ nhật | L1: Cờ trùng GV (ẩn) →
A2: 6A5 | B2: S | C2: 1 | D2: Giang | E2: Hoa | F2: Minh Anh | G2: Nhung | H2: Giang
A3: 6A5 | B3: S | C3: 2 | D3: Giang | E3: Lan Ly | F3: Nhung | G3: Hồng | H3: Huyền Ly
A4: 6A5 | B4: S | C4: 3 | D4: Huyền Ly | E4: Huyền Ly | F4: Sơn | G4: Hoa | H4: Hoa
A5: 6A5 | B5: S | C5: 4 | D5: Hồng | E5: Khu | F5: Hoa | G5: Huyền Ly | H5: Giang
A6: 6A5 | B6: C | C6: 1 | D6: Hoa | E6: Hà | F6: Giang
A7: 6A5 | B7: C | C7: 2 | D7: Sơn | E7: Lan | F7: Sơn
A8: 6A5 | B8: C | C8: 3 | D8: Huyền Ly | E8: Sơn | F8: Giang
A9: 6A6 | B9: S | C9: 1 | D9: Hoa | E9: Trung | F9: Trung | G9: Hoa | H9: Huyền Ly
A10: 6A6 | B10: S | C10: 2 | D10: Hoa | E10: Hồng | F10: Hoa | G10: Huyền Ly | H10: Sơn
A11: 6A6 | B11: S | C11: 3 | D11: Trung | E11: Hoa | F11: Khu | G11: Sơn | H11: Hồng
A12: 6A6 | B12: S | C12: 4 | D12: Huyền Ly | E12: Huyền Ly | F12: Sơn | G12: Lan Ly | H12: Hoa
A13: 6A6 | B13: C | C13: 1 | D13: Huyền Ly | E13: Lan | F13: Hà
A14: 6A6 | B14: C | C14: 2 | D14: Hoa | E14: Sơn | F14: Nhung
A15: 6A6 | B15: C | C15: 3 | D15: Nhung | E15: Hoa | F15: Sơn
A16: 7A4 | B16: S | C16: 1 | D16: Lệ | E16: Nhung | F16: Lệ | G16: Khu | H16: Sơn
A17: 7A4 | B17: S | C17: 2 | D17: Hồng | E17: Nhung | F17: Huyền Ly | G17: Lệ | H17: Nhung
A18: 7A4 | B18: S | C18: 3 | D18: Nhung | E18: Lệ | F18: Thành | G18: Hồng | H18: Lệ
A19: 7A4 | B19: S | C19: 4 | D19: Trung | E19: Trung | F19: Lệ | G19: Nhung | H19: Lệ
A20: 7A4 | B20: C | C20: 1 | D20: Lan Ly | E20: Hoà | F20: Trung
A21: 7A4 | B21: C | C21: 2 | D21: Hoà | E21: Lan Ly | F21: Hoà
A22: 7A4 | B22: C | C22: 3 | D22: Khu | E22: Thành | F22: Lan Ly
A23: 7A5 | B23: S | C23: 1 | D23: Hoà | E23: Hồng | F23: Thành | G23: Trung | H23: Lan Ly
A24: 7A5 | B24: S | C24: 2 | D24: Thành | E24: Trung | F24: Lệ | G24: Thành | H24: Lệ
A25: 7A5 | B25: S | C25: 3 | D25: Lệ | E25: Thành | F25: Huyền Ly | G25: Lệ | H25: Khu
A26: 7A5 | B26: S | C26: 4 | D26: Thành | E26: Lan Ly | F26: Khu | G26: Hồng | H26: Hoà
A27: 7A5 | B27: C | C27: 1 | D27: Hoà | E27: Sơn | F27: Hoà
A28: 7A5 | B28: C | C28: 2 | D28: Nhung | E28: Thành | F28: Lan Ly
A29: 7A5 | B29: C | C29: 3 | D29: Hoà | E29: Trung | F29: Hoà
A30: 8A5 | B30: S | C30: 1 | D30: Minh Anh | E30: Khu | F30: Uyên | G30: Minh Anh | H30: Nhung
A31: 8A5 | B31: S | C31: 2 | D31: Minh Anh | E31: Uyên | F31: Khu | G31: Minh Anh | H31: Minh Anh
A32: 8A5 | B32: S | C32: 3 | D32: Hồng | E32: Minh Anh | F32: Nhung | G32: Trung | H32: Sơn
A33: 8A5 | B33: S | C33: 4 | D33: Uyên | E33: Nhung | F33: Thành | G33: Khu | H33: Uyên
A34: 8A5 | B34: S | C34: 5 | H34: Minh Anh
A35: 8A5 | B35: C | C35: 1 | D35: Sơn | E35: Trung | F35: Lệ
A36: 8A5 | B36: C | C36: 2 | D36: Lan Ly | E36: Hoà | F36: Trung
A37: 8A5 | B37: C | C37: 3 | D37: Lan Ly | E37: Nguyễn Ly | F37: Hồng
A38: 8A6 | B38: S | C38: 1 | D38: Uyên | E38: Minh Anh | F38: Khu | G38: Hồng | H38: Uyên
A39: 8A6 | B39: S | C39: 2 | D39: Uyên | E39: Khu | F39: Minh Anh | G39: Lan Ly | H39: Khu
A40: 8A6 | B40: S | C40: 3 | D40: Lan Ly | E40: Uyên | F40: Uyên | G40: Minh Anh | H40: Nhung
...

Sheet PhanCong
A1: PHÂN CÔNG CHUYÊN MÔN — 8 lớp (2 lớp/khối, khối 6–9)
B2: 6A5 | C2: 6A6 | D2: 7A4 | E2: 7A5 | F2: 8A5 | G2: 8A6 | H2: 9A5 | I2: 9A6 | K2: MÃ VAI TRÒ
A3: Toán học | B3: Huyền Ly | C3: Huyền Ly | D3: Lệ | E3: Lệ | F3: Minh Anh | G3: Minh Anh | H3: Nguyễn Ly | I3: Nguyễn Ly | K3: 1
A4: Ngữ văn | B4: Hoa | C4: Hoa | D4: Nhung | E4: Thành | F4: Uyên | G4: Uyên | H4: Lan | I4: Lan | K4: 1
A5: Ngoại ngữ | B5: Giang | C5: Trung | D5: Trung | E5: Trung | F5: Trung | G5: Trung | H5: Giang | I5: Giang | K5: 1
A6: Khoa học tự nhiên (Vật lý) | D6: Huyền Ly | E6: Huyền Ly | F6: Nguyễn Ly | G6: Nguyễn Ly | K6: 0
A7: Khoa học tự nhiên (Hóa học) | B7: Sơn | C7: Sơn | D7: Hoà | E7: Hoà | F7: Khu | G7: Khu | H7: Khu | I7: Khu | K7: 0
A8: Khoa học tự nhiên (Sinh học) | D8: Hoà | E8: Hoà | H8: Sơn | I8: Sơn | K8: 0
A9: Lịch sử và Địa Lý (Lịch sử) | B9: Hoa | C9: Hoa | D9: Thành | E9: Thành | F9: Thành | G9: Thành | H9: Thành | I9: Thành | K9: 0
A10: Lịch sử và Địa Lý (Địa lý) | B10: Nhung | C10: Nhung | D10: Nhung | E10: Nhung | F10: Nhung | G10: Nhung | H10: Nhung | I10: Nhung | K10: 0
A11: GDCD | B11: Khu | C11: Khu | D11: Lan Ly | E11: Lan Ly | F11: Hoà | G11: Uyên | H11: Uyên | I11: Uyên | K11: 0
A12: Công nghệ | B12: Huyền Ly | C12: Huyền Ly | D12: Sơn | E12: Sơn | F12: Sơn | G12: Sơn | H12: Khu | I12: Khu | K12: 0
A13: Tin học | B13: Minh Anh | C13: Sơn | D13: Khu | E13: Khu | F13: Lệ | G13: Lệ | H13: Minh Anh | I13: Minh Anh | K13: 0
A14: Giáo dục thể chất | B14: Hồng | C14: Hồng | D14: Hồng | E14: Hồng | F14: Hồng | G14: Hồng | H14: Hồng | I14: Hồng | K14: 4
A15: Nội dung giáo dục của địa phương | B15: Lan | C15: Lan | D15: Khu | E15: Khu | F15: Nhung | G15: Nhung | H15: Thành | I15: Thành | K15: 0
A16: Hoạt động trải nghiệm, hướng nghiệp | B16: Giang | C16: Hoa | D16: Lệ | E16: Hoà | F16: Minh Anh | G16: Uyên | H16: Nguyễn Ly | I16: Lan | K16: 5
A17: Nghệ thuật (Âm nhạc) | B17: Hà | C17: Hà | D17: Lan Ly | E17: Lan Ly | F17: Lan Ly | G17: Lan Ly | H17: Hà | I17: Hà | K17: 0
A18: Nghệ thuật (Mỹ thuật) | B18: Lan Ly | C18: Lan Ly | D18: Lan Ly | E18: Lan Ly | F18: Lan Ly | G18: Lan Ly | H18: Lan Ly | I18: Lan Ly | K18: 0

Sheet SoTiet
A1: ĐỊNH MỨC TIẾT/TUẦN — (C)=chẵn, (L)=lẻ. Môn .5: chẵn=2 lẻ=1
B2: 6A5 C | C2: 6A6 C | D2: 7A4 C | E2: 7A5 C | F2: 8A5 C | G2: 8A6 C | H2: 9A5 C | I2: 9A6 C | K2: 6A5 L | L2: 6A6 L | M2: 7A4 L | N2: 7A5 L | O2: 8A5 L | P2: 8A6 L | Q2: 9A5 L | R2: 9A6 L
A3: Toán học | B3: 4 | C3: 4 | D3: 4 | E3: 4 | F3: 4 | G3: 4 | H3: 4 | I3: 4 | K3: 4 | L3: 4 | M3: 4 | N3: 4 | O3: 4 | P3: 4 | Q3: 4 | R3: 4
A4: Ngữ văn | B4: 4 | C4: 4 | D4: 4 | E4: 4 | F4: 4 | G4: 4 | H4: 4 | I4: 4 | K4: 4 | L4: 4 | M4: 4 | N4: 4 | O4: 4 | P4: 4 | Q4: 4 | R4: 4
A5: Ngoại ngữ | B5: 3 | C5: 3 | D5: 3 | E5: 3 | F5: 3 | G5: 3 | H5: 3 | I5: 3 | K5: 3 | L5: 3 | M5: 3 | N5: 3 | O5: 3 | P5: 3 | Q5: 3 | R5: 3
A6: Khoa học tự nhiên (Vật lý) | B6: 0 | C6: 0 | D6: 1 | E6: 1 | F6: 1 | G6: 1 | H6: 0 | I6: 0 | K6: 0 | L6: 0 | M6: 1 | N6: 1 | O6: 1 | P6: 1 | Q6: 0 | R6: 0
A7: Khoa học tự nhiên (Hóa học) | B7: 4 | C7: 4 | D7: 1 | E7: 1 | F7: 3 | G7: 3 | H7: 3 | I7: 3 | K7: 4 | L7: 4 | M7: 1 | N7: 1 | O7: 3 | P7: 3 | Q7: 3 | R7: 3
A8: Khoa học tự nhiên (Sinh học) | B8: 0 | C8: 0 | D8: 2 | E8: 2 | F8: 0 | G8: 0 | H8: 1 | I8: 1 | K8: 0 | L8: 0 | M8: 2 | N8: 2 | O8: 0 | P8: 0 | Q8: 1 | R8: 1
A9: Lịch sử và Địa Lý (Lịch sử) | B9: 1 | C9: 1 | D9: 2 | E9: 2 | F9: 1 | G9: 1 | H9: 2 | I9: 2 | K9: 1 | L9: 1 | M9: 2 | N9: 2 | O9: 1 | P9: 1 | Q9: 2 | R9: 2
A10: Lịch sử và Địa Lý (Địa lý) | B10: 2 | C10: 2 | D10: 1 | E10: 1 | F10: 2 | G10: 2 | H10: 1 | I10: 1 | K10: 2 | L10: 2 | M10: 1 | N10: 1 | O10: 2 | P10: 2 | Q10: 1 | R10: 1
A11: GDCD | B11: 1 | C11: 1 | D11: 1 | E11: 1 | F11: 1 | G11: 1 | H11: 1 | I11: 1 | K11: 1 | L11: 1 | M11: 1 | N11: 1 | O11: 1 | P11: 1 | Q11: 1 | R11: 1
A12: Công nghệ | B12: 1 | C12: 1 | D12: 1 | E12: 1 | F12: 2 | G12: 2 | H12: 2 | I12: 2 | K12: 1 | L12: 1 | M12: 1 | N12: 1 | O12: 2 | P12: 2 | Q12: 2 | R12: 2
A13: Tin học | B13: 1 | C13: 1 | D13: 1 | E13: 1 | F13: 1 | G13: 1 | H13: 1 | I13: 1 | K13: 1 | L13: 1 | M13: 1 | N13: 1 | O13: 1 | P13: 1 | Q13: 1 | R13: 1
A14: Giáo dục thể chất | B14: 2 | C14: 2 | D14: 2 | E14: 2 | F14: 2 | G14: 2 | H14: 2 | I14: 2 | K14: 2 | L14: 2 | M14: 2 | N14: 2 | O14: 2 | P14: 2 | Q14: 2 | R14: 2
... A18: Nghệ thuật (Mỹ thuật) | B18: 1 | C18: 1 | D18: 1 | E18: 1 | F18: 1 | G18: 1 | H18: 1 | I18: 1 | K18: 1 | L18: 1 | M18: 1 | N18: 1 | O18: 1 | P18: 1 | Q18: 1 | R18: 1

Sheet DinhMuc_GV
A1: ĐỊNH MỨC GIÁO VIÊN — Vượt>0 (đỏ)=quá tải. Chức vụ điền sẵn từ Sheet2. | H1: Chuẩn: | I1: 19 | K1: Chức vụ | L1: Giảm | N1: Sàn tối thiểu: | O1: 0
A2: Tên GV | B2: Chức vụ | H2: Đi T2 (1/0) | I2: GVCN (1/0) | K2: GVCN | L2: 4
A3: Huyền Ly | H3: 1 | I3: 0 | K3: Tổ trưởng | L3: 3
A4: Lệ | B4: GVCN | H4: 1 | I4: 1 | K4: Tổ phó | L4: 1
A5: Minh Anh | B5: GVCN | H5: 1 | I5: 1 | K5: Tổng phụ trách | L5: 8
A6: Nguyễn Ly | B6: GVCN | H6: 1 | I6: 1 | K6: Phó hiệu trưởng | L6: 15
A7: Hoa | B7: GVCN | H7: 1 | I7: 1 | K7: Hỗ trợ TPT | L7: 5
A8: Nhung | H8: 1 | I8: 0 | K8: Thư ký HĐ | L8: 2
A9: Thành | H9: 1 | I9: 0
A10: Uyên | B10: GVCN | H10: 1 | I10: 1
A11: Lan | B11: GVCN | H11: 1 | I11: 1
A12: Giang | B12: GVCN | H12: 1 | I12: 1
A13: Trung | H13: 1 | I13: 0
A14: Sơn | H14: 1 | I14: 0
A15: Hoà | B15: GVCN | H15: 1 | I15: 1
A16: Khu | B16: Thư ký HĐ | H16: 1 | I16: 0
A17: Lan Ly | H17: 1 | I17: 0
A18: Hồng | H18: 0 | I18: 0
A19: Hà | B19: Phó hiệu trưởng | H19: 1 | I19: 0

Sheet GV_Ban
A1: GIÁO VIÊN BẬN / XIN NGHỈ — macro né các khung giờ này, chỉ đổi tối thiểu số tiết
A2: Giáo viên | B2: Thứ | C2: Buổi | D2: Tiết
A3: Hà | B3: 2 | C3: C | D3: 1
A4: Hà | B4: 2 | C4: C | D4: 2
A5: Hà | B5: 2 | C5: C | D5: 3
A6: Hà | B6: 2 | C6: S | D6: 1
A7: Hà | B7: 2 | C7: S | D7: 2
A8: Hà | B8: 2 | C8: S | D8: 3
A9: Hà | B9: 2 | C9: S | D9: 4
A10: Hà | B10: 3 | C10: S | D10: 1
A11: Hà | B11: 3 | C11: S | D11: 2
A12: Hà | B12: 3 | C12: S | D12: 3
A13: Hà | B13: 3 | C13: S | D13: 4
... A37: Hồng | B37: 4 | C37: C | D37: 1

Sheet Khung
D2: x | E2: x | F2: x | G2: x | H2: x
D3: x | E3: x | F3: x | G3: x | H3: x
D4: x | E4: x | F4: x | G4: x | H4: x
D5: x | E5: x | F5: x | G5: x | H5: x
D6: x | E6: x | F6: x
D7: x | E7: x | F7: x
D8: x | E8: x | F8: x
D9: x | E9: x | F9: x | G9: x | H9: x
D10: x | E10: x | F10: x | G10: x | H10: x
D11: x | E11: x | F11: x | G11: x | H11: x
D12: x | E12: x | F12: x | G12: x | H12: x
D13: x | E13: x | F13: x
D14: x | E14: x | F14: x
D15: x | E15: x | F15: x
D16: x | E16: x | F16: x | G16: x | H16: x
D17: x | E17: x | F17: x | G17: x | H17: x
D18: x | E18: x | F18: x | G18: x | H18: x
D19: x | E19: x | F19: x | G19: x | H19: x
D20: x | E20: x | F20: x
D21: x | E21: x | F21: x
D22: x | E22: x | F22: x
D23: x | E23: x | F23: x | G23: x | H23: x
D24: x | E24: x | F24: x | G24: x | H24: x
D25: x | E25: x | F25: x | G25: x | H25: x
D26: x | E26: x | F26: x | G26: x | H26: x
D27: x | E27: x | F27: x
D28: x | E28: x | F28: x
D29: x | E29: x | F29: x
D30: x | E30: x | F30: x | G30: x | H30: x
D31: x | E31: x | F31: x | G31: x | H31: x
D32: x | E32: x | F32: x | G32: x | H32: x
D33: x | E33: x | F33: x | G33: x | H33: x
H34: x
D35: x | E35: x | F35: x
D36: x | E36: x | F36: x
D37: x | E37: x | F37: x
D38: x | E38: x | F38: x | G38: x | H38: x
D39: x | E39: x | F39: x | G39: x | H39: x
D40: x | E40: x | F40: x | G40: x | H40: x
D41: x | E41: x | F41: x | G41: x | H41: x
...

Sheet TKB_Nhap
A1: LỚP HỌC | B1: BUỔI | C1: TIẾT THỨ | D1: Thứ 2 | E1: Thứ 3 | F1: Thứ 4 | G1: Thứ 5 | H1: Thứ 6 | I1: Thứ 7 | J1: Chủ nhật
A2: 6A5 | B2: S | C2: 1 | D2: Hoạt động trải nghiệm, hướng nghiệp | E2: Ngữ văn | F2: Tin học | G2: Lịch sử và Địa Lý (Địa lý) | H2: Ngoại ngữ
A3: 6A5 | B3: S | C3: 2 | D3: Ngoại ngữ | E3: Nghệ thuật (Mỹ thuật) | F3: Lịch sử và Địa Lý (Địa lý) | G3: Giáo dục thể chất | H3: Toán học
A4: 6A5 | B4: S | C4: 3 | D4: Toán học | E4: Toán học | F4: Khoa học tự nhiên (Hóa học) | G4: Ngữ văn | H4: Ngữ văn
A5: 6A5 | B5: S | C5: 4 | D5: Giáo dục thể chất | E5: GDCD | F5: Ngữ văn | G5: Toán học | H5: Hoạt động trải nghiệm, hướng nghiệp
A6: 6A5 | B6: C | C6: 1 | D6: Lịch sử và Địa Lý (Lịch sử) | E6: Nghệ thuật (Âm nhạc) | F6: Ngoại ngữ
A7: 6A5 | B7: C | C7: 2 | D7: Khoa học tự nhiên (Hóa học) | E7: Nội dung giáo dục của địa phương | F7: Khoa học tự nhiên (Hóa học)
A8: 6A5 | B8: C | C8: 3 | D8: Công nghệ | E8: Khoa học tự nhiên (Hóa học) | F8: Hoạt động trải nghiệm, hướng nghiệp
A9: 6A6 | B9: S | C9: 1 | D9: Hoạt động trải nghiệm, hướng nghiệp | E9: Ngoại ngữ | F9: Ngoại ngữ | G9: Ngữ văn | H9: Toán học
A10: 6A6 | B10: S | C10: 2 | D10: Ngữ văn | E10: Giáo dục thể chất | F10: Ngữ văn | G10: Toán học | H10: Khoa học tự nhiên (Hóa học)
A11: 6A6 | B11: S | C11: 3 | D11: Ngoại ngữ | E11: Ngữ văn | F11: GDCD | G11: Khoa học tự nhiên (Hóa học) | H11: Giáo dục thể chất
A12: 6A6 | B12: S | C12: 4 | D12: Toán học | E12: Toán học | F12: Tin học | G12: Nghệ thuật (Mỹ thuật) | H12: Hoạt động trải nghiệm, hướng nghiệp
A13: 6A6 | B13: C | C13: 1 | D13: Công nghệ | E13: Nội dung giáo dục của địa phương | F13: Nghệ thuật (Âm nhạc)
A14: 6A6 | B14: C | C14: 2 | D14: Lịch sử và Địa Lý (Lịch sử) | E14: Khoa học tự nhiên (Hóa học) | F14: Lịch sử và Địa Lý (Địa lý)
A15: 6A6 | B15: C | C15: 3 | D15: Lịch sử và Địa Lý (Địa lý) | E15: Hoạt động trải nghiệm, hướng nghiệp | F15: Khoa học tự nhiên (Hóa học)
A16: 7A4 | B16: S | C16: 1 | D16: Hoạt động trải nghiệm, hướng nghiệp | E16: Lịch sử và Địa Lý (Địa lý) | F16: Toán học | G16: Tin học | H16: Công nghệ
A17: 7A4 | B17: S | C17: 2 | D17: Giáo dục thể chất | E17: Ngữ văn | F17: Khoa học tự nhiên (Vật lý) | G17: Toán học | H17: Ngữ văn
A18: 7A4 | B18: S | C18: 3 | D18: Ngữ văn | E18: Toán học | F18: Lịch sử và Địa Lý (Lịch sử) | G18: Giáo dục thể chất | H18: Toán học
A19: 7A4 | B19: S | C19: 4 | D19: Ngoại ngữ | E19: Ngoại ngữ | F19: Hoạt động trải nghiệm, hướng nghiệp | G19: Ngữ văn | H19: Hoạt động trải nghiệm, hướng nghiệp
A20: 7A4 | B20: C | C20: 1 | D20: Nghệ thuật (Mỹ thuật) | E20: Khoa học tự nhiên (Hóa học) | F20: Ngoại ngữ
A21: 7A4 | B21: C | C21: 2 | D21: Khoa học tự nhiên (Sinh học) | E21: Nghệ thuật (Âm nhạc) | F21: Khoa học tự nhiên (Sinh học)
A22: 7A4 | B22: C | C22: 3 | D22: Nội dung giáo dục của địa phương | E22: Lịch sử và Địa Lý (Lịch sử) | F22: GDCD
A23: 7A5 | B23: S | C23: 1 | D23: Hoạt động trải nghiệm, hướng nghiệp | E23: Giáo dục thể chất | F23: Ngữ văn | G23: Ngoại ngữ | H23: Nghệ thuật (Âm nhạc)
A24: 7A5 | B24: S | C24: 2 | D24: Ngữ văn | E24: Ngoại ngữ | F24: Toán học | G24: Ngữ văn | H24: Toán học
A25: 7A5 | B25: S | C25: 3 | D25: Toán học | E25: Ngữ văn | F25: Khoa học tự nhiên (Vật lý) | G25: Toán học | H25: Nội dung giáo dục của địa phương
A26: 7A5 | B26: S | C26: 4 | D26: Lịch sử và Địa Lý (Lịch sử) | E26: GDCD | F26: Tin học | G26: Giáo dục thể chất | H26: Hoạt động trải nghiệm, hướng nghiệp
A27: 7A5 | B27: C | C27: 1 | D27: Khoa học tự nhiên (Sinh học) | E27: Công nghệ | F27: Khoa học tự nhiên (Sinh học)
A28: 7A5 | B28: C | C28: 2 | D28: Lịch sử và Địa Lý (Địa lý) | E28: Lịch sử và Địa Lý (Lịch sử) | F28: Nghệ thuật (Mỹ thuật)
A29: 7A5 | B29: C | C29: 3 | D29: Khoa học tự nhiên (Hóa học) | E29: Ngoại ngữ | F29: Hoạt động trải nghiệm, hướng nghiệp
A30: 8A5 | B30: S | C30: 1 | D30: Hoạt động trải nghiệm, hướng nghiệp | E30: Khoa học tự nhiên (Hóa học) | F30: Ngữ văn | G30: Toán học | H30: Lịch sử và Địa Lý (Địa lý)
A31: 8A5 | B31: S | C31: 2 | D31: Toán học | E31: Ngữ văn | F31: Khoa học tự nhiên (Hóa học) | G31: Hoạt động trải nghiệm, hướng nghiệp | H31: Toán học
A32: 8A5 | B32: S | C32: 3 | D32: Giáo dục thể chất | E32: Toán học | F32: Nội dung giáo dục của địa phương | G32: Ngoại ngữ | H32: Công nghệ
A33: 8A5 | B33: S | C33: 4 | D33: Ngữ văn | E33: Lịch sử và Địa Lý (Địa lý) | F33: Lịch sử và Địa Lý (Lịch sử) | G33: Khoa học tự nhiên (Hóa học) | H33: Ngữ văn
A34: 8A5 | B34: S | C34: 5 | H34: Hoạt động trải nghiệm, hướng nghiệp
A35: 8A5 | B35: C | C35: 1 | D35: Công nghệ | E35: Ngoại ngữ | F35: Tin học
A36: 8A5 | B36: C | C36: 2 | D36: Nghệ thuật (Âm nhạc) | E36: GDCD | F36: Ngoại ngữ
A37: 8A5 | B37: C | C37: 3 | D37: Nghệ thuật (Mỹ thuật) | E37: Khoa học tự nhiên (Vật lý) | F37: Giáo dục thể chất
A38: 8A6 | B38: S | C38: 1 | D38: Hoạt động trải nghiệm, hướng nghiệp | E38: Toán học | F38: Khoa học tự nhiên (Hóa học) | G38: Giáo dục thể chất | H38: Ngữ văn
A39: 8A6 | B39: S | C39: 2 | D39: Ngữ văn | E39: Khoa học tự nhiên (Hóa học) | F39: Toán học | G39: Nghệ thuật (Âm nhạc) | H39: Khoa học tự nhiên (Hóa học)
A40: 8A6 | B40: S | C40: 3 | D40: Nghệ thuật (Mỹ thuật) | E40: Ngữ văn | F40: Ngữ văn | G40: Toán học | H40: Nội dung giáo dục của địa phương
...

Sheet TuanConfig
A1: SEED HIEN TAI -> | B1: 2026
A2: TUAN HIEN TAI (C=chan/L=le) -> | B2: C
A3: Tuan | B3: Seed | C3: Ngay tao
A4: 1 | B4: 2026 | C4: 2026-09-07T00:00:00 [C]

Sheet KiemTra
A1: KIỂM TRA — Định mức theo TuanConfig!B2 (C/L). Chênh lệch=Đã xếp−Định mức (0=đạt)
A3: Môn \ Lớp | B3: 6A5 | C3: 6A6 | D3: 7A4 | E3: 7A5 | F3: 8A5 | G3: 8A6 | H3: 9A5 | I3: 9A6
A4: Toán học | B4: =SUMPRODUCT((TKB_Nhap!$A$2:$A$57=B$3)*(TKB_Nhap!$D$2:$J$57=$A4))-IFERROR(N(IF(TuanConfig!$B$2="C",INDEX(SoTiet!$B$3:$I$18,MATCH($A4,SoTiet!$A$3:$A$18,0),1),INDEX(SoTiet!$K$3:$R$18,MATCH($A4,SoTiet!$A$3:$A$18,0),1))),0) | C4: =SUMPRODUCT((TKB_Nhap!$A$2:$A$57=C$3)*(TKB_Nhap!$D$2:$J$57=$A4))-IFERROR(N(IF(TuanConfig!$B$2="C",INDEX(SoTiet!$B$3:$I$18,MATCH($A4,SoTiet!$A$3:$A$18,0),2),INDEX(SoTiet!$K$3:$R$18,MATCH($A4,SoTiet!$A$3:$A$18,0),2))),0) | D4: =SUMPRODUCT((TKB_Nhap!$A$2:$A$57=D$3)*(TKB_Nhap!$D$2:$J$57=$A4))-IFERROR(N(IF(TuanConfig!$B$2="C",INDEX(SoTiet!$B$3:$I$18,MATCH($A4,SoTiet!$A$3:$A$18,0),3),INDEX(SoTiet!$K$3:$R$18,MATCH($A4,SoTiet!$A$3:$A$18,0),3))),0) | E4: =SUMPRODUCT((TKB_Nhap!$A$2:$A$57=E$3)*(TKB_Nhap!$D$2:$J$57=$A4))-IFERROR(N(IF(TuanConfig!$B$2="C",INDEX(SoTiet!$B$3:$I$18,MATCH($A4,SoTiet!$A$3:$A$18,0),4),INDEX(SoTiet!$K$3:$R$18,MATCH($A4,SoTiet!$A$3:$A$18,0),4))),0) | F4: =SUMPRODUCT((TKB_Nhap!$A$2:$A$57=F$3)*(TKB_Nhap!$D$2:$J$57=$A4))-IFERROR(N(IF(TuanConfig!$B$2="C",INDEX(SoTiet!$B$3:$I$18,MATCH($A4,SoTiet!$A$3:$A$18,0),5),INDEX(SoTiet!$K$3:$R$18,MATCH($A4,SoTiet!$A$3:$A$18,0),5))),0) | G4: =SUMPRODUCT((TKB_Nhap!$A$2:$A$57=G$3)*(TKB_Nhap!$D$2:$J$57=$A4))-IFERROR(N(IF(TuanConfig!$B$2="C",INDEX(SoTiet!$B$3:$I$18,MATCH($A4,SoTiet!$A$3:$A$18,0),6),INDEX(SoTiet!$K$3:$R$18,MATCH($A4,SoTiet!$A$3:$A$18,0),6))),0) | H4: =SUMPRODUCT((TKB_Nhap!$A$2:$A$57=H$3)*(TKB_Nhap!$D$2:$J$57=$A4))-IFERROR(N(IF(TuanConfig!$B$2="C",INDEX(SoTiet!$B$3:$I$18,MATCH($A4,SoTiet!$A$3:$A$18,0),7),INDEX(SoTiet!$K$3:$R$18,MATCH($A4,SoTiet!$A$3:$A$18,0),7))),0) | I4: =SUMPRODUCT((TKB_Nhap!$A$2:$A$57=I$3)*(TKB_Nhap!$D$2:$J$57=$A4))-IFERROR(N(IF(TuanConfig!$B$2="C",INDEX(SoTiet!$B$3:$I$18,MATCH($A4,SoTiet!$A$3:$A$18,0),8),INDEX(SoTiet!$K$3:$R$18,MATCH($A4,SoTiet!$A$3:$A$18,0),8))),0)
A5: Ngữ văn | B5: =SUMPRODUCT((TKB_Nhap!$A$2:$A$57=B$3)*(TKB_Nhap!$D$2:$J$57=$A5))-IFERROR(N(IF(TuanConfig!$B$2="C",INDEX(SoTiet!$B$3:$I$18,MATCH($A5,SoTiet!$A$3:$A$18,0),1),INDEX(SoTiet!$K$3:$R$18,MATCH($A5,SoTiet!$A$3:$A$18,0),1))),0) | C5: =SUMPRODUCT((TKB_Nhap!$A$2:$A$57=C$3)*(TKB_Nhap!$D$2:$J$57=$A5))-IFERROR(N(IF(TuanConfig!$B$2="C",INDEX(SoTiet!$B$3:$I$18,MATCH($A5,SoTiet!$A$3:$A$18,0),2),INDEX(SoTiet!$K$3:$R$18,MATCH($A5,SoTiet!$A$3:$A$18,0),2))),0) | D5: =SUMPRODUCT((TKB_Nhap!$A$2:$A$57=D$3)*(TKB_Nhap!$D$2:$J$57=$A5))-IFERROR(N(IF(TuanConfig!$B$2="C",INDEX(SoTiet!$B$3:$I$18,MATCH($A5,SoTiet!$A$3:$A$18,0),3),INDEX(SoTiet!$K$3:$R$18,MATCH($A5,SoTiet!$A$3:$A$18,0),3))),0) | E5: =SUMPRODUCT((TKB_Nhap!$A$2:$A$57=E$3)*(TKB_Nhap!$D$2:$J$57=$A5))-IFERROR(N(IF(TuanConfig!$B$2="C",INDEX(SoTiet!$B$3:$I$18,MATCH($A5,SoTiet!$A$3:$A$18,0),4),INDEX(SoTiet!$K$3:$R$18,MATCH($A5,SoTiet!$A$3:$A$18,0),4))),0) | F5: =SUMPRODUCT((TKB_Nhap!$A$2:$A$57=F$3)*(TKB_Nhap!$D$2:$J$57=$A5))-IFERROR(N(IF(TuanConfig!$B$2="C",INDEX(SoTiet!$B$3:$I$18,MATCH($A5,SoTiet!$A$3:$A$18,0),5),INDEX(SoTiet!$K$3:$R$18,MATCH($A5,SoTiet!$A$3:$A$18,0),5))),0) | G5: =SUMPRODUCT((TKB_Nhap!$A$2:$A$57=G$3)*(TKB_Nhap!$D$2:$J$57=$A5))-IFERROR(N(IF(TuanConfig!$B$2="C",INDEX(SoTiet!$B$3:$I$18,MATCH($A5,SoTiet!$A$3:$A$18,0),6),INDEX(SoTiet!$K$3:$R$18,MATCH($A5,SoTiet!$A$3:$A$18,0),6))),0) | H5: =SUMPRODUCT((TKB_Nhap!$A$2:$A$57=H$3)*(TKB_Nhap!$D$2:$J$57=$A5))-IFERROR(N(IF(TuanConfig!$B$2="C",INDEX(SoTiet!$B$3:$I$18,MATCH($A5,SoTiet!$A$3:$A$18,0),7),INDEX(SoTiet!$K$3:$R$18,MATCH($A5,SoTiet!$A$3:$A$18,0),7))),0) | I5: =SUMPRODUCT((TKB_Nhap!$A$2:$A$57=I$3)*(TKB_Nhap!$D$2:$J$57=$A5))-IFERROR(N(IF(TuanConfig!$B$2="C",INDEX(SoTiet!$B$3:$I$18,MATCH($A5,SoTiet!$A$3:$A$18,0),8),INDEX(SoTiet!$K$3:$R$18,MATCH($A5,SoTiet!$A$3:$A$18,0),8))),0)
A6: Ngoại ngữ | B6: =SUMPRODUCT((TKB_Nhap!$A$2:$A$57=B$3)*(TKB_Nhap!$D$2:$J$57=$A6))-IFERROR(N(IF(TuanConfig!$B$2="C",INDEX(SoTiet!$B$3:$I$18,MATCH($A6,SoTiet!$A$3:$A$18,0),1),INDEX(SoTiet!$K$3:$R$18,MATCH($A6,SoTiet!$A$3:$A$18,0),1))),0) | C6: =SUMPRODUCT((TKB_Nhap!$A$2:$A$57=C$3)*(TKB_Nhap!$D$2:$J$57=$A6))-IFERROR(N(IF(TuanConfig!$B$2="C",INDEX(SoTiet!$B$3:$I$18,MATCH($A6,SoTiet!$A$3:$A$18,0),2),INDEX(SoTiet!$K$3:$R$18,MATCH($A6,SoTiet!$A$3:$A$18,0),2))),0) | D6: =SUMPRODUCT((TKB_Nhap!$A$2:$A$57=D$3)*(TKB_Nhap!$D$2:$J$57=$A6))-IFERROR(N(IF(TuanConfig!$B$2="C",INDEX(SoTiet!$B$3:$I$18,MATCH($A6,SoTiet!$A$3:$A$18,0),3),INDEX(SoTiet!$K$3:$R$18,MATCH($A6,SoTiet!$A$3:$A$18,0),3))),0) | E6: =SUMPRODUCT((TKB_Nhap!$A$2:$A$57=E$3)*(TKB_Nhap!$D$2:$J$57=$A6))-IFERROR(N(IF(TuanConfig!$B$2="C",INDEX(SoTiet!$B$3:$I$18,MATCH($A6,SoTiet!$A$3:$A$18,0),4),INDEX(SoTiet!$K$3:$R$18,MATCH($A6,SoTiet!$A$3:$A$18,0),4))),0) | F6: =SUMPRODUCT((TKB_Nhap!$A$2:$A$57=F$3)*(TKB_Nhap!$D$2:$J$57=$A6))-IFERROR(N(IF(TuanConfig!$B$2="C",INDEX(SoTiet!$B$3:$I$18,MATCH($A6,SoTiet!$A$3:$A$18,0),5),INDEX(SoTiet!$K$3:$R$18,MATCH($A6,SoTiet!$A$3:$A$18,0),5))),0) | G6: =SUMPRODUCT((TKB_Nhap!$A$2:$A$57=G$3)*(TKB_Nhap!$D$2:$J$57=$A6))-IFERROR(N(IF(TuanConfig!$B$2="C",INDEX(SoTiet!$B$3:$I$18,MATCH($A6,SoTiet!$A$3:$A$18,0),6),INDEX(SoTiet!$K$3:$R$18,MATCH($A6,SoTiet!$A$3:$A$18,0),6))),0) | H6: =SUMPRODUCT((TKB_Nhap!$A$2:$A$57=H$3)*(TKB_Nhap!$D$2:$J$57=$A6))-IFERROR(N(IF(TuanConfig!$B$2="C",INDEX(SoTiet!$B$3:$I$18,MATCH($A6,SoTiet!$A$3:$A$18,0),7),INDEX(SoTiet!$K$3:$R$18,MATCH($A6,SoTiet!$A$3:$A$18,0),7))),0) | I6: =SUMPRODUCT((TKB_Nhap!$A$2:$A$57=I$3)*(TKB_Nhap!$D$2:$J$57=$A6))-IFERROR(N(IF(TuanConfig!$B$2="C",INDEX(SoTiet!$B$3:$I$18,MATCH($A6,SoTiet!$A$3:$A$18,0),8),INDEX(SoTiet!$K$3:$R$18,MATCH($A6,SoTiet!$A$3:$A$18,0),8))),0)
A7: Khoa học tự nhiên (Vật lý) | B7: =SUMPRODUCT((TKB_Nhap!$A$2:$A$57=B$3)*(TKB_Nhap!$D$2:$J$57=$A7))-IFERROR(N(IF(TuanConfig!$B$2="C",INDEX(SoTiet!$B$3:$I$18,MATCH($A7,SoTiet!$A$3:$A$18,0),1),INDEX(SoTiet!$K$3:$R$18,MATCH($A7,SoTiet!$A$3:$A$18,0),1))),0) | C7: =SUMPRODUCT((TKB_Nhap!$A$2:$A$57=C$3)*(TKB_Nhap!$D$2:$J$57=$A7))-IFERROR(N(IF(TuanConfig!$B$2="C",INDEX(SoTiet!$B$3:$I$18,MATCH($A7,SoTiet!$A$3:$A$18,0),2),INDEX(SoTiet!$K$3:$R$18,MATCH($A7,SoTiet!$A$3:$A$18,0),2))),0) | D7: =SUMPRODUCT((TKB_Nhap!$A$2:$A$57=D$3)*(TKB_Nhap!$D$2:$J$57=$A7))-IFERROR(N(IF(TuanConfig!$B$2="C",INDEX(SoTiet!$B$3:$I$18,MATCH($A7,SoTiet!$A$3:$A$18,0),3),INDEX(SoTiet!$K$3:$R$18,MATCH($A7,SoTiet!$A$3:$A$18,0),3))),0) | E7: =SUMPRODUCT((TKB_Nhap!$A$2:$A$57=E$3)*(TKB_Nhap!$D$2:$J$57=$A7))-IFERROR(N(IF(TuanConfig!$B$2="C",INDEX(SoTiet!$B$3:$I$18,MATCH($A7,SoTiet!$A$3:$A$18,0),4),INDEX(SoTiet!$K$3:$R$18,MATCH($A7,SoTiet!$A$3:$A$18,0),4))),0) | F7: =SUMPRODUCT((TKB_Nhap!$A$2:$A$57=F$3)*(TKB_Nhap!$D$2:$J$57=$A7))-IFERROR(N(IF(TuanConfig!$B$2="C",INDEX(SoTiet!$B$3:$I$18,MATCH($A7,SoTiet!$A$3:$A$18,0),5),INDEX(SoTiet!$K$3:$R$18,MATCH($A7,SoTiet!$A$3:$A$18,0),5))),0) | G7: =SUMPRODUCT((TKB_Nhap!$A$2:$A$57=G$3)*(TKB_Nhap!$D$2:$J$57=$A7))-IFERROR(N(IF(TuanConfig!$B$2="C",INDEX(SoTiet!$B$3:$I$18,MATCH($A7,SoTiet!$A$3:$A$18,0),6),INDEX(SoTiet!$K$3:$R$18,MATCH($A7,SoTiet!$A$3:$A$18,0),6))),0) | H7: =SUMPRODUCT((TKB_Nhap!$A$2:$A$57=H$3)*(TKB_Nhap!$D$2:$J$57=$A7))-IFERROR(N(IF(TuanConfig!$B$2="C",INDEX(SoTiet!$B$3:$I$18,MATCH($A7,SoTiet!$A$3:$A$18,0),7),INDEX(SoTiet!$K$3:$R$18,MATCH($A7,SoTiet!$A$3:$A$18,0),7))),0) | I7: =SUMPRODUCT((TKB_Nhap!$A$2:$A$57=I$3)*(TKB_Nhap!$D$2:$J$57=$A7))-IFERROR(N(IF(TuanConfig!$B$2="C",INDEX(SoTiet!$B$3:$I$18,MATCH($A7,SoTiet!$A$3:$A$18,0),8),INDEX(SoTiet!$K$3:$R$18,MATCH($A7,SoTiet!$A$3:$A$18,0),8))),0)
A8: Khoa học tự nhiên (Hoá học) | B8: =SUMPRODUCT((TKB_Nhap!$A$2:$A$57=B$3)*(TKB_Nhap!$D$2:$J$57=$A8))-IFERROR(N(IF(TuanConfig!$B$2="C",INDEX(SoTiet!$B$3:$I$18,MATCH($A8,SoTiet!$A$3:$A$18,0),1),INDEX(SoTiet!$K$3:$R$18,MATCH($A8,SoTiet!$A$3:$A$18,0),1))),0) | C8: =SUMPRODUCT((TKB_Nhap!$A$2:$A$57=C$3)*(TKB_Nhap!$D$2:$J$57=$A8))-IFERROR(N(IF(TuanConfig!$B$2="C",INDEX(SoTiet!$B$3:$I$18,MATCH($A8,SoTiet!$A$3:$A$18,0),2),INDEX(SoTiet!$K$3:$R$18,MATCH($A8,SoTiet!$A$3:$A$18,0),2))),0) | D8: =SUMPRODUCT((TKB_Nhap!$A$2:$A$57=D$3)*(TKB_Nhap!$D$2:$J$57=$A8))-IFERROR(N(IF(TuanConfig!$B$2="C",INDEX(SoTiet!$B$3:$I$18,MATCH($A8,SoTiet!$A$3:$A$18,0),3),INDEX(SoTiet!$K$3:$R$18,MATCH($A8,SoTiet!$A$3:$A$18,0),3))),0) | E8: =SUMPRODUCT((TKB_Nhap!$A$2:$A$57=E$3)*(TKB_Nhap!$D$2:$J$57=$A8))-IFERROR(N(IF(TuanConfig!$B$2="C",INDEX(SoTiet!$B$3:$I$18,MATCH($A8,SoTiet!$A$3:$A$18,0),4),INDEX(SoTiet!$K$3:$R$18,MATCH($A8,SoTiet!$A$3:$A$18,0),4))),0) | F8: =SUMPRODUCT((TKB_Nhap!$A$2:$A$57=F$3)*(TKB_Nhap!$D$2:$J$57=$A8))-IFERROR(N(IF(TuanConfig!$B$2="C",INDEX(SoTiet!$B$3:$I$18,MATCH($A8,SoTiet!$A$3:$A$18,0),5),INDEX(SoTiet!$K$3:$R$18,MATCH($A8,SoTiet!$A$3:$A$18,0),5))),0) | G8: =SUMPRODUCT((TKB_Nhap!$A$2:$A$57=G$3)*(TKB_Nhap!$D$2:$J$57=$A8))-IFERROR(N(IF(TuanConfig!$B$2="C",INDEX(SoTiet!$B$3:$I$18,MATCH($A8,SoTiet!$A$3:$A$18,0),6),INDEX(SoTiet!$K$3:$R$18,MATCH($A8,SoTiet!$A$3:$A$18,0),6))),0) | H8: =SUMPRODUCT((TKB_Nhap!$A$2:$A$57=H$3)*(TKB_Nhap!$D$2:$J$57=$A8))-IFERROR(N(IF(TuanConfig!$B$2="C",INDEX(SoTiet!$B$3:$I$18,MATCH($A8,SoTiet!$A$3:$A$18,0),7),INDEX(SoTiet!$K$3:$R$18,MATCH($A8,SoTiet!$A$3:$A$18,0),7))),0) | I8: =SUMPRODUCT((TKB_Nhap!$A$2:$A$57=I$3)*(TKB_Nhap!$D$2:$J$57=$A8))-IFERROR(N(IF(TuanConfig!$B$2="C",INDEX(SoTiet!$B$3:$I$18,MATCH($A8,SoTiet!$A$3:$A$18,0),8),INDEX(SoTiet!$K$3:$R$18,MATCH($A8,SoTiet!$A$3:$A$18,0),8))),0)
A9: Khoa học tự nhiên (Sinh học) | B9: =SUMPRODUCT((TKB_Nhap!$A$2:$A$57=B$3)*(TKB_Nhap!$D$2:$J$57=$A9))-IFERROR(N(IF(TuanConfig!$B$2="C",INDEX(SoTiet!$B$3:$I$18,MATCH($A9,SoTiet!$A$3:$A$18,0),1),INDEX(SoTiet!$K$3:$R$18,MATCH($A9,SoTiet!$A$3:$A$18,0),1))),0) | C9: =SUMPRODUCT((TKB_Nhap!$A$2:$A$57=C$3)*(TKB_Nhap!$D$2:$J$57=$A9))-IFERROR(N(IF(TuanConfig!$B$2="C",INDEX(SoTiet!$B$3:$I$18,MATCH($A9,SoTiet!$A$3:$A$18,0),2),INDEX(SoTiet!$K$3:$R$18,MATCH($A9,SoTiet!$A$3:$A$18,0),2))),0) | D9: =SUMPRODUCT((TKB_Nhap!$A$2:$A$57=D$3)*(TKB_Nhap!$D$2:$J$57=$A9))-IFERROR(N(IF(TuanConfig!$B$2="C",INDEX(SoTiet!$B$3:$I$18,MATCH($A9,SoTiet!$A$3:$A$18,0),3),INDEX(SoTiet!$K$3:$R$18,MATCH($A9,SoTiet!$A$3:$A$18,0),3))),0) | E9: =SUMPRODUCT((TKB_Nhap!$A$2:$A$57=E$3)*(TKB_Nhap!$D$2:$J$57=$A9))-IFERROR(N(IF(TuanConfig!$B$2="C",INDEX(SoTiet!$B$3:$I$18,MATCH($A9,SoTiet!$A$3:$A$18,0),4),INDEX(SoTiet!$K$3:$R$18,MATCH($A9,SoTiet!$A$3:$A$18,0),4))),0) | F9: =SUMPRODUCT((TKB_Nhap!$A$2:$A$57=F$3)*(TKB_Nhap!$D$2:$J$57=$A9))-IFERROR(N(IF(TuanConfig!$B$2="C",INDEX(SoTiet!$B$3:$I$18,MATCH($A9,SoTiet!$A$3:$A$18,0),5),INDEX(SoTiet!$K$3:$R$18,MATCH($A9,SoTiet!$A$3:$A$18,0),5))),0) | G9: =SUMPRODUCT((TKB_Nhap!$A$2:$A$57=G$3)*(TKB_Nhap!$D$2:$J$57=$A9))-IFERROR(N(IF(TuanConfig!$B$2="C",INDEX(SoTiet!$B$3:$I$18,MATCH($A9,SoTiet!$A$3:$A$18,0),6),INDEX(SoTiet!$K$3:$R$18,MATCH($A9,SoTiet!$A$3:$A$18,0),6))),0) | H9: =SUMPRODUCT((TKB_Nhap!$A$2:$A$57=H$3)*(TKB_Nhap!$D$2:$J$57=$A9))-IFERROR(N(IF(TuanConfig!$B$2="C",INDEX(SoTiet!$B$3:$I$18,MATCH($A9,SoTiet!$A$3:$A$18,0),7),INDEX(SoTiet!$K$3:$R$18,MATCH($A9,SoTiet!$A$3:$A$18,0),7))),0) | I9: =SUMPRODUCT((TKB_Nhap!$A$2:$A$57=I$3)*(TKB_Nhap!$D$2:$J$57=$A9))-IFERROR(N(IF(TuanConfig!$B$2="C",INDEX(SoTiet!$B$3:$I$18,MATCH($A9,SoTiet!$A$3:$A$18,0),8),INDEX(SoTiet!$K$3:$R$18,MATCH($A9,SoTiet!$A$3:$A$18,0),8))),0)
A10: Lịch sử và địa lý (Lịch sử) | B10: =SUMPRODUCT((TKB_Nhap!$A$2:$A$57=B$3)*(TKB_Nhap!$D$2:$J$57=$A10))-IFERROR(N(IF(TuanConfig!$B$2="C",INDEX(SoTiet!$B$3:$I$18,MATCH($A10,SoTiet!$A$3:$A$18,0),1),INDEX(SoTiet!$K$3:$R$18,MATCH($A10,SoTiet!$A$3:$A$18,0),1))),0) | C10: =SUMPRODUCT((TKB_Nhap!$A$2:$A$57=C$3)*(TKB_Nhap!$D$2:$J$57=$A10))-IFERROR(N(IF(TuanConfig!$B$2="C",INDEX(SoTiet!$B$3:$I$18,MATCH($A10,SoTiet!$A$3:$A$18,0),2),INDEX(SoTiet!$K$3:$R$18,MATCH($A10,SoTiet!$A$3:$A$18,0),2))),0) | D10: =SUMPRODUCT((TKB_Nhap!$A$2:$A$57=D$3)*(TKB_Nhap!$D$2:$J$57=$A10))-IFERROR(N(IF(TuanConfig!$B$2="C",INDEX(SoTiet!$B$3:$I$18,MATCH($A10,SoTiet!$A$3:$A$18,0),3),INDEX(SoTiet!$K$3:$R$18,MATCH($A10,SoTiet!$A$3:$A$18,0),3))),0) | E10: =SUMPRODUCT((TKB_Nhap!$A$2:$A$57=E$3)*(TKB_Nhap!$D$2:$J$57=$A10))-IFERROR(N(IF(TuanConfig!$B$2="C",INDEX(SoTiet!$B$3:$I$18,MATCH($A10,SoTiet!$A$3:$A$18,0),4),INDEX(SoTiet!$K$3:$R$18,MATCH($A10,SoTiet!$A$3:$A$18,0),4))),0) | F10: =SUMPRODUCT((TKB_Nhap!$A$2:$A$57=F$3)*(TKB_Nhap!$D$2:$J$57=$A10))-IFERROR(N(IF(TuanConfig!$B$2="C",INDEX(SoTiet!$B$3:$I$18,MATCH($A10,SoTiet!$A$3:$A$18,0),5),INDEX(SoTiet!$K$3:$R$18,MATCH($A10,SoTiet!$A$3:$A$18,0),5))),0) | G10: =SUMPRODUCT((TKB_Nhap!$A$2:$A$57=G$3)*(TKB_Nhap!$D$2:$J$57=$A10))-IFERROR(N(IF(TuanConfig!$B$2="C",INDEX(SoTiet!$B$3:$I$18,MATCH($A10,SoTiet!$A$3:$A$18,0),6),INDEX(SoTiet!$K$3:$R$18,MATCH($A10,SoTiet!$A$3:$A$18,0),6))),0) | H10: =SUMPRODUCT((TKB_Nhap!$A$2:$A$57=H$3)*(TKB_Nhap!$D$2:$J$57=$A10))-IFERROR(N(IF(TuanConfig!$B$2="C",INDEX(SoTiet!$B$3:$I$18,MATCH($A10,SoTiet!$A$3:$A$18,0),7),INDEX(SoTiet!$K$3:$R$18,MATCH($A10,SoTiet!$A$3:$A$18,0),7))),0) | I10: =SUMPRODUCT((TKB_Nhap!$A$2:$A$57=I$3)*(TKB_Nhap!$D$2:$J$57=$A10))-IFERROR(N(IF(TuanConfig!$B$2="C",INDEX(SoTiet!$B$3:$I$18,MATCH($A10,SoTiet!$A$3:$A$18,0),8),INDEX(SoTiet!$K$3:$R$18,MATCH($A10,SoTiet!$A$3:$A$18,0),8))),0)
A11: Lịch sử và địa lý (Địa lý) | B11: =SUMPRODUCT((TKB_Nhap!$A$2:$A$57=B$3)*(TKB_Nhap!$D$2:$J$57=$A11))-IFERROR(N(IF(TuanConfig!$B$2="C",INDEX(SoTiet!$B$3:$I$18,MATCH($A11,SoTiet!$A$3:$A$18,0),1),INDEX(SoTiet!$K$3:$R$18,MATCH($A11,SoTiet!$A$3:$A$18,0),1))),0) | C11: =SUMPRODUCT((TKB_Nhap!$A$2:$A$57=C$3)*(TKB_Nhap!$D$2:$J$57=$A11))-IFERROR(N(IF(TuanConfig!$B$2="C",INDEX(SoTiet!$B$3:$I$18,MATCH($A11,SoTiet!$A$3:$A$18,0),2),INDEX(SoTiet!$K$3:$R$18,MATCH($A11,SoTiet!$A$3:$A$18,0),2))),0) | D11: =SUMPRODUCT((TKB_Nhap!$A$2:$A$57=D$3)*(TKB_Nhap!$D$2:$J$57=$A11))-IFERROR(N(IF(TuanConfig!$B$2="C",INDEX(SoTiet!$B$3:$I$18,MATCH($A11,SoTiet!$A$3:$A$18,0),3),INDEX(SoTiet!$K$3:$R$18,MATCH($A11,SoTiet!$A$3:$A$18,0),3))),0) | E11: =SUMPRODUCT((TKB_Nhap!$A$2:$A$57=E$3)*(TKB_Nhap!$D$2:$J$57=$A11))-IFERROR(N(IF(TuanConfig!$B$2="C",INDEX(SoTiet!$B$3:$I$18,MATCH($A11,SoTiet!$A$3:$A$18,0),4),INDEX(SoTiet!$K$3:$R$18,MATCH($A11,SoTiet!$A$3:$A$18,0),4))),0) | F11: =SUMPRODUCT((TKB_Nhap!$A$2:$A$57=F$3)*(TKB_Nhap!$D$2:$J$57=$A11))-IFERROR(N(IF(TuanConfig!$B$2="C",INDEX(SoTiet!$B$3:$I$18,MATCH($A11,SoTiet!$A$3:$A$18,0),5),INDEX(SoTiet!$K$3:$R$18,MATCH($A11,SoTiet!$A$3:$A$18,0),5))),0) | G11: =SUMPRODUCT((TKB_Nhap!$A$2:$A$57=G$3)*(TKB_Nhap!$D$2:$J$57=$A11))-IFERROR(N(IF(TuanConfig!$B$2="C",INDEX(SoTiet!$B$3:$I$18,MATCH($A11,SoTiet!$A$3:$A$18,0),6),INDEX(SoTiet!$K$3:$R$18,MATCH($A11,SoTiet!$A$3:$A$18,0),6))),0) | H11: =SUMPRODUCT((TKB_Nhap!$A$2:$A$57=H$3)*(TKB_Nhap!$D$2:$J$57=$A11))-IFERROR(N(IF(TuanConfig!$B$2="C",INDEX(SoTiet!$B$3:$I$18,MATCH($A11,SoTiet!$A$3:$A$18,0),7),INDEX(SoTiet!$K$3:$R$18,MATCH($A11,SoTiet!$A$3:$A$18,0),7))),0) | I11: =SUMPRODUCT((TKB_Nhap!$A$2:$A$57=I$3)*(TKB_Nhap!$D$2:$J$57=$A11))-IFERROR(N(IF(TuanConfig!$B$2="C",INDEX(SoTiet!$B$3:$I$18,MATCH($A11,SoTiet!$A$3:$A$18,0),8),INDEX(SoTiet!$K$3:$R$18,MATCH($A11,SoTiet!$A$3:$A$18,0),8))),0)
A12: Giáo dục công dân | B12: =SUMPRODUCT((TKB_Nhap!$A$2:$A$57=B$3)*(TKB_Nhap!$D$2:$J$57=$A12))-IFERROR(N(IF(TuanConfig!$B$2="C",INDEX(SoTiet!$B$3:$I$18,MATCH($A12,SoTiet!$A$3:$A$18,0),1),INDEX(SoTiet!$K$3:$R$18,MATCH($A12,SoTiet!$A$3:$A$18,0),1))),0) | C12: =SUMPRODUCT((TKB_Nhap!$A$2:$A$57=C$3)*(TKB_Nhap!$D$2:$J$57=$A12))-IFERROR(N(IF(TuanConfig!$B$2="C",INDEX(SoTiet!$B$3:$I$18,MATCH($A12,SoTiet!$A$3:$A$18,0),2),INDEX(SoTiet!$K$3:$R$18,MATCH($A12,SoTiet!$A$3:$A$18,0),2))),0) | D12: =SUMPRODUCT((TKB_Nhap!$A$2:$A$57=D$3)*(TKB_Nhap!$D$2:$J$57=$A12))-IFERROR(N(IF(TuanConfig!$B$2="C",INDEX(SoTiet!$B$3:$I$18,MATCH($A12,SoTiet!$A$3:$A$18,0),3),INDEX(SoTiet!$K$3:$R$18,MATCH($A12,SoTiet!$A$3:$A$18,0),3))),0) | E12: =SUMPRODUCT((TKB_Nhap!$A$2:$A$57=E$3)*(TKB_Nhap!$D$2:$J$57=$A12))-IFERROR(N(IF(TuanConfig!$B$2="C",INDEX(SoTiet!$B$3:$I$18,MATCH($A12,SoTiet!$A$3:$A$18,0),4),INDEX(SoTiet!$K$3:$R$18,MATCH($A12,SoTiet!$A$3:$A$18,0),4))),0) | F12: =SUMPRODUCT((TKB_Nhap!$A$2:$A$57=F$3)*(TKB_Nhap!$D$2:$J$57=$A12))-IFERROR(N(IF(TuanConfig!$B$2="C",INDEX(SoTiet!$B$3:$I$18,MATCH($A12,SoTiet!$A$3:$A$18,0),5),INDEX(SoTiet!$K$3:$R$18,MATCH($A12,SoTiet!$A$3:$A$18,0),5))),0) | G12: =SUMPRODUCT((TKB_Nhap!$A$2:$A$57=G$3)*(TKB_Nhap!$D$2:$J$57=$A12))-IFERROR(N(IF(TuanConfig!$B$2="C",INDEX(SoTiet!$B$3:$I$18,MATCH($A12,SoTiet!$A$3:$A$18,0),6),INDEX(SoTiet!$K$3:$R$18,MATCH($A12,SoTiet!$A$3:$A$18,0),6))),0) | H12: =SUMPRODUCT((TKB_Nhap!$A$2:$A$57=H$3)*(TKB_Nhap!$D$2:$J$57=$A12))-IFERROR(N(IF(TuanConfig!$B$2="C",INDEX(SoTiet!$B$3:$I$18,MATCH($A12,SoTiet!$A$3:$A$18,0),7),INDEX(SoTiet!$K$3:$R$18,MATCH($A12,SoTiet!$A$3:$A$18,0),7))),0) | I12: =SUMPRODUCT((TKB_Nhap!$A$2:$A$57=I$3)*(TKB_Nhap!$D$2:$J$57=$A12))-IFERROR(N(IF(TuanConfig!$B$2="C",INDEX(SoTiet!$B$3:$I$18,MATCH($A12,SoTiet!$A$3:$A$18,0),8),INDEX(SoTiet!$K$3:$R$18,MATCH($A12,SoTiet!$A$3:$A$18,0),8))),0)
A13: Công nghệ | B13: =SUMPRODUCT((TKB_Nhap!$A$2:$A$57=B$3)*(TKB_Nhap!$D$2:$J$57=$A13))-IFERROR(N(IF(TuanConfig!$B$2="C",INDEX(SoTiet!$B$3:$I$18,MATCH($A13,SoTiet!$A$3:$A$18,0),1),INDEX(SoTiet!$K$3:$R$18,MATCH($A13,SoTiet!$A$3:$A$18,0),1))),0) | C13: =SUMPRODUCT((TKB_Nhap!$A$2:$A$57=C$3)*(TKB_Nhap!$D$2:$J$57=$A13))-IFERROR(N(IF(TuanConfig!$B$2="C",INDEX(SoTiet!$B$3:$I$18,MATCH($A13,SoTiet!$A$3:$A$18,0),2),INDEX(SoTiet!$K$3:$R$18,MATCH($A13,SoTiet!$A$3:$A$18,0),2))),0) | D13: =SUMPRODUCT((TKB_Nhap!$A$2:$A$57=D$3)*(TKB_Nhap!$D$2:$J$57=$A13))-IFERROR(N(IF(TuanConfig!$B$2="C",INDEX(SoTiet!$B$3:$I$18,MATCH($A13,SoTiet!$A$3:$A$18,0),3),INDEX(SoTiet!$K$3:$R$18,MATCH($A13,SoTiet!$A$3:$A$18,0),3))),0) | E13: =SUMPRODUCT((TKB_Nhap!$A$2:$A$57=E$3)*(TKB_Nhap!$D$2:$J$57=$A13))-IFERROR(N(IF(TuanConfig!$B$2="C",INDEX(SoTiet!$B$3:$I$18,MATCH($A13,SoTiet!$A$3:$A$18,0),4),INDEX(SoTiet!$K$3:$R$18,MATCH($A13,SoTiet!$A$3:$A$18,0),4))),0) | F13: =SUMPRODUCT((TKB_Nhap!$A$2:$A$57=F$3)*(TKB_Nhap!$D$2:$J$57=$A13))-IFERROR(N(IF(TuanConfig!$B$2="C",INDEX(SoTiet!$B$3:$I$18,MATCH($A13,SoTiet!$A$3:$A$18,0),5),INDEX(SoTiet!$K$3:$R$18,MATCH($A13,SoTiet!$A$3:$A$18,0),5))),0) | G13: =SUMPRODUCT((TKB_Nhap!$A$2:$A$57=G$3)*(TKB_Nhap!$D$2:$J$57=$A13))-IFERROR(N(IF(TuanConfig!$B$2="C",INDEX(SoTiet!$B$3:$I$18,MATCH($A13,SoTiet!$A$3:$A$18,0),6),INDEX(SoTiet!$K$3:$R$18,MATCH($A13,SoTiet!$A$3:$A$18,0),6))),0) | H13: =SUMPRODUCT((TKB_Nhap!$A$2:$A$57=H$3)*(TKB_Nhap!$D$2:$J$57=$A13))-IFERROR(N(IF(TuanConfig!$B$2="C",INDEX(SoTiet!$B$3:$I$18,MATCH($A13,SoTiet!$A$3:$A$18,0),7),INDEX(SoTiet!$K$3:$R$18,MATCH($A13,SoTiet!$A$3:$A$18,0),7))),0) | I13: =SUMPRODUCT((TKB_Nhap!$A$2:$A$57=I$3)*(TKB_Nhap!$D$2:$J$57=$A13))-IFERROR(N(IF(TuanConfig!$B$2="C",INDEX(SoTiet!$B$3:$I$18,MATCH($A13,SoTiet!$A$3:$A$18,0),8),INDEX(SoTiet!$K$3:$R$18,MATCH($A13,SoTiet!$A$3:$A$18,0),8))),0)
A14: Tin | B14: =SUMPRODUCT((TKB_Nhap!$A$2:$A$57=B$3)*(TKB_Nhap!$D$2:$J$57=$A14))-IFERROR(N(IF(TuanConfig!$B$2="C",INDEX(SoTiet!$B$3:$I$18,MATCH($A14,SoTiet!$A$3:$A$18,0),1),INDEX(SoTiet!$K$3:$R$18,MATCH($A14,SoTiet!$A$3:$A$18,0),1))),0) | C14: =SUMPRODUCT((TKB_Nhap!$A$2:$A$57=C$3)*(TKB_Nhap!$D$2:$J$57=$A14))-IFERROR(N(IF(TuanConfig!$B$2="C",INDEX(SoTiet!$B$3:$I$18,MATCH($A14,SoTiet!$A$3:$A$18,0),2),INDEX(SoTiet!$K$3:$R$18,MATCH($A14,SoTiet!$A$3:$A$18,0),2))),0) | D14: =SUMPRODUCT((TKB_Nhap!$A$2:$A$57=D$3)*(TKB_Nhap!$D$2:$J$57=$A14))-IFERROR(N(IF(TuanConfig!$B$2="C",INDEX(SoTiet!$B$3:$I$18,MATCH($A14,SoTiet!$A$3:$A$18,0),3),INDEX(SoTiet!$K$3:$R$18,MATCH($A14,SoTiet!$A$3:$A$18,0),3))),0) | E14: =SUMPRODUCT((TKB_Nhap!$A$2:$A$57=E$3)*(TKB_Nhap!$D$2:$J$57=$A14))-IFERROR(N(IF(TuanConfig!$B$2="C",INDEX(SoTiet!$B$3:$I$18,MATCH($A14,SoTiet!$A$3:$A$18,0),4),INDEX(SoTiet!$K$3:$R$18,MATCH($A14,SoTiet!$A$3:$A$18,0),4))),0) | F14: =SUMPRODUCT((TKB_Nhap!$A$2:$A$57=F$3)*(TKB_Nhap!$D$2:$J$57=$A14))-IFERROR(N(IF(TuanConfig!$B$2="C",INDEX(SoTiet!$B$3:$I$18,MATCH($A14,SoTiet!$A$3:$A$18,0),5),INDEX(SoTiet!$K$3:$R$18,MATCH($A14,SoTiet!$A$3:$A$18,0),5))),0) | G14: =SUMPRODUCT((TKB_Nhap!$A$2:$A$57=G$3)*(TKB_Nhap!$D$2:$J$57=$A14))-IFERROR(N(IF(TuanConfig!$B$2="C",INDEX(SoTiet!$B$3:$I$18,MATCH($A14,SoTiet!$A$3:$A$18,0),6),INDEX(SoTiet!$K$3:$R$18,MATCH($A14,SoTiet!$A$3:$A$18,0),6))),0) | H14: =SUMPRODUCT((TKB_Nhap!$A$2:$A$57=H$3)*(TKB_Nhap!$D$2:$J$57=$A14))-IFERROR(N(IF(TuanConfig!$B$2="C",INDEX(SoTiet!$B$3:$I$18,MATCH($A14,SoTiet!$A$3:$A$18,0),7),INDEX(SoTiet!$K$3:$R$18,MATCH($A14,SoTiet!$A$3:$A$18,0),7))),0) | I14: =SUMPRODUCT((TKB_Nhap!$A$2:$A$57=I$3)*(TKB_Nhap!$D$2:$J$57=$A14))-IFERROR(N(IF(TuanConfig!$B$2="C",INDEX(SoTiet!$B$3:$I$18,MATCH($A14,SoTiet!$A$3:$A$18,0),8),INDEX(SoTiet!$K$3:$R$18,MATCH($A14,SoTiet!$A$3:$A$18,0),8))),0)
A15: Giáo dục thể chất | B15: =SUMPRODUCT((TKB_Nhap!$A$2:$A$57=B$3)*(TKB_Nhap!$D$2:$J$57=$A15))-IFERROR(N(IF(TuanConfig!$B$2="C",INDEX(SoTiet!$B$3:$I$18,MATCH($A15,SoTiet!$A$3:$A$18,0),1),INDEX(SoTiet!$K$3:$R$18,MATCH($A15,SoTiet!$A$3:$A$18,0),1))),0) | C15: =SUMPRODUCT((TKB_Nhap!$A$2:$A$57=C$3)*(TKB_Nhap!$D$2:$J$57=$A15))-IFERROR(N(IF(TuanConfig!$B$2="C",INDEX(SoTiet!$B$3:$I$18,MATCH($A15,SoTiet!$A$3:$A$18,0),2),INDEX(SoTiet!$K$3:$R$18,MATCH($A15,SoTiet!$A$3:$A$18,0),2))),0) | D15: =SUMPRODUCT((TKB_Nhap!$A$2:$A$57=D$3)*(TKB_Nhap!$D$2:$J$57=$A15))-IFERROR(N(IF(TuanConfig!$B$2="C",INDEX(SoTiet!$B$3:$I$18,MATCH($A15,SoTiet!$A$3:$A$18,0),3),INDEX(SoTiet!$K$3:$R$18,MATCH($A15,SoTiet!$A$3:$A$18,0),3))),0) | E15: =SUMPRODUCT((TKB_Nhap!$A$2:$A$57=E$3)*(TKB_Nhap!$D$2:$J$57=$A15))-IFERROR(N(IF(TuanConfig!$B$2="C",INDEX(SoTiet!$B$3:$I$18,MATCH($A15,SoTiet!$A$3:$A$18,0),4),INDEX(SoTiet!$K$3:$R$18,MATCH($A15,SoTiet!$A$3:$A$18,0),4))),0) | F15: =SUMPRODUCT((TKB_Nhap!$A$2:$A$57=F$3)*(TKB_Nhap!$D$2:$J$57=$A15))-IFERROR(N(IF(TuanConfig!$B$2="C",INDEX(SoTiet!$B$3:$I$18,MATCH($A15,SoTiet!$A$3:$A$18,0),5),INDEX(SoTiet!$K$3:$R$18,MATCH($A15,SoTiet!$A$3:$A$18,0),5))),0) | G15: =SUMPRODUCT((TKB_Nhap!$A$2:$A$57=G$3)*(TKB_Nhap!$D$2:$J$57=$A15))-IFERROR(N(IF(TuanConfig!$B$2="C",INDEX(SoTiet!$B$3:$I$18,MATCH($A15,SoTiet!$A$3:$A$18,0),6),INDEX(SoTiet!$K$3:$R$18,MATCH($A15,SoTiet!$A$3:$A$18,0),6))),0) | H15: =SUMPRODUCT((TKB_Nhap!$A$2:$A$57=H$3)*(TKB_Nhap!$D$2:$J$57=$A15))-IFERROR(N(IF(TuanConfig!$B$2="C",INDEX(SoTiet!$B$3:$I$18,MATCH($A15,SoTiet!$A$3:$A$18,0),7),INDEX(SoTiet!$K$3:$R$18,MATCH($A15,SoTiet!$A$3:$A$18,0),7))),0) | I15: =SUMPRODUCT((TKB_Nhap!$A$2:$A$57=I$3)*(TKB_Nhap!$D$2:$J$57=$A15))-IFERROR(N(IF(TuanConfig!$B$2="C",INDEX(SoTiet!$B$3:$I$18,MATCH($A15,SoTiet!$A$3:$A$18,0),8),INDEX(SoTiet!$K$3:$R$18,MATCH($A15,SoTiet!$A$3:$A$18,0),8))),0)
... A19: Nghệ thuật (Mỹ thuật) | B19: =SUMPRODUCT((TKB_Nhap!$A$2:$A$57=B$3)*(TKB_Nhap!$D$2:$J$57=$A19))-IFERROR(N(IF(TuanConfig!$B$2="C",INDEX(SoTiet!$B$3:$I$18,MATCH($A19,SoTiet!$A$3:$A$18,0),1),INDEX(SoTiet!$K$3:$R$18,MATCH($A19,SoTiet!$A$3:$A$18,0),1))),0) | C19: =SUMPRODUCT((TKB_Nhap!$A$2:$A$57=C$3)*(TKB_Nhap!$D$2:$J$57=$A19))-IFERROR(N(IF(TuanConfig!$B$2="C",INDEX(SoTiet!$B$3:$I$18,MATCH($A19,SoTiet!$A$3:$A$18,0),2),INDEX(SoTiet!$K$3:$R$18,MATCH($A19,SoTiet!$A$3:$A$18,0),2))),0) | D19: =SUMPRODUCT((TKB_Nhap!$A$2:$A$57=D$3)*(TKB_Nhap!$D$2:$J$57=$A19))-IFERROR(N(IF(TuanConfig!$B$2="C",INDEX(SoTiet!$B$3:$I$18,MATCH($A19,SoTiet!$A$3:$A$18,0),3),INDEX(SoTiet!$K$3:$R$18,MATCH($A19,SoTiet!$A$3:$A$18,0),3))),0) | E19: =SUMPRODUCT((TKB_Nhap!$A$2:$A$57=E$3)*(TKB_Nhap!$D$2:$J$57=$A19))-IFERROR(N(IF(TuanConfig!$B$2="C",INDEX(SoTiet!$B$3:$I$18,MATCH($A19,SoTiet!$A$3:$A$18,0),4),INDEX(SoTiet!$K$3:$R$18,MATCH($A19,SoTiet!$A$3:$A$18,0),4))),0) | F19: =SUMPRODUCT((TKB_Nhap!$A$2:$A$57=F$3)*(TKB_Nhap!$D$2:$J$57=$A19))-IFERROR(N(IF(TuanConfig!$B$2="C",INDEX(SoTiet!$B$3:$I$18,MATCH($A19,SoTiet!$A$3:$A$18,0),5),INDEX(SoTiet!$K$3:$R$18,MATCH($A19,SoTiet!$A$3:$A$18,0),5))),0) | G19: =SUMPRODUCT((TKB_Nhap!$A$2:$A$57=G$3)*(TKB_Nhap!$D$2:$J$57=$A19))-IFERROR(N(IF(TuanConfig!$B$2="C",INDEX(SoTiet!$B$3:$I$18,MATCH($A19,SoTiet!$A$3:$A$18,0),6),INDEX(SoTiet!$K$3:$R$18,MATCH($A19,SoTiet!$A$3:$A$18,0),6))),0) | H19: =SUMPRODUCT((TKB_Nhap!$A$2:$A$57=H$3)*(TKB_Nhap!$D$2:$J$57=$A19))-IFERROR(N(IF(TuanConfig!$B$2="C",INDEX(SoTiet!$B$3:$I$18,MATCH($A19,SoTiet!$A$3:$A$18,0),7),INDEX(SoTiet!$K$3:$R$18,MATCH($A19,SoTiet!$A$3:$A$18,0),7))),0) | I19: =SUMPRODUCT((TKB_Nhap!$A$2:$A$57=I$3)*(TKB_Nhap!$D$2:$J$57=$A19))-IFERROR(N(IF(TuanConfig!$B$2="C",INDEX(SoTiet!$B$3:$I$18,MATCH($A19,SoTiet!$A$3:$A$18,0),8),INDEX(SoTiet!$K$3:$R$18,MATCH($A19,SoTiet!$A$3:$A$18,0),8))),0)
A20: TỔNG | B20: =SUM(B4:B19) | C20: =SUM(C4:C19) | D20: =SUM(D4:D19) | E20: =SUM(E4:E19) | F20: =SUM(F4:F19) | G20: =SUM(G4:G19) | H20: =SUM(H4:H19) | I20: =SUM(I4:I19)

Sheet HuongDan
A1: HƯỚNG DẪN — PHIÊN BẢN 9 LỚP + RÀNG BUỘC SƯ PHẠM
A3: Nhập liệu: PhanCong (GV — lớp 6C đang tạm chép từ 6B, HÃY SỬA LẠI), SoTiet (định mức), GV_Ban (GV nghỉ/bận), TKB_Nhap (vị trí tiết).
A4: Tự động: TKB (in), TKB_GV (đỏ = trùng GV), KiemTra (đỏ = lệch định mức; tổng tiết mỗi lớp so với khung 29–30 + buổi 2).
A6: MACRO XepTKB (Alt+F8) tự xếp với đầy đủ ràng buộc:
A7: Hệ thống: không trùng GV, không trùng lớp (1 ô 1 môn), đúng định mức SoTiet từng môn/lớp (⇒ đủ tiết GV).
A8: Sư phạm: mỗi môn ≤1 tiết/ngày (riêng Ngữ văn được tiết kép — 2 tiết LIỀN nhau cùng buổi);
A9: không quá 3 tiết 'môn nặng' (Toán, Văn, KHTN Lý/Hoá) liên tiếp trong 1 buổi; Thể dục tránh tiết 5;
A10: ưu tiên rải đều các tiết cùng môn cách ngày; chào cờ = HĐTN Thứ 2 tiết 1; sinh hoạt lớp = HĐTN tiết cuối Thứ 7.
A11: Số tiết/ngày do khung tiết quyết định (sheet ẩn Khung): ngày 2 buổi 7 tiết, ngày 1 buổi 5 tiết — đã đúng chuẩn.
A12: Chế độ giữ lịch tối đa: chỉ đổi các ô bắt buộc, báo rõ số ô giữ/đổi.
A14: Lần đầu sau khi thêm 6C: KiemTra sẽ đỏ ở cột 6C (chưa xếp tiết) — chạy macro 1 lần để điền.
A16: ĐỊNH MỨC GIÁO VIÊN (sheet DinhMuc_GV):
... A19: Macro v4 kiểm tra định mức trước khi xếp và thêm ràng buộc: GV không dạy quá 4 tiết/buổi (không full 5 tiết).

Sheet HuongDan_ChiTiet
B1: HƯỚNG DẪN CHI TIẾT — HỆ THỐNG XẾP THỜI KHÓA BIỂU TỰ ĐỘNG
B3: 8. CÂN BẰNG TẢI GIÁO VIÊN (ModCanBangTai)
B4: Alt+F8 → CanBangTai → tạo sheet 'DeXuat_CanBang'.
B5: Macro quét GV vượt trần (DinhMuc_GV), tìm GV nhược tải DẠY CÙNG MÔN còn quota để chuyển bớt tiết.
B6: Chỉ ĐỀ XUẤT — không tự sửa PhanCong (chuyển GV kéo theo GVCN/thực tế macro không biết).
B7: Quy trình: chạy CanBangTai → xem đề xuất → sửa tay PhanCong → chạy lại để kiểm → XepTKB.
B8: Nếu báo 'không tìm được GV nhận cùng môn': môn đó chỉ 1 GV dạy — cần phân công thêm GV hoặc chấp nhận vượt.
B9: • GV_Ban [NHẬP] — Giáo viên bận/nghỉ theo Thứ/Buổi/Tiết. Macro sẽ né các ô này.
B10: • DinhMuc_GV[NHẬP] — Chức vụ GV → trần tiết (19 − giảm trừ). Cột 'Vượt' đỏ = phải sửa PhanCong.
B11: • TKB_Nhap [LÕI] — Lưới TKB. Macro ghi kết quả vào đây. Là nguồn cho mọi sheet hiển thị.
B12: • Khung [ẨN] — Bản đồ ô được phép xếp (dấu 'x'). Quyết định mẫu buổi học (S4-C3, S5...).
B13: • TuanConfig[CẤU HÌNH] — Seed mỗi tuần (B1) + lịch sử. Điều khiển 'mỗi tuần một TKB'.
... B72: • Luôn lưu file dạng .xlsm (Macro-Enabled). Lưu .xlsx sẽ MẤT toàn bộ macro.
